Workbook

Sheet 00_Инструкция
A1: Методика работы с Excel-шаблоном классификации компаний по уровням конкуренции | B1: Методика работы с Excel-шаблоном классификации компаний по уровням конкуренции | C1: Методика работы с Excel-шаблоном классификации компаний по уровням конкуренции | D1: Методика работы с Excel-шаблоном классификации компаний по уровням конкуренции | E1: Методика работы с Excel-шаблоном классификации компаний по уровням конкуренции | F1: Методика работы с Excel-шаблоном классификации компаний по уровням конкуренции | G1: Методика работы с Excel-шаблоном классификации компаний по уровням конкуренции | H1: Методика работы с Excel-шаблоном классификации компаний по уровням конкуренции
A3: Блок | B3: Что делает аналитик | C3: Где заполнять | D3: Результат | E3: Контроль качества | F3: Тип ошибки | G3: Как исправлять | H3: Итог
A4: 1. Формирование списка | B4: Собрать первичный перечень компаний из поиска, отраслевых обзоров, каталогов, рекламы, рекомендаций и найденных на сайтах ссылок. | C4: 01_Компании | D4: Единый реестр компаний | E4: У каждой компании есть сайт и краткое описание товара. | F4: В список попали нерелевантные компании без объяснения. | G4: Оставлять только с пометкой «объект наблюдения» или исключать. | H4: Сформирован массив для проверки.
A5: 2. Сбор доказательств | B5: По каждой компании фиксировать факты с сайта: продукт, аудитория, цена, сценарии, каналы, доверие, география. | C5: 02_Доказательства | D5: Набор проверяемых сигналов | E5: Каждый вывод имеет URL и наблюдаемый факт. | F5: Аналитик записывает мнение без факта. | G5: Разделять факт и вывод; добавлять ссылку. | H5: Создана доказательная база.
A6: 3. Оценка по критериям | B6: Присвоить баллы 0–5 по каждому критерию согласно листу 03. | C6: 04_Оценка | D6: Взвешенный балл близости | E6: Оценка не ставится без доказательств. | F6: Завышение баллов из-за общего отраслевого сходства. | G6: Проверять заменяемость товара и потребительскую задачу. | H6: Получена расчетная классификация.
A7: 4. Проверка ограничителей | B7: Проверить, не мешает ли низкое совпадение задачи или заменяемости присвоить прямую конкуренцию. | C7: 04_Оценка | D7: Автоматическое ограничение уровня | E7: Прямой конкурент невозможен без совпадения задачи и заменяемости. | F7: Компания названа прямым конкурентом только из-за известности. | G7: Снизить уровень до альтернативы или заменителя. | H7: Классификация становится строгой.
A8: 5. Экспертная корректировка | B8: При необходимости изменить уровень, но только с письменным обоснованием. | C8: 04_Оценка | D8: Итоговый уровень | E8: У корректировки есть причина и ссылка. | F8: Корректировка без объяснения. | G8: Заполнить обоснование и ключевые ссылки. | H8: Получена финальная классификация.
A9: 6. Сводный анализ | B9: Оценить распределение компаний по уровням, выделить прямых конкурентов и ближайшие альтернативы. | C9: 06_Сводка, 07_Карта | D9: Карта конкурентного окружения | E9: Прямые конкуренты отделены от заменителей и смежных компаний. | F9: Все компании смешаны в одну группу. | G9: Использовать уровни и зоны карты отдельно. | H9: Сформирован список для последующего анализа сайтов, товара и бизнес-модели.
A11: Правило | B11: Содержание
A12: Факт важнее предположения | B12: Уровень конкуренции нельзя назначать только по общему впечатлению от компании. Минимальное основание — сайт, страница товара, тарифы, описание сегмента или иной публичный сигнал.
A13: Прямой конкурент — это не просто похожая компания | B13: Прямым конкурентом считается только тот, кто решает ту же задачу для близкой аудитории с функционально заменяемым цифровым товаром.
A14: Заменитель не равен прямому конкуренту | B14: Если конечная потребность похожа, но способ решения другой, компания относится к косвенной конкуренции или заменителям.
A15: Потенциальный конкурент требует сигнала | B15: Недостаточно предположить, что компания может войти в рынок. Нужны признаки: смежные продукты, новые разделы, вакансии, партнерства, дорожная карта, объявления.
A16: Экспертная корректировка допустима | B16: Она нужна для спорных случаев, но всегда должна сопровождаться обоснованием и ссылками на доказательства.

Sheet 01_Компании
A1: Реестр компаний для классификации по уровням конкуренции | B1: Реестр компаний для классификации по уровням конкуренции | C1: Реестр компаний для классификации по уровням конкуренции | D1: Реестр компаний для классификации по уровням конкуренции | E1: Реестр компаний для классификации по уровням конкуренции | F1: Реестр компаний для классификации по уровням конкуренции | G1: Реестр компаний для классификации по уровням конкуренции | H1: Реестр компаний для классификации по уровням конкуренции | I1: Реестр компаний для классификации по уровням конкуренции | J1: Реестр компаний для классификации по уровням конкуренции | K1: Реестр компаний для классификации по уровням конкуренции | L1: Реестр компаний для классификации по уровням конкуренции | M1: Реестр компаний для классификации по уровням конкуренции
A3: ID | B3: Компания | C3: Сайт | D3: Рынок / страна | E3: Тип компании | F3: Основной цифровой товар | G3: Целевой сегмент | H3: Предварительная гипотеза | I3: Приоритет | J3: Ответственный | K3: Статус | L3: Дата обновления | M3: Комментарий
A4: K001 | B4: PerfectXL | C4: perfectxl.com | D4: Нидерланды, мир | E4: специализированный инструмент | F4: аудит Excel: риски, потоки данных, сравнение | G4: аудит, консалтинг, страхование | H4: гипотеза уточняется оценкой | I4: высокий | J4: Р. В. Земляник | K4: Проверено | L4: 46298 | M4: ЛР5, снимок 03.10.2026
A5: K002 | B5: Arixcel | C5: arixcel.com | D5: мир | E5: специализированный инструмент | F5: надстройка навигации и аудита моделей | G5: аналитики, моделисты | H5: гипотеза уточняется оценкой | I5: высокий | J5: Р. В. Земляник | K5: Проверено | L5: 46298 | M5: ЛР5, снимок 03.10.2026
A6: K003 | B6: Operis | C6: operis.com | D6: Великобритания, мир | E6: консалтинг и инструмент | F6: аудит моделей и надстройка OAK | G6: проектное финансирование | H6: гипотеза уточняется оценкой | I6: высокий | J6: Р. В. Земляник | K6: Проверено | L6: 46298 | M6: ЛР5, снимок 03.10.2026
A7: K004 | B7: Shortcut | C7: shortcut.ai | D7: США, мир | E7: AI-агент | F7: AI-агент для финансовых моделей в Excel | G7: финансовые институты, FP&A | H7: гипотеза уточняется оценкой | I7: высокий | J7: Р. В. Земляник | K7: Проверено | L7: 46298 | M7: ЛР5, снимок 03.10.2026
A8: K005 | B8: Numerous.ai | C8: numerous.ai | D8: США, мир | E8: AI-помощник | F8: функция =AI в Sheets и Excel | G8: массовые пользователи | H8: гипотеза уточняется оценкой | I8: высокий | J8: Р. В. Земляник | K8: Проверено | L8: 46298 | M8: ЛР5, снимок 03.10.2026
A9: K006 | B9: Datarails | C9: datarails.com | D9: США, Израиль | E9: FP&A-платформа | F9: FinanceOS над Excel | G9: финансовые команды среднего размера | H9: гипотеза уточняется оценкой | I9: высокий | J9: Р. В. Земляник | K9: Проверено | L9: 46298 | M9: ЛР5, снимок 03.10.2026
A10: K007 | B10: DataSnipper | C10: datasnipper.com | D10: Нидерланды, мир | E10: платформа аудита | F10: агентная автоматизация аудита | G10: аудиторские фирмы | H10: гипотеза уточняется оценкой | I10: высокий | J10: Р. В. Земляник | K10: Проверено | L10: 46298 | M10: ЛР5, снимок 03.10.2026
A11: K008 | B11: Rows | C11: rows.com | D11: Португалия, мир | E11: электронная таблица с AI | F11: альтернативная таблица с AI-функциями | G11: команды и бизнес | H11: гипотеза уточняется оценкой | I11: средний | J11: Р. В. Земляник | K11: Проверено | L11: 46298 | M11: ЛР5, снимок 03.10.2026
A12: K009 | B12: Formula Bot | C12: formulabot.com | D12: мир | E12: AI-помощник | F12: генерация формул и анализ данных | G12: массовые пользователи | H12: гипотеза уточняется оценкой | I12: средний | J12: Р. В. Земляник | K12: Проверено | L12: 46298 | M12: ЛР5, снимок 03.10.2026
A13: K010 | B13: Microsoft 365 Copilot | C13: microsoft.com/microsoft-365-copilot | D13: мир | E13: встроенный AI | F13: AI-ассистент внутри Excel | G13: корпоративные пользователи Microsoft 365 | H13: гипотеза уточняется оценкой | I13: средний | J13: Р. В. Земляник | K13: Проверено | L13: 46298 | M13: ЛР5, снимок 03.10.2026
A14: K011
A15: K012
A16: K013
A17: K014
A18: K015
A19: K016
A20: K017
A21: K018
A22: K019
A23: K020
A24: K021
A25: K022
... A103: K100

Sheet 02_Доказательства
A1: Доказательства и сигналы с сайтов конкурентов | B1: Доказательства и сигналы с сайтов конкурентов | C1: Доказательства и сигналы с сайтов конкурентов | D1: Доказательства и сигналы с сайтов конкурентов | E1: Доказательства и сигналы с сайтов конкурентов | F1: Доказательства и сигналы с сайтов конкурентов | G1: Доказательства и сигналы с сайтов конкурентов | H1: Доказательства и сигналы с сайтов конкурентов | I1: Доказательства и сигналы с сайтов конкурентов | J1: Доказательства и сигналы с сайтов конкурентов | K1: Доказательства и сигналы с сайтов конкурентов | L1: Доказательства и сигналы с сайтов конкурентов
A3: ID компании | B3: Компания | C3: Раздел сайта | D3: URL | E3: Наблюдаемый факт | F3: Тип сигнала | G3: Сила сигнала 1–5 | H3: Дата фиксации | I3: Вывод для классификации | J3: Достоверность 1–5 | K3: Скриншот / архив | L3: Комментарий
A4: K001 | B4: =IFERROR(INDEX('01_Компании'!$B$4:$B$103,MATCH(A4,'01_Компании'!$A$4:$A$103,0)),"") -> PerfectXL | C4: Главная | D4: https://www.perfectxl.com/ | E4: Software That Helps You Master Excel; клиенты Deloitte, Grant Thornton, BDO; премия 2026 | F4: Потребительская задача | G4: 4 | H4: 46298 | I4: Позиционирование на контроле качества и рисках | J4: 5 | L4: просмотр в Chrome или WebFetch 03.10.2026
A5: K001 | B5: =IFERROR(INDEX('01_Компании'!$B$4:$B$103,MATCH(A5,'01_Компании'!$A$4:$A$103,0)),"") -> PerfectXL | C5: Цены | D5: https://www.perfectxl.com/pricing/ | E5: один инструмент от 69 EUR в месяц; пакеты без цен; обучение от 49 EUR | F5: Цена и тарифы | G5: 4 | H5: 46298 | I5: Цены раскрыты частично | J5: 5 | L5: просмотр в Chrome или WebFetch 03.10.2026
A6: K002 | B6: =IFERROR(INDEX('01_Компании'!$B$4:$B$103,MATCH(A6,'01_Компании'!$A$4:$A$103,0)),"") -> Arixcel | C6: Главная | D6: https://www.arixcel.com/ | E6: надстройка Excel: логика формул, сравнение, карта формул, трассировка | F6: Потребительская задача | G6: 4 | H6: 46298 | I6: Узкий инструмент без цен и без отзывов | J6: 4 | L6: просмотр в Chrome или WebFetch 03.10.2026
A7: K003 | B7: =IFERROR(INDEX('01_Компании'!$B$4:$B$103,MATCH(A7,'01_Компании'!$A$4:$A$103,0)),"") -> Operis | C7: Главная | D7: https://www.operis.com/ | E7: Advisory, Modelling, Model Audit, Tax & Accounting, OAK, Training; с 1990 г., более 1 200 проектов | F7: Потребительская задача | G7: 4 | H7: 46298 | I7: Консалтинговый бизнес с надстройкой | J7: 4 | L7: просмотр в Chrome или WebFetch 03.10.2026
A8: K004 | B8: =IFERROR(INDEX('01_Компании'!$B$4:$B$103,MATCH(A8,'01_Компании'!$A$4:$A$103,0)),"") -> Shortcut | C8: Главная | D8: https://www.shortcut.ai/ | E8: AI-агент для финансистов, SOC 2 Type II, Excel Add-in, веб, CLI | F8: Потребительская задача | G8: 4 | H8: 46298 | I8: Сильное доверие и безопасность на первом экране | J8: 5 | L8: просмотр в Chrome или WebFetch 03.10.2026
A9: K004 | B9: =IFERROR(INDEX('01_Компании'!$B$4:$B$103,MATCH(A9,'01_Компании'!$A$4:$A$103,0)),"") -> Shortcut | C9: Цены | D9: https://www.shortcut.ai/pricing | E9: Free, Pro 100 USD, Teams 320 USD + 100 USD за место, Enterprise | F9: Цена и тарифы | G9: 4 | H9: 46298 | I9: Прозрачные тарифы | J9: 5 | L9: просмотр в Chrome или WebFetch 03.10.2026
A10: K005 | B10: =IFERROR(INDEX('01_Компании'!$B$4:$B$103,MATCH(A10,'01_Компании'!$A$4:$A$103,0)),"") -> Numerous.ai | C10: Главная | D10: https://www.numerous.ai/ | E10: ChatGPT в Sheets и Excel, функция =AI, без API-ключей | F10: Потребительская задача | G10: 4 | H10: 46298 | I10: Простое предложение для массового пользователя | J10: 5 | L10: просмотр в Chrome или WebFetch 03.10.2026
A11: K005 | B11: =IFERROR(INDEX('01_Компании'!$B$4:$B$103,MATCH(A11,'01_Компании'!$A$4:$A$103,0)),"") -> Numerous.ai | C11: Цены | D11: https://www.numerous.ai/pricing | E11: 10 USD в месяц, 7 дней пробного периода | F11: Цена и тарифы | G11: 4 | H11: 46298 | I11: Один тариф | J11: 5 | L11: просмотр в Chrome или WebFetch 03.10.2026
A12: K006 | B12: =IFERROR(INDEX('01_Компании'!$B$4:$B$103,MATCH(A12,'01_Компании'!$A$4:$A$103,0)),"") -> Datarails | C12: Главная | D12: https://datarails.com/ | E12: Trusted AI for Finance Teams; 600+ интеграций; 2 000+ клиентов | F12: Потребительская задача | G12: 4 | H12: 46298 | I12: Платформа, а не инструмент проверки | J12: 5 | L12: просмотр в Chrome или WebFetch 03.10.2026
A13: K007 | B13: =IFERROR(INDEX('01_Компании'!$B$4:$B$103,MATCH(A13,'01_Компании'!$A$4:$A$103,0)),"") -> DataSnipper | C13: Главная | D13: https://www.datasnipper.com/ | E13: End-to-end Agentic Automation for Audit and Finance; SOC 2, GDPR, AI Act | F13: Потребительская задача | G13: 4 | H13: 46298 | I13: Сильная позиция в аудите | J13: 5 | L13: просмотр в Chrome или WebFetch 03.10.2026
A14: K004 | B14: =IFERROR(INDEX('01_Компании'!$B$4:$B$103,MATCH(A14,'01_Компании'!$A$4:$A$103,0)),"") -> Shortcut | C14: Отзывы | D14: https://www.g2.com/search?query=shortcut | E14: карточки на G2 нет | F14: Доверие | G14: 4 | H14: 46298 | I14: Нет публичных отзывов | J14: 4 | L14: просмотр в Chrome или WebFetch 03.10.2026
A15: K006 | B15: =IFERROR(INDEX('01_Компании'!$B$4:$B$103,MATCH(A15,'01_Компании'!$A$4:$A$103,0)),"") -> Datarails | C15: Отзывы | D15: https://www.g2.com/search?query=datarails | E15: G2 386 отзывов, 4,6 | F15: Доверие | G15: 4 | H15: 46298 | I15: Самый сильный репутационный профиль | J15: 5 | L15: просмотр в Chrome или WebFetch 03.10.2026
... A38: K010 | B38: =IFERROR(INDEX('01_Компании'!$B$4:$B$103,MATCH(A38,'01_Компании'!$A$4:$A$103,0)),"") -> Microsoft 365 Copilot | C38: Цены | D38: https://www.microsoft.com/en-us/microsoft-365-copilot/pricing | E38: Copilot Business 18 USD в месяц за пользователя при оплате за год | F38: Цена и тарифы | G38: 5 | H38: 46298 | I38: Встроенный AI-заменитель | J38: 5 | L38: просмотр в Chrome или WebFetch 03.10.2026
B39: =IFERROR(INDEX('01_Компании'!$B$4:$B$103,MATCH(A39,'01_Компании'!$A$4:$A$103,0)),"")
B40: =IFERROR(INDEX('01_Компании'!$B$4:$B$103,MATCH(A40,'01_Компании'!$A$4:$A$103,0)),"")
B41: =IFERROR(INDEX('01_Компании'!$B$4:$B$103,MATCH(A41,'01_Компании'!$A$4:$A$103,0)),"")
B42: =IFERROR(INDEX('01_Компании'!$B$4:$B$103,MATCH(A42,'01_Компании'!$A$4:$A$103,0)),"")
B43: =IFERROR(INDEX('01_Компании'!$B$4:$B$103,MATCH(A43,'01_Компании'!$A$4:$A$103,0)),"")
B44: =IFERROR(INDEX('01_Компании'!$B$4:$B$103,MATCH(A44,'01_Компании'!$A$4:$A$103,0)),"")
B45: =IFERROR(INDEX('01_Компании'!$B$4:$B$103,MATCH(A45,'01_Компании'!$A$4:$A$103,0)),"")
B46: =IFERROR(INDEX('01_Компании'!$B$4:$B$103,MATCH(A46,'01_Компании'!$A$4:$A$103,0)),"")
B47: =IFERROR(INDEX('01_Компании'!$B$4:$B$103,MATCH(A47,'01_Компании'!$A$4:$A$103,0)),"")
B48: =IFERROR(INDEX('01_Компании'!$B$4:$B$103,MATCH(A48,'01_Компании'!$A$4:$A$103,0)),"")
B49: =IFERROR(INDEX('01_Компании'!$B$4:$B$103,MATCH(A49,'01_Компании'!$A$4:$A$103,0)),"")
B50: =IFERROR(INDEX('01_Компании'!$B$4:$B$103,MATCH(A50,'01_Компании'!$A$4:$A$103,0)),"")
... B303: =IFERROR(INDEX('01_Компании'!$B$4:$B$103,MATCH(A303,'01_Компании'!$A$4:$A$103,0)),"")

Sheet 03_Критерии
A1: Критерии оценки уровня конкуренции | B1: Критерии оценки уровня конкуренции | C1: Критерии оценки уровня конкуренции | D1: Критерии оценки уровня конкуренции | E1: Критерии оценки уровня конкуренции | F1: Критерии оценки уровня конкуренции | G1: Критерии оценки уровня конкуренции | H1: Критерии оценки уровня конкуренции | I1: Критерии оценки уровня конкуренции | J1: Критерии оценки уровня конкуренции
A3: Код | B3: Критерий | C3: Что проверяется по сайту | D3: Индикаторы | E3: Вес | F3: 0 баллов | G3: 1 балл | H3: 3 балла | I3: 5 баллов | J3: Обязателен для прямого конкурента
A4: C1 | B4: Потребительская задача | C4: Какую проблему клиента компания обещает решить. | D4: Формулировки на главной странице, страницы продукта, выгоды, результаты, случаи применения. | E4: 20 | F4: Задача не совпадает | G4: Есть общее отраслевое сходство | H4: Задача в значительной степени совпадает | I4: Та же задача и тот же ожидаемый результат | J4: Да
A5: C2 | B5: Целевая аудитория | C5: Для кого предназначен товар. | D5: Сегменты, отрасли, роли пользователей, размер клиента, B2B/B2C/B2G. | E5: 15 | F5: Иная аудитория | G5: Частичное пересечение | H5: Существенное пересечение | I5: Та же целевая аудитория | J5: Да
A6: C3 | B6: Функциональная заменяемость товара | C6: Может ли товар заменить анализируемое решение. | D6: Функции, модули, демонстрации, страницы возможностей, интеграции. | E6: 18 | F6: Не заменяет | G6: Заменяет отдельный участок | H6: Заменяет значимую часть задачи | I6: Может полностью заменить товар | J6: Да
A7: C4 | B7: Сценарий использования | C7: В каком процессе и в какой ситуации используется товар. | D7: Путь пользователя, описания внедрения, варианты использования, инструкции. | E7: 10 | F7: Иной сценарий | G7: Слабое совпадение сценария | H7: Сценарии близки | I7: Сценарии практически одинаковы | J7: Нет
A8: C5 | B8: Ценовой уровень и форма оплаты | C8: Сопоставима ли экономическая логика покупки. | D8: Тарифы, подписка, комиссия, пакет, бесплатный период, корпоративный расчет. | E8: 8 | F8: Нет данных/иная экономика | G8: Частично сопоставимо | H8: Сопоставимый диапазон | I8: Почти тот же диапазон и форма оплаты | J8: Нет
A9: C6 | B9: Каналы продаж и привлечения | C9: Как клиент приходит к покупке и получает доступ. | D9: Сайт, приложение, маркетплейсы, партнеры, личные продажи, демонстрация, пробный доступ. | E9: 8 | F9: Каналы не совпадают | G9: Есть один общий канал | H9: Несколько общих каналов | I9: Путь к покупке почти одинаков | J9: Нет
A10: C7 | B10: География, язык, регулирование | C10: Работает ли компания на том же рынке в сопоставимых условиях. | D10: Страны, языки, валюта, юридическая информация, требования отрасли. | E10: 7 | F10: Иной рынок | G10: Потенциально релевантно | H10: Рынки частично совпадают | I10: Тот же рынок и условия | J10: Нет
A11: C8 | B11: Модель монетизации | C11: Как компания получает выручку. | D11: Тарифные планы, комиссия, freemium, лицензия, платные модули, реклама. | E11: 7 | F11: Иная логика выручки | G11: Есть отдельные сходства | H11: Модель близка | I11: Модель практически совпадает | J11: Нет
A12: C9 | B12: Уровень зрелости и доверия | C12: Способна ли компания реально конкурировать за выбор клиента. | D12: Кейсы, клиенты, отзывы, сертификаты, партнеры, история, служба поддержки. | E12: 4 | F12: Слабые признаки зрелости | G12: Единичные признаки | H12: Достаточные признаки надежности | I12: Сильная доказанная рыночная позиция | J12: Нет
A13: C10 | B13: Вероятность переключения клиента | C13: Насколько реалистично, что клиент заменит одно решение другим. | D13: Миграция, импорт данных, интеграции, поддержка перехода, сравнения, обещания простого старта. | E13: 3 | F13: Переключение маловероятно | G13: Требует значительных усилий | H13: Переключение возможно | I13: Переключение явно поддерживается | J13: Нет
A15: Примечание | B15: Вес можно изменять под отрасль. Итоговая оценка на листе 04 автоматически пересчитывается по измененным весам.

Sheet 04_Оценка
A1: Матрица оценки и автоматическая классификация уровня конкуренции | B1: Матрица оценки и автоматическая классификация уровня конкуренции | C1: Матрица оценки и автоматическая классификация уровня конкуренции | D1: Матрица оценки и автоматическая классификация уровня конкуренции | E1: Матрица оценки и автоматическая классификация уровня конкуренции | F1: Матрица оценки и автоматическая классификация уровня конкуренции | G1: Матрица оценки и автоматическая классификация уровня конкуренции | H1: Матрица оценки и автоматическая классификация уровня конкуренции | I1: Матрица оценки и автоматическая классификация уровня конкуренции | J1: Матрица оценки и автоматическая классификация уровня конкуренции | K1: Матрица оценки и автоматическая классификация уровня конкуренции | L1: Матрица оценки и автоматическая классификация уровня конкуренции | M1: Матрица оценки и автоматическая классификация уровня конкуренции | N1: Матрица оценки и автоматическая классификация уровня конкуренции | O1: Матрица оценки и автоматическая классификация уровня конкуренции | P1: Матрица оценки и автоматическая классификация уровня конкуренции | Q1: Матрица оценки и автоматическая классификация уровня конкуренции | R1: Матрица оценки и автоматическая классификация уровня конкуренции | S1: Матрица оценки и автоматическая классификация уровня конкуренции | T1: Матрица оценки и автоматическая классификация уровня конкуренции | U1: Матрица оценки и автоматическая классификация уровня конкуренции | V1: Матрица оценки и автоматическая классификация уровня конкуренции
A3: ID | B3: Компания | C3: Сайт | D3: C1 задача | E3: C2 аудитория | F3: C3 заменяемость | G3: C4 сценарий | H3: C5 цена | I3: C6 каналы | J3: C7 география | K3: C8 монетизация | L3: C9 зрелость | M3: C10 переключение | N3: Взвешенный балл | O3: Ограничитель | P3: Расчетный уровень | Q3: Экспертная корректировка | R3: Итоговый уровень | S3: Статус решения | T3: Ключевое обоснование | U3: Ключевые ссылки | V3: Дата проверки
A4: K001 | B4: =IFERROR(INDEX('01_Компании'!$B$4:$B$103,MATCH(A4,'01_Компании'!$A$4:$A$103,0)),"") -> PerfectXL | C4: =IFERROR(INDEX('01_Компании'!$C$4:$C$103,MATCH(A4,'01_Компании'!$A$4:$A$103,0)),"") -> perfectxl.com | D4: 5 | E4: 4 | F4: 4 | G4: 5 | H4: 3 | I4: 3 | J4: 4 | K4: 4 | L4: 4 | M4: 3 | N4: =IF(COUNTA(D4:M4)=0,"",MMULT(D4:M4,'03_Критерии'!$E$4:$E$13)/SUM('03_Критерии'!$E$4:$E$13)) -> 4.11 | O4: =IF(N4="","",IF(COUNTA(D4:M4)<6,"Недостаточно данных",IF(D4<3,"Низкое совпадение задачи",IF(F4<3,"Низкая товарная заменяемость","Нет")))) -> Нет | P4: =IF(N4="","",IF(O4="Недостаточно данных","Недостаточно данных",IF(OR(D4<3,F4<3),IF(N4>=2.5,"Косвенный конкурент / заменитель",IF(N4>=1.6,"Смежная или потенциальная конкуренция","Не конкурент / объект наблюдения")),IF(N4>=4.2,"Прямой конкурент",IF(N4>=3.4,"Близкий альтернативный конкурент",IF(N4>=2.5,"Косвенный конкурент / заменитель",IF(N4>=1.6,"Смежная или потенциальная конкуренция","Не конкурент / объект наблюдения"))))))) -> Близкий альтернативный конкурент | R4: =IF(Q4="",P4,Q4) -> Близкий альтернативный конкурент
A5: K002 | B5: =IFERROR(INDEX('01_Компании'!$B$4:$B$103,MATCH(A5,'01_Компании'!$A$4:$A$103,0)),"") -> Arixcel | C5: =IFERROR(INDEX('01_Компании'!$C$4:$C$103,MATCH(A5,'01_Компании'!$A$4:$A$103,0)),"") -> arixcel.com | D5: 4 | E5: 4 | F5: 3 | G5: 4 | H5: 3 | I5: 2 | J5: 4 | K5: 3 | L5: 3 | M5: 3 | N5: =IF(COUNTA(D5:M5)=0,"",MMULT(D5:M5,'03_Критерии'!$E$4:$E$13)/SUM('03_Критерии'!$E$4:$E$13)) -> 3.44 | O5: =IF(N5="","",IF(COUNTA(D5:M5)<6,"Недостаточно данных",IF(D5<3,"Низкое совпадение задачи",IF(F5<3,"Низкая товарная заменяемость","Нет")))) -> Нет | P5: =IF(N5="","",IF(O5="Недостаточно данных","Недостаточно данных",IF(OR(D5<3,F5<3),IF(N5>=2.5,"Косвенный конкурент / заменитель",IF(N5>=1.6,"Смежная или потенциальная конкуренция","Не конкурент / объект наблюдения")),IF(N5>=4.2,"Прямой конкурент",IF(N5>=3.4,"Близкий альтернативный конкурент",IF(N5>=2.5,"Косвенный конкурент / заменитель",IF(N5>=1.6,"Смежная или потенциальная конкуренция","Не конкурент / объект наблюдения"))))))) -> Близкий альтернативный конкурент | R5: =IF(Q5="",P5,Q5) -> Близкий альтернативный конкурент
A6: K003 | B6: =IFERROR(INDEX('01_Компании'!$B$4:$B$103,MATCH(A6,'01_Компании'!$A$4:$A$103,0)),"") -> Operis | C6: =IFERROR(INDEX('01_Компании'!$C$4:$C$103,MATCH(A6,'01_Компании'!$A$4:$A$103,0)),"") -> operis.com | D6: 4 | E6: 3 | F6: 3 | G6: 3 | H6: 2 | I6: 2 | J6: 3 | K6: 3 | L6: 4 | M6: 2 | N6: =IF(COUNTA(D6:M6)=0,"",MMULT(D6:M6,'03_Критерии'!$E$4:$E$13)/SUM('03_Критерии'!$E$4:$E$13)) -> 3.05 | O6: =IF(N6="","",IF(COUNTA(D6:M6)<6,"Недостаточно данных",IF(D6<3,"Низкое совпадение задачи",IF(F6<3,"Низкая товарная заменяемость","Нет")))) -> Нет | P6: =IF(N6="","",IF(O6="Недостаточно данных","Недостаточно данных",IF(OR(D6<3,F6<3),IF(N6>=2.5,"Косвенный конкурент / заменитель",IF(N6>=1.6,"Смежная или потенциальная конкуренция","Не конкурент / объект наблюдения")),IF(N6>=4.2,"Прямой конкурент",IF(N6>=3.4,"Близкий альтернативный конкурент",IF(N6>=2.5,"Косвенный конкурент / заменитель",IF(N6>=1.6,"Смежная или потенциальная конкуренция","Не конкурент / объект наблюдения"))))))) -> Косвенный конкурент / заменитель | R6: =IF(Q6="",P6,Q6) -> Косвенный конкурент / заменитель
A7: K004 | B7: =IFERROR(INDEX('01_Компании'!$B$4:$B$103,MATCH(A7,'01_Компании'!$A$4:$A$103,0)),"") -> Shortcut | C7: =IFERROR(INDEX('01_Компании'!$C$4:$C$103,MATCH(A7,'01_Компании'!$A$4:$A$103,0)),"") -> shortcut.ai | D7: 3 | E7: 4 | F7: 3 | G7: 4 | H7: 3 | I7: 4 | J7: 4 | K7: 4 | L7: 3 | M7: 3 | N7: =IF(COUNTA(D7:M7)=0,"",MMULT(D7:M7,'03_Критерии'!$E$4:$E$13)/SUM('03_Критерии'!$E$4:$E$13)) -> 3.47 | O7: =IF(N7="","",IF(COUNTA(D7:M7)<6,"Недостаточно данных",IF(D7<3,"Низкое совпадение задачи",IF(F7<3,"Низкая товарная заменяемость","Нет")))) -> Нет | P7: =IF(N7="","",IF(O7="Недостаточно данных","Недостаточно данных",IF(OR(D7<3,F7<3),IF(N7>=2.5,"Косвенный конкурент / заменитель",IF(N7>=1.6,"Смежная или потенциальная конкуренция","Не конкурент / объект наблюдения")),IF(N7>=4.2,"Прямой конкурент",IF(N7>=3.4,"Близкий альтернативный конкурент",IF(N7>=2.5,"Косвенный конкурент / заменитель",IF(N7>=1.6,"Смежная или потенциальная конкуренция","Не конкурент / объект наблюдения"))))))) -> Близкий альтернативный конкурент | R7: =IF(Q7="",P7,Q7) -> Близкий альтернативный конкурент
A8: K005 | B8: =IFERROR(INDEX('01_Компании'!$B$4:$B$103,MATCH(A8,'01_Компании'!$A$4:$A$103,0)),"") -> Numerous.ai | C8: =IFERROR(INDEX('01_Компании'!$C$4:$C$103,MATCH(A8,'01_Компании'!$A$4:$A$103,0)),"") -> numerous.ai | D8: 2 | E8: 2 | F8: 2 | G8: 2 | H8: 5 | I8: 4 | J8: 4 | K8: 3 | L8: 2 | M8: 2 | N8: =IF(COUNTA(D8:M8)=0,"",MMULT(D8:M8,'03_Критерии'!$E$4:$E$13)/SUM('03_Критерии'!$E$4:$E$13)) -> 2.61 | O8: =IF(N8="","",IF(COUNTA(D8:M8)<6,"Недостаточно данных",IF(D8<3,"Низкое совпадение задачи",IF(F8<3,"Низкая товарная заменяемость","Нет")))) -> Низкое совпадение задачи | P8: =IF(N8="","",IF(O8="Недостаточно данных","Недостаточно данных",IF(OR(D8<3,F8<3),IF(N8>=2.5,"Косвенный конкурент / заменитель",IF(N8>=1.6,"Смежная или потенциальная конкуренция","Не конкурент / объект наблюдения")),IF(N8>=4.2,"Прямой конкурент",IF(N8>=3.4,"Близкий альтернативный конкурент",IF(N8>=2.5,"Косвенный конкурент / заменитель",IF(N8>=1.6,"Смежная или потенциальная конкуренция","Не конкурент / объект наблюдения"))))))) -> Косвенный конкурент / заменитель | R8: =IF(Q8="",P8,Q8) -> Косвенный конкурент / заменитель
A9: K006 | B9: =IFERROR(INDEX('01_Компании'!$B$4:$B$103,MATCH(A9,'01_Компании'!$A$4:$A$103,0)),"") -> Datarails | C9: =IFERROR(INDEX('01_Компании'!$C$4:$C$103,MATCH(A9,'01_Компании'!$A$4:$A$103,0)),"") -> datarails.com | D9: 2 | E9: 3 | F9: 2 | G9: 3 | H9: 2 | I9: 3 | J9: 4 | K9: 5 | L9: 4 | M9: 5 | N9: =IF(COUNTA(D9:M9)=0,"",MMULT(D9:M9,'03_Критерии'!$E$4:$E$13)/SUM('03_Критерии'!$E$4:$E$13)) -> 2.85 | O9: =IF(N9="","",IF(COUNTA(D9:M9)<6,"Недостаточно данных",IF(D9<3,"Низкое совпадение задачи",IF(F9<3,"Низкая товарная заменяемость","Нет")))) -> Низкое совпадение задачи | P9: =IF(N9="","",IF(O9="Недостаточно данных","Недостаточно данных",IF(OR(D9<3,F9<3),IF(N9>=2.5,"Косвенный конкурент / заменитель",IF(N9>=1.6,"Смежная или потенциальная конкуренция","Не конкурент / объект наблюдения")),IF(N9>=4.2,"Прямой конкурент",IF(N9>=3.4,"Близкий альтернативный конкурент",IF(N9>=2.5,"Косвенный конкурент / заменитель",IF(N9>=1.6,"Смежная или потенциальная конкуренция","Не конкурент / объект наблюдения"))))))) -> Косвенный конкурент / заменитель | R9: =IF(Q9="",P9,Q9) -> Косвенный конкурент / заменитель
A10: K007 | B10: =IFERROR(INDEX('01_Компании'!$B$4:$B$103,MATCH(A10,'01_Компании'!$A$4:$A$103,0)),"") -> DataSnipper | C10: =IFERROR(INDEX('01_Компании'!$C$4:$C$103,MATCH(A10,'01_Компании'!$A$4:$A$103,0)),"") -> datasnipper.com | D10: 3 | E10: 3 | F10: 2 | G10: 3 | H10: 2 | I10: 3 | J10: 4 | K10: 5 | L10: 4 | M10: 4 | N10: =IF(COUNTA(D10:M10)=0,"",MMULT(D10:M10,'03_Критерии'!$E$4:$E$13)/SUM('03_Критерии'!$E$4:$E$13)) -> 3.02 | O10: =IF(N10="","",IF(COUNTA(D10:M10)<6,"Недостаточно данных",IF(D10<3,"Низкое совпадение задачи",IF(F10<3,"Низкая товарная заменяемость","Нет")))) -> Низкая товарная заменяемость | P10: =IF(N10="","",IF(O10="Недостаточно данных","Недостаточно данных",IF(OR(D10<3,F10<3),IF(N10>=2.5,"Косвенный конкурент / заменитель",IF(N10>=1.6,"Смежная или потенциальная конкуренция","Не конкурент / объект наблюдения")),IF(N10>=4.2,"Прямой конкурент",IF(N10>=3.4,"Близкий альтернативный конкурент",IF(N10>=2.5,"Косвенный конкурент / заменитель",IF(N10>=1.6,"Смежная или потенциальная конкуренция","Не конкурент / объект наблюдения"))))))) -> Косвенный конкурент / заменитель | R10: =IF(Q10="",P10,Q10) -> Косвенный конкурент / заменитель
A11: K008 | B11: =IFERROR(INDEX('01_Компании'!$B$4:$B$103,MATCH(A11,'01_Компании'!$A$4:$A$103,0)),"") -> Rows | C11: =IFERROR(INDEX('01_Компании'!$C$4:$C$103,MATCH(A11,'01_Компании'!$A$4:$A$103,0)),"") -> rows.com | D11: 1 | E11: 2 | F11: 2 | G11: 2 | H11: 5 | I11: 4 | J11: 4 | K11: 4 | L11: 3 | M11: 2 | N11: =IF(COUNTA(D11:M11)=0,"",MMULT(D11:M11,'03_Критерии'!$E$4:$E$13)/SUM('03_Критерии'!$E$4:$E$13)) -> 2.52 | O11: =IF(N11="","",IF(COUNTA(D11:M11)<6,"Недостаточно данных",IF(D11<3,"Низкое совпадение задачи",IF(F11<3,"Низкая товарная заменяемость","Нет")))) -> Низкое совпадение задачи | P11: =IF(N11="","",IF(O11="Недостаточно данных","Недостаточно данных",IF(OR(D11<3,F11<3),IF(N11>=2.5,"Косвенный конкурент / заменитель",IF(N11>=1.6,"Смежная или потенциальная конкуренция","Не конкурент / объект наблюдения")),IF(N11>=4.2,"Прямой конкурент",IF(N11>=3.4,"Близкий альтернативный конкурент",IF(N11>=2.5,"Косвенный конкурент / заменитель",IF(N11>=1.6,"Смежная или потенциальная конкуренция","Не конкурент / объект наблюдения"))))))) -> Косвенный конкурент / заменитель | R11: =IF(Q11="",P11,Q11) -> Косвенный конкурент / заменитель
A12: K009 | B12: =IFERROR(INDEX('01_Компании'!$B$4:$B$103,MATCH(A12,'01_Компании'!$A$4:$A$103,0)),"") -> Formula Bot | C12: =IFERROR(INDEX('01_Компании'!$C$4:$C$103,MATCH(A12,'01_Компании'!$A$4:$A$103,0)),"") -> formulabot.com | D12: 2 | E12: 2 | F12: 2 | G12: 2 | H12: 5 | I12: 4 | J12: 4 | K12: 3 | L12: 2 | M12: 1 | N12: =IF(COUNTA(D12:M12)=0,"",MMULT(D12:M12,'03_Критерии'!$E$4:$E$13)/SUM('03_Критерии'!$E$4:$E$13)) -> 2.58 | O12: =IF(N12="","",IF(COUNTA(D12:M12)<6,"Недостаточно данных",IF(D12<3,"Низкое совпадение задачи",IF(F12<3,"Низкая товарная заменяемость","Нет")))) -> Низкое совпадение задачи | P12: =IF(N12="","",IF(O12="Недостаточно данных","Недостаточно данных",IF(OR(D12<3,F12<3),IF(N12>=2.5,"Косвенный конкурент / заменитель",IF(N12>=1.6,"Смежная или потенциальная конкуренция","Не конкурент / объект наблюдения")),IF(N12>=4.2,"Прямой конкурент",IF(N12>=3.4,"Близкий альтернативный конкурент",IF(N12>=2.5,"Косвенный конкурент / заменитель",IF(N12>=1.6,"Смежная или потенциальная конкуренция","Не конкурент / объект наблюдения"))))))) -> Косвенный конкурент / заменитель | R12: =IF(Q12="",P12,Q12) -> Косвенный конкурент / заменитель
A13: K010 | B13: =IFERROR(INDEX('01_Компании'!$B$4:$B$103,MATCH(A13,'01_Компании'!$A$4:$A$103,0)),"") -> Microsoft 365 Copilot | C13: =IFERROR(INDEX('01_Компании'!$C$4:$C$103,MATCH(A13,'01_Компании'!$A$4:$A$103,0)),"") -> microsoft.com/microsoft-365-copilot | D13: 3 | E13: 5 | F13: 3 | G13: 3 | H13: 3 | I13: 5 | J13: 5 | K13: 5 | L13: 5 | M13: 5 | N13: =IF(COUNTA(D13:M13)=0,"",MMULT(D13:M13,'03_Критерии'!$E$4:$E$13)/SUM('03_Критерии'!$E$4:$E$13)) -> 3.88 | O13: =IF(N13="","",IF(COUNTA(D13:M13)<6,"Недостаточно данных",IF(D13<3,"Низкое совпадение задачи",IF(F13<3,"Низкая товарная заменяемость","Нет")))) -> Нет | P13: =IF(N13="","",IF(O13="Недостаточно данных","Недостаточно данных",IF(OR(D13<3,F13<3),IF(N13>=2.5,"Косвенный конкурент / заменитель",IF(N13>=1.6,"Смежная или потенциальная конкуренция","Не конкурент / объект наблюдения")),IF(N13>=4.2,"Прямой конкурент",IF(N13>=3.4,"Близкий альтернативный конкурент",IF(N13>=2.5,"Косвенный конкурент / заменитель",IF(N13>=1.6,"Смежная или потенциальная конкуренция","Не конкурент / объект наблюдения"))))))) -> Близкий альтернативный конкурент | R13: =IF(Q13="",P13,Q13) -> Близкий альтернативный конкурент
A14: K011 | B14: =IFERROR(INDEX('01_Компании'!$B$4:$B$103,MATCH(A14,'01_Компании'!$A$4:$A$103,0)),"") -> 0 | C14: =IFERROR(INDEX('01_Компании'!$C$4:$C$103,MATCH(A14,'01_Компании'!$A$4:$A$103,0)),"") -> 0 | N14: =IF(COUNTA(D14:M14)=0,"",MMULT(D14:M14,'03_Критерии'!$E$4:$E$13)/SUM('03_Критерии'!$E$4:$E$13)) | O14: =IF(N14="","",IF(COUNTA(D14:M14)<6,"Недостаточно данных",IF(D14<3,"Низкое совпадение задачи",IF(F14<3,"Низкая товарная заменяемость","Нет")))) | P14: =IF(N14="","",IF(O14="Недостаточно данных","Недостаточно данных",IF(OR(D14<3,F14<3),IF(N14>=2.5,"Косвенный конкурент / заменитель",IF(N14>=1.6,"Смежная или потенциальная конкуренция","Не конкурент / объект наблюдения")),IF(N14>=4.2,"Прямой конкурент",IF(N14>=3.4,"Близкий альтернативный конкурент",IF(N14>=2.5,"Косвенный конкурент / заменитель",IF(N14>=1.6,"Смежная или потенциальная конкуренция","Не конкурент / объект наблюдения"))))))) | R14: =IF(Q14="",P14,Q14)
A15: K012 | B15: =IFERROR(INDEX('01_Компании'!$B$4:$B$103,MATCH(A15,'01_Компании'!$A$4:$A$103,0)),"") -> 0 | C15: =IFERROR(INDEX('01_Компании'!$C$4:$C$103,MATCH(A15,'01_Компании'!$A$4:$A$103,0)),"") -> 0 | N15: =IF(COUNTA(D15:M15)=0,"",MMULT(D15:M15,'03_Критерии'!$E$4:$E$13)/SUM('03_Критерии'!$E$4:$E$13)) | O15: =IF(N15="","",IF(COUNTA(D15:M15)<6,"Недостаточно данных",IF(D15<3,"Низкое совпадение задачи",IF(F15<3,"Низкая товарная заменяемость","Нет")))) | P15: =IF(N15="","",IF(O15="Недостаточно данных","Недостаточно данных",IF(OR(D15<3,F15<3),IF(N15>=2.5,"Косвенный конкурент / заменитель",IF(N15>=1.6,"Смежная или потенциальная конкуренция","Не конкурент / объект наблюдения")),IF(N15>=4.2,"Прямой конкурент",IF(N15>=3.4,"Близкий альтернативный конкурент",IF(N15>=2.5,"Косвенный конкурент / заменитель",IF(N15>=1.6,"Смежная или потенциальная конкуренция","Не конкурент / объект наблюдения"))))))) | R15: =IF(Q15="",P15,Q15)
A16: K013 | B16: =IFERROR(INDEX('01_Компании'!$B$4:$B$103,MATCH(A16,'01_Компании'!$A$4:$A$103,0)),"") -> 0 | C16: =IFERROR(INDEX('01_Компании'!$C$4:$C$103,MATCH(A16,'01_Компании'!$A$4:$A$103,0)),"") -> 0 | N16: =IF(COUNTA(D16:M16)=0,"",MMULT(D16:M16,'03_Критерии'!$E$4:$E$13)/SUM('03_Критерии'!$E$4:$E$13)) | O16: =IF(N16="","",IF(COUNTA(D16:M16)<6,"Недостаточно данных",IF(D16<3,"Низкое совпадение задачи",IF(F16<3,"Низкая товарная заменяемость","Нет")))) | P16: =IF(N16="","",IF(O16="Недостаточно данных","Недостаточно данных",IF(OR(D16<3,F16<3),IF(N16>=2.5,"Косвенный конкурент / заменитель",IF(N16>=1.6,"Смежная или потенциальная конкуренция","Не конкурент / объект наблюдения")),IF(N16>=4.2,"Прямой конкурент",IF(N16>=3.4,"Близкий альтернативный конкурент",IF(N16>=2.5,"Косвенный конкурент / заменитель",IF(N16>=1.6,"Смежная или потенциальная конкуренция","Не конкурент / объект наблюдения"))))))) | R16: =IF(Q16="",P16,Q16)
A17: K014 | B17: =IFERROR(INDEX('01_Компании'!$B$4:$B$103,MATCH(A17,'01_Компании'!$A$4:$A$103,0)),"") -> 0 | C17: =IFERROR(INDEX('01_Компании'!$C$4:$C$103,MATCH(A17,'01_Компании'!$A$4:$A$103,0)),"") -> 0 | N17: =IF(COUNTA(D17:M17)=0,"",MMULT(D17:M17,'03_Критерии'!$E$4:$E$13)/SUM('03_Критерии'!$E$4:$E$13)) | O17: =IF(N17="","",IF(COUNTA(D17:M17)<6,"Недостаточно данных",IF(D17<3,"Низкое совпадение задачи",IF(F17<3,"Низкая товарная заменяемость","Нет")))) | P17: =IF(N17="","",IF(O17="Недостаточно данных","Недостаточно данных",IF(OR(D17<3,F17<3),IF(N17>=2.5,"Косвенный конкурент / заменитель",IF(N17>=1.6,"Смежная или потенциальная конкуренция","Не конкурент / объект наблюдения")),IF(N17>=4.2,"Прямой конкурент",IF(N17>=3.4,"Близкий альтернативный конкурент",IF(N17>=2.5,"Косвенный конкурент / заменитель",IF(N17>=1.6,"Смежная или потенциальная конкуренция","Не конкурент / объект наблюдения"))))))) | R17: =IF(Q17="",P17,Q17)
A18: K015 | B18: =IFERROR(INDEX('01_Компании'!$B$4:$B$103,MATCH(A18,'01_Компании'!$A$4:$A$103,0)),"") -> 0 | C18: =IFERROR(INDEX('01_Компании'!$C$4:$C$103,MATCH(A18,'01_Компании'!$A$4:$A$103,0)),"") -> 0 | N18: =IF(COUNTA(D18:M18)=0,"",MMULT(D18:M18,'03_Критерии'!$E$4:$E$13)/SUM('03_Критерии'!$E$4:$E$13)) | O18: =IF(N18="","",IF(COUNTA(D18:M18)<6,"Недостаточно данных",IF(D18<3,"Низкое совпадение задачи",IF(F18<3,"Низкая товарная заменяемость","Нет")))) | P18: =IF(N18="","",IF(O18="Недостаточно данных","Недостаточно данных",IF(OR(D18<3,F18<3),IF(N18>=2.5,"Косвенный конкурент / заменитель",IF(N18>=1.6,"Смежная или потенциальная конкуренция","Не конкурент / объект наблюдения")),IF(N18>=4.2,"Прямой конкурент",IF(N18>=3.4,"Близкий альтернативный конкурент",IF(N18>=2.5,"Косвенный конкурент / заменитель",IF(N18>=1.6,"Смежная или потенциальная конкуренция","Не конкурент / объект наблюдения"))))))) | R18: =IF(Q18="",P18,Q18)
A19: K016 | B19: =IFERROR(INDEX('01_Компании'!$B$4:$B$103,MATCH(A19,'01_Компании'!$A$4:$A$103,0)),"") -> 0 | C19: =IFERROR(INDEX('01_Компании'!$C$4:$C$103,MATCH(A19,'01_Компании'!$A$4:$A$103,0)),"") -> 0 | N19: =IF(COUNTA(D19:M19)=0,"",MMULT(D19:M19,'03_Критерии'!$E$4:$E$13)/SUM('03_Критерии'!$E$4:$E$13)) | O19: =IF(N19="","",IF(COUNTA(D19:M19)<6,"Недостаточно данных",IF(D19<3,"Низкое совпадение задачи",IF(F19<3,"Низкая товарная заменяемость","Нет")))) | P19: =IF(N19="","",IF(O19="Недостаточно данных","Недостаточно данных",IF(OR(D19<3,F19<3),IF(N19>=2.5,"Косвенный конкурент / заменитель",IF(N19>=1.6,"Смежная или потенциальная конкуренция","Не конкурент / объект наблюдения")),IF(N19>=4.2,"Прямой конкурент",IF(N19>=3.4,"Близкий альтернативный конкурент",IF(N19>=2.5,"Косвенный конкурент / заменитель",IF(N19>=1.6,"Смежная или потенциальная конкуренция","Не конкурент / объект наблюдения"))))))) | R19: =IF(Q19="",P19,Q19)
A20: K017 | B20: =IFERROR(INDEX('01_Компании'!$B$4:$B$103,MATCH(A20,'01_Компании'!$A$4:$A$103,0)),"") -> 0 | C20: =IFERROR(INDEX('01_Компании'!$C$4:$C$103,MATCH(A20,'01_Компании'!$A$4:$A$103,0)),"") -> 0 | N20: =IF(COUNTA(D20:M20)=0,"",MMULT(D20:M20,'03_Критерии'!$E$4:$E$13)/SUM('03_Критерии'!$E$4:$E$13)) | O20: =IF(N20="","",IF(COUNTA(D20:M20)<6,"Недостаточно данных",IF(D20<3,"Низкое совпадение задачи",IF(F20<3,"Низкая товарная заменяемость","Нет")))) | P20: =IF(N20="","",IF(O20="Недостаточно данных","Недостаточно данных",IF(OR(D20<3,F20<3),IF(N20>=2.5,"Косвенный конкурент / заменитель",IF(N20>=1.6,"Смежная или потенциальная конкуренция","Не конкурент / объект наблюдения")),IF(N20>=4.2,"Прямой конкурент",IF(N20>=3.4,"Близкий альтернативный конкурент",IF(N20>=2.5,"Косвенный конкурент / заменитель",IF(N20>=1.6,"Смежная или потенциальная конкуренция","Не конкурент / объект наблюдения"))))))) | R20: =IF(Q20="",P20,Q20)
A21: K018 | B21: =IFERROR(INDEX('01_Компании'!$B$4:$B$103,MATCH(A21,'01_Компании'!$A$4:$A$103,0)),"") -> 0 | C21: =IFERROR(INDEX('01_Компании'!$C$4:$C$103,MATCH(A21,'01_Компании'!$A$4:$A$103,0)),"") -> 0 | N21: =IF(COUNTA(D21:M21)=0,"",MMULT(D21:M21,'03_Критерии'!$E$4:$E$13)/SUM('03_Критерии'!$E$4:$E$13)) | O21: =IF(N21="","",IF(COUNTA(D21:M21)<6,"Недостаточно данных",IF(D21<3,"Низкое совпадение задачи",IF(F21<3,"Низкая товарная заменяемость","Нет")))) | P21: =IF(N21="","",IF(O21="Недостаточно данных","Недостаточно данных",IF(OR(D21<3,F21<3),IF(N21>=2.5,"Косвенный конкурент / заменитель",IF(N21>=1.6,"Смежная или потенциальная конкуренция","Не конкурент / объект наблюдения")),IF(N21>=4.2,"Прямой конкурент",IF(N21>=3.4,"Близкий альтернативный конкурент",IF(N21>=2.5,"Косвенный конкурент / заменитель",IF(N21>=1.6,"Смежная или потенциальная конкуренция","Не конкурент / объект наблюдения"))))))) | R21: =IF(Q21="",P21,Q21)
A22: K019 | B22: =IFERROR(INDEX('01_Компании'!$B$4:$B$103,MATCH(A22,'01_Компании'!$A$4:$A$103,0)),"") -> 0 | C22: =IFERROR(INDEX('01_Компании'!$C$4:$C$103,MATCH(A22,'01_Компании'!$A$4:$A$103,0)),"") -> 0 | N22: =IF(COUNTA(D22:M22)=0,"",MMULT(D22:M22,'03_Критерии'!$E$4:$E$13)/SUM('03_Критерии'!$E$4:$E$13)) | O22: =IF(N22="","",IF(COUNTA(D22:M22)<6,"Недостаточно данных",IF(D22<3,"Низкое совпадение задачи",IF(F22<3,"Низкая товарная заменяемость","Нет")))) | P22: =IF(N22="","",IF(O22="Недостаточно данных","Недостаточно данных",IF(OR(D22<3,F22<3),IF(N22>=2.5,"Косвенный конкурент / заменитель",IF(N22>=1.6,"Смежная или потенциальная конкуренция","Не конкурент / объект наблюдения")),IF(N22>=4.2,"Прямой конкурент",IF(N22>=3.4,"Близкий альтернативный конкурент",IF(N22>=2.5,"Косвенный конкурент / заменитель",IF(N22>=1.6,"Смежная или потенциальная конкуренция","Не конкурент / объект наблюдения"))))))) | R22: =IF(Q22="",P22,Q22)
A23: K020 | B23: =IFERROR(INDEX('01_Компании'!$B$4:$B$103,MATCH(A23,'01_Компании'!$A$4:$A$103,0)),"") -> 0 | C23: =IFERROR(INDEX('01_Компании'!$C$4:$C$103,MATCH(A23,'01_Компании'!$A$4:$A$103,0)),"") -> 0 | N23: =IF(COUNTA(D23:M23)=0,"",MMULT(D23:M23,'03_Критерии'!$E$4:$E$13)/SUM('03_Критерии'!$E$4:$E$13)) | O23: =IF(N23="","",IF(COUNTA(D23:M23)<6,"Недостаточно данных",IF(D23<3,"Низкое совпадение задачи",IF(F23<3,"Низкая товарная заменяемость","Нет")))) | P23: =IF(N23="","",IF(O23="Недостаточно данных","Недостаточно данных",IF(OR(D23<3,F23<3),IF(N23>=2.5,"Косвенный конкурент / заменитель",IF(N23>=1.6,"Смежная или потенциальная конкуренция","Не конкурент / объект наблюдения")),IF(N23>=4.2,"Прямой конкурент",IF(N23>=3.4,"Близкий альтернативный конкурент",IF(N23>=2.5,"Косвенный конкурент / заменитель",IF(N23>=1.6,"Смежная или потенциальная конкуренция","Не конкурент / объект наблюдения"))))))) | R23: =IF(Q23="",P23,Q23)
A24: K021 | B24: =IFERROR(INDEX('01_Компании'!$B$4:$B$103,MATCH(A24,'01_Компании'!$A$4:$A$103,0)),"") -> 0 | C24: =IFERROR(INDEX('01_Компании'!$C$4:$C$103,MATCH(A24,'01_Компании'!$A$4:$A$103,0)),"") -> 0 | N24: =IF(COUNTA(D24:M24)=0,"",MMULT(D24:M24,'03_Критерии'!$E$4:$E$13)/SUM('03_Критерии'!$E$4:$E$13)) | O24: =IF(N24="","",IF(COUNTA(D24:M24)<6,"Недостаточно данных",IF(D24<3,"Низкое совпадение задачи",IF(F24<3,"Низкая товарная заменяемость","Нет")))) | P24: =IF(N24="","",IF(O24="Недостаточно данных","Недостаточно данных",IF(OR(D24<3,F24<3),IF(N24>=2.5,"Косвенный конкурент / заменитель",IF(N24>=1.6,"Смежная или потенциальная конкуренция","Не конкурент / объект наблюдения")),IF(N24>=4.2,"Прямой конкурент",IF(N24>=3.4,"Близкий альтернативный конкурент",IF(N24>=2.5,"Косвенный конкурент / заменитель",IF(N24>=1.6,"Смежная или потенциальная конкуренция","Не конкурент / объект наблюдения"))))))) | R24: =IF(Q24="",P24,Q24)
A25: K022 | B25: =IFERROR(INDEX('01_Компании'!$B$4:$B$103,MATCH(A25,'01_Компании'!$A$4:$A$103,0)),"") -> 0 | C25: =IFERROR(INDEX('01_Компании'!$C$4:$C$103,MATCH(A25,'01_Компании'!$A$4:$A$103,0)),"") -> 0 | N25: =IF(COUNTA(D25:M25)=0,"",MMULT(D25:M25,'03_Критерии'!$E$4:$E$13)/SUM('03_Критерии'!$E$4:$E$13)) | O25: =IF(N25="","",IF(COUNTA(D25:M25)<6,"Недостаточно данных",IF(D25<3,"Низкое совпадение задачи",IF(F25<3,"Низкая товарная заменяемость","Нет")))) | P25: =IF(N25="","",IF(O25="Недостаточно данных","Недостаточно данных",IF(OR(D25<3,F25<3),IF(N25>=2.5,"Косвенный конкурент / заменитель",IF(N25>=1.6,"Смежная или потенциальная конкуренция","Не конкурент / объект наблюдения")),IF(N25>=4.2,"Прямой конкурент",IF(N25>=3.4,"Близкий альтернативный конкурент",IF(N25>=2.5,"Косвенный конкурент / заменитель",IF(N25>=1.6,"Смежная или потенциальная конкуренция","Не конкурент / объект наблюдения"))))))) | R25: =IF(Q25="",P25,Q25)
... A103: K100 | B103: =IFERROR(INDEX('01_Компании'!$B$4:$B$103,MATCH(A103,'01_Компании'!$A$4:$A$103,0)),"") -> 0 | C103: =IFERROR(INDEX('01_Компании'!$C$4:$C$103,MATCH(A103,'01_Компании'!$A$4:$A$103,0)),"") -> 0 | N103: =IF(COUNTA(D103:M103)=0,"",MMULT(D103:M103,'03_Критерии'!$E$4:$E$13)/SUM('03_Критерии'!$E$4:$E$13)) | O103: =IF(N103="","",IF(COUNTA(D103:M103)<6,"Недостаточно данных",IF(D103<3,"Низкое совпадение задачи",IF(F103<3,"Низкая товарная заменяемость","Нет")))) | P103: =IF(N103="","",IF(O103="Недостаточно данных","Недостаточно данных",IF(OR(D103<3,F103<3),IF(N103>=2.5,"Косвенный конкурент / заменитель",IF(N103>=1.6,"Смежная или потенциальная конкуренция","Не конкурент / объект наблюдения")),IF(N103>=4.2,"Прямой конкурент",IF(N103>=3.4,"Близкий альтернативный конкурент",IF(N103>=2.5,"Косвенный конкурент / заменитель",IF(N103>=1.6,"Смежная или потенциальная конкуренция","Не конкурент / объект наблюдения"))))))) | R103: =IF(Q103="",P103,Q103)

Sheet 05_Уровни
A1: Классификация компаний по уровням конкуренции | B1: Классификация компаний по уровням конкуренции | C1: Классификация компаний по уровням конкуренции | D1: Классификация компаний по уровням конкуренции | E1: Классификация компаний по уровням конкуренции | F1: Классификация компаний по уровням конкуренции | G1: Классификация компаний по уровням конкуренции
A3: Уровень | B3: Определение | C3: Ключевой критерий | D3: Порог по баллу | E3: Обязательные условия | F3: Типовые признаки на сайте | G3: Решение аналитика
A4: Прямой конкурент | B4: Компания удовлетворяет ту же потребительскую задачу для той же или близкой аудитории сопоставимым цифровым товаром. | C4: Высокая заменяемость товара и совпадение целевого сегмента. | D4: 4,20–5,00 | E4: Потребительская задача ≥ 3; функциональная заменяемость ≥ 3. | F4: Сходные тарифы, сценарии использования, обещания результата, демонстрации товара, одинаковые категории клиентов. | G4: Включить в постоянный конкурентный мониторинг.
A5: Близкий альтернативный конкурент | B5: Компания решает ту же или близкую задачу, но делает это через иной формат товара, канал, сегмент или модель оплаты. | C5: Клиент может рассматривать решение как практическую альтернативу. | D5: 3,40–4,19 | E5: Нет критического расхождения по потребительской задаче. | F5: Похожие выгоды, частично отличающаяся функциональность, иной формат доступа, другая тарифная логика. | G5: Сравнивать по ценностному предложению и причинам выбора.
A6: Косвенный конкурент / заменитель | B6: Компания закрывает ту же потребность и может заменить покупку, но товарная категория или способ решения заметно отличаются. | C6: Есть конкуренция за бюджет, внимание или способ выполнения задачи. | D6: 2,50–3,39 | E6: Достаточно доказательств заменяемости. | F6: Иные продукты, услуги или платформы, которые дают сходный конечный результат. | G6: Анализировать как угрозу замещения.
A7: Смежная или потенциальная конкуренция | B7: Компания пока не является прямым конкурентом, но имеет близкую аудиторию, смежный товар, инфраструктуру или возможность расшириться в рассматриваемый рынок. | C7: Вероятность входа в рынок или расширения товарной линейки. | D7: 1,60–2,49 | E7: Наличие хотя бы одного сильного сигнала пересечения. | F7: Смежные разделы сайта, близкие категории клиентов, партнерства, вакансии, дорожная карта, упоминания планов развития. | G7: Наблюдать периодически; не смешивать с прямыми конкурентами.
A8: Не конкурент / объект наблюдения | B8: Компания не показывает значимого пересечения по задаче, аудитории, товару и заменяемости. | C8: Недостаточная рыночная и товарная близость. | D8: 0,00–1,59 | E8: Нет значимых доказательств конкуренции. | F8: Общее сходство отрасли без совпадения задачи и товара. | G8: Исключить из основной матрицы, оставить только при методической необходимости.
A9: Недостаточно данных | B9: По сайту невозможно надежно установить уровень конкуренции. | C9: Недостаток фактов или противоречивые сигналы. | D9: не применяется | E9: Менее трех содержательных доказательств. | F9: Закрытые тарифы, неполные описания, отсутствие страниц товара, нет сегментации клиентов. | G9: Вернуться к анализу после сбора дополнительных источников.

Sheet 06_Сводка
A1: Сводка классификации компаний по уровням конкуренции | B1: Сводка классификации компаний по уровням конкуренции | C1: Сводка классификации компаний по уровням конкуренции | D1: Сводка классификации компаний по уровням конкуренции | E1: Сводка классификации компаний по уровням конкуренции | F1: Сводка классификации компаний по уровням конкуренции | G1: Сводка классификации компаний по уровням конкуренции | H1: Сводка классификации компаний по уровням конкуренции | I1: Сводка классификации компаний по уровням конкуренции | J1: Сводка классификации компаний по уровням конкуренции
A3: Показатель | B3: Значение
A4: Всего компаний в реестре | B4: =COUNTA('01_Компании'!$B$4:$B$103) -> 10
A5: Компаний с заполненной оценкой | B5: =COUNT('04_Оценка'!$N$4:$N$103) -> 10
A6: Средний взвешенный балл | B6: =IFERROR(AVERAGE('04_Оценка'!$N$4:$N$103),"") -> 3.153
A7: Компаний с уровнем «Прямой конкурент» | B7: =COUNTIF('04_Оценка'!$R$4:$R$103,"Прямой конкурент") -> 0
A8: Компаний с уровнем «Близкий альтернативный конкурент» | B8: =COUNTIF('04_Оценка'!$R$4:$R$103,"Близкий альтернативный конкурент") -> 4
A10: Уровень конкуренции | B10: Количество | C10: Доля | D10: Методическое действие
A11: Прямой конкурент | B11: =COUNTIF('04_Оценка'!$R$4:$R$103,A11) -> 0 | C11: =IFERROR(B11/SUM($B$11:$B$16),0) -> 0 | D11: Включить в основной бенчмарк и регулярный мониторинг
A12: Близкий альтернативный конкурент | B12: =COUNTIF('04_Оценка'!$R$4:$R$103,A12) -> 4 | C12: =IFERROR(B12/SUM($B$11:$B$16),0) -> 0.4 | D12: Сравнивать по причинам выбора и формату ценности
A13: Косвенный конкурент / заменитель | B13: =COUNTIF('04_Оценка'!$R$4:$R$103,A13) -> 6 | C13: =IFERROR(B13/SUM($B$11:$B$16),0) -> 0.6 | D13: Оценивать угрозу замещения и конкуренцию за бюджет
A14: Смежная или потенциальная конкуренция | B14: =COUNTIF('04_Оценка'!$R$4:$R$103,A14) -> 0 | C14: =IFERROR(B14/SUM($B$11:$B$16),0) -> 0 | D14: Наблюдать по сигналам расширения
A15: Не конкурент / объект наблюдения | B15: =COUNTIF('04_Оценка'!$R$4:$R$103,A15) -> 0 | C15: =IFERROR(B15/SUM($B$11:$B$16),0) -> 0 | D15: Исключить из основной матрицы
A16: Недостаточно данных | B16: =COUNTIF('04_Оценка'!$R$4:$R$103,A16) -> 0 | C16: =IFERROR(B16/SUM($B$11:$B$16),0) -> 0 | D16: Дособрать доказательства
A18: Топ компаний по близости к прямой конкуренции | B18: Компания | C18: Сайт | D18: Бал | E18: Итоговый уровень | F18: Обоснование
A19: 1 | B19: =IF(D19="","",INDEX('04_Оценка'!$B$4:$B$103,MATCH(D19,'04_Оценка'!$N$4:$N$103,0))) -> PerfectXL | C19: =IF(D19="","",INDEX('04_Оценка'!$C$4:$C$103,MATCH(D19,'04_Оценка'!$N$4:$N$103,0))) -> perfectxl.com | D19: =IFERROR(LARGE('04_Оценка'!$N$4:$N$103,A19),"") -> 4.11 | E19: =IF(D19="","",INDEX('04_Оценка'!$R$4:$R$103,MATCH(D19,'04_Оценка'!$N$4:$N$103,0))) -> Близкий альтернативный конкурент | F19: =IF(D19="","",INDEX('04_Оценка'!$T$4:$T$103,MATCH(D19,'04_Оценка'!$N$4:$N$103,0))) -> 0
A20: 2 | B20: =IF(D20="","",INDEX('04_Оценка'!$B$4:$B$103,MATCH(D20,'04_Оценка'!$N$4:$N$103,0))) -> Microsoft 365 Copilot | C20: =IF(D20="","",INDEX('04_Оценка'!$C$4:$C$103,MATCH(D20,'04_Оценка'!$N$4:$N$103,0))) -> microsoft.com/microsoft-365-copilot | D20: =IFERROR(LARGE('04_Оценка'!$N$4:$N$103,A20),"") -> 3.88 | E20: =IF(D20="","",INDEX('04_Оценка'!$R$4:$R$103,MATCH(D20,'04_Оценка'!$N$4:$N$103,0))) -> Близкий альтернативный конкурент | F20: =IF(D20="","",INDEX('04_Оценка'!$T$4:$T$103,MATCH(D20,'04_Оценка'!$N$4:$N$103,0))) -> 0
A21: 3 | B21: =IF(D21="","",INDEX('04_Оценка'!$B$4:$B$103,MATCH(D21,'04_Оценка'!$N$4:$N$103,0))) -> Shortcut | C21: =IF(D21="","",INDEX('04_Оценка'!$C$4:$C$103,MATCH(D21,'04_Оценка'!$N$4:$N$103,0))) -> shortcut.ai | D21: =IFERROR(LARGE('04_Оценка'!$N$4:$N$103,A21),"") -> 3.47 | E21: =IF(D21="","",INDEX('04_Оценка'!$R$4:$R$103,MATCH(D21,'04_Оценка'!$N$4:$N$103,0))) -> Близкий альтернативный конкурент | F21: =IF(D21="","",INDEX('04_Оценка'!$T$4:$T$103,MATCH(D21,'04_Оценка'!$N$4:$N$103,0))) -> 0
A22: 4 | B22: =IF(D22="","",INDEX('04_Оценка'!$B$4:$B$103,MATCH(D22,'04_Оценка'!$N$4:$N$103,0))) -> Arixcel | C22: =IF(D22="","",INDEX('04_Оценка'!$C$4:$C$103,MATCH(D22,'04_Оценка'!$N$4:$N$103,0))) -> arixcel.com | D22: =IFERROR(LARGE('04_Оценка'!$N$4:$N$103,A22),"") -> 3.44 | E22: =IF(D22="","",INDEX('04_Оценка'!$R$4:$R$103,MATCH(D22,'04_Оценка'!$N$4:$N$103,0))) -> Близкий альтернативный конкурент | F22: =IF(D22="","",INDEX('04_Оценка'!$T$4:$T$103,MATCH(D22,'04_Оценка'!$N$4:$N$103,0))) -> 0
A23: 5 | B23: =IF(D23="","",INDEX('04_Оценка'!$B$4:$B$103,MATCH(D23,'04_Оценка'!$N$4:$N$103,0))) -> Operis | C23: =IF(D23="","",INDEX('04_Оценка'!$C$4:$C$103,MATCH(D23,'04_Оценка'!$N$4:$N$103,0))) -> operis.com | D23: =IFERROR(LARGE('04_Оценка'!$N$4:$N$103,A23),"") -> 3.05 | E23: =IF(D23="","",INDEX('04_Оценка'!$R$4:$R$103,MATCH(D23,'04_Оценка'!$N$4:$N$103,0))) -> Косвенный конкурент / заменитель | F23: =IF(D23="","",INDEX('04_Оценка'!$T$4:$T$103,MATCH(D23,'04_Оценка'!$N$4:$N$103,0))) -> 0
A24: 6 | B24: =IF(D24="","",INDEX('04_Оценка'!$B$4:$B$103,MATCH(D24,'04_Оценка'!$N$4:$N$103,0))) -> DataSnipper | C24: =IF(D24="","",INDEX('04_Оценка'!$C$4:$C$103,MATCH(D24,'04_Оценка'!$N$4:$N$103,0))) -> datasnipper.com | D24: =IFERROR(LARGE('04_Оценка'!$N$4:$N$103,A24),"") -> 3.02 | E24: =IF(D24="","",INDEX('04_Оценка'!$R$4:$R$103,MATCH(D24,'04_Оценка'!$N$4:$N$103,0))) -> Косвенный конкурент / заменитель | F24: =IF(D24="","",INDEX('04_Оценка'!$T$4:$T$103,MATCH(D24,'04_Оценка'!$N$4:$N$103,0))) -> 0
A25: 7 | B25: =IF(D25="","",INDEX('04_Оценка'!$B$4:$B$103,MATCH(D25,'04_Оценка'!$N$4:$N$103,0))) -> Datarails | C25: =IF(D25="","",INDEX('04_Оценка'!$C$4:$C$103,MATCH(D25,'04_Оценка'!$N$4:$N$103,0))) -> datarails.com | D25: =IFERROR(LARGE('04_Оценка'!$N$4:$N$103,A25),"") -> 2.85 | E25: =IF(D25="","",INDEX('04_Оценка'!$R$4:$R$103,MATCH(D25,'04_Оценка'!$N$4:$N$103,0))) -> Косвенный конкурент / заменитель | F25: =IF(D25="","",INDEX('04_Оценка'!$T$4:$T$103,MATCH(D25,'04_Оценка'!$N$4:$N$103,0))) -> 0
A26: 8 | B26: =IF(D26="","",INDEX('04_Оценка'!$B$4:$B$103,MATCH(D26,'04_Оценка'!$N$4:$N$103,0))) -> Numerous.ai | C26: =IF(D26="","",INDEX('04_Оценка'!$C$4:$C$103,MATCH(D26,'04_Оценка'!$N$4:$N$103,0))) -> numerous.ai | D26: =IFERROR(LARGE('04_Оценка'!$N$4:$N$103,A26),"") -> 2.61 | E26: =IF(D26="","",INDEX('04_Оценка'!$R$4:$R$103,MATCH(D26,'04_Оценка'!$N$4:$N$103,0))) -> Косвенный конкурент / заменитель | F26: =IF(D26="","",INDEX('04_Оценка'!$T$4:$T$103,MATCH(D26,'04_Оценка'!$N$4:$N$103,0))) -> 0
A27: 9 | B27: =IF(D27="","",INDEX('04_Оценка'!$B$4:$B$103,MATCH(D27,'04_Оценка'!$N$4:$N$103,0))) -> Formula Bot | C27: =IF(D27="","",INDEX('04_Оценка'!$C$4:$C$103,MATCH(D27,'04_Оценка'!$N$4:$N$103,0))) -> formulabot.com | D27: =IFERROR(LARGE('04_Оценка'!$N$4:$N$103,A27),"") -> 2.58 | E27: =IF(D27="","",INDEX('04_Оценка'!$R$4:$R$103,MATCH(D27,'04_Оценка'!$N$4:$N$103,0))) -> Косвенный конкурент / заменитель | F27: =IF(D27="","",INDEX('04_Оценка'!$T$4:$T$103,MATCH(D27,'04_Оценка'!$N$4:$N$103,0))) -> 0
A28: 10 | B28: =IF(D28="","",INDEX('04_Оценка'!$B$4:$B$103,MATCH(D28,'04_Оценка'!$N$4:$N$103,0))) -> Rows | C28: =IF(D28="","",INDEX('04_Оценка'!$C$4:$C$103,MATCH(D28,'04_Оценка'!$N$4:$N$103,0))) -> rows.com | D28: =IFERROR(LARGE('04_Оценка'!$N$4:$N$103,A28),"") -> 2.52 | E28: =IF(D28="","",INDEX('04_Оценка'!$R$4:$R$103,MATCH(D28,'04_Оценка'!$N$4:$N$103,0))) -> Косвенный конкурент / заменитель | F28: =IF(D28="","",INDEX('04_Оценка'!$T$4:$T$103,MATCH(D28,'04_Оценка'!$N$4:$N$103,0))) -> 0

Sheet 07_Карта
A1: Карта конкурентной близости | B1: Карта конкурентной близости | C1: Карта конкурентной близости | D1: Карта конкурентной близости | E1: Карта конкурентной близости | F1: Карта конкурентной близости | G1: Карта конкурентной близости | H1: Карта конкурентной близости | I1: Карта конкурентной близости | J1: Карта конкурентной близости | K1: Карта конкурентной близости
A3: ID | B3: Компания | C3: X: задача + заменяемость | D3: Y: аудитория + рынок | E3: Взвешенный балл | F3: Итоговый уровень | G3: Зона карты | H3: Комментарий | I3: Доказательства | J3: Приоритет | K3: Статус
A4: K001 | B4: =IFERROR(INDEX('04_Оценка'!$B$4:$B$103,MATCH(A4,'04_Оценка'!$A$4:$A$103,0)),"") -> PerfectXL | C4: =IFERROR(AVERAGE('04_Оценка'!D4,'04_Оценка'!F4),"") -> 4.5 | D4: =IFERROR(AVERAGE('04_Оценка'!E4,'04_Оценка'!J4),"") -> 4 | E4: =IFERROR('04_Оценка'!N4,"") -> 4.11 | F4: =IFERROR('04_Оценка'!R4,"") -> Близкий альтернативный конкурент | G4: =IF(E4="","",IF(AND(C4>=4,D4>=4),"Ядро прямой конкуренции",IF(AND(C4>=3,D4>=3),"Близкая альтернатива",IF(C4>=3,"Функциональный заменитель",IF(D4>=3,"Аудиторное пересечение","Периферия"))))) -> Ядро прямой конкуренции | J4: =IFERROR(INDEX('01_Компании'!$I$4:$I$103,MATCH(A4,'01_Компании'!$A$4:$A$103,0)),"") -> высокий | K4: =IFERROR(INDEX('04_Оценка'!$S$4:$S$103,MATCH(A4,'04_Оценка'!$A$4:$A$103,0)),"") -> 0
A5: K002 | B5: =IFERROR(INDEX('04_Оценка'!$B$4:$B$103,MATCH(A5,'04_Оценка'!$A$4:$A$103,0)),"") -> Arixcel | C5: =IFERROR(AVERAGE('04_Оценка'!D5,'04_Оценка'!F5),"") -> 3.5 | D5: =IFERROR(AVERAGE('04_Оценка'!E5,'04_Оценка'!J5),"") -> 4 | E5: =IFERROR('04_Оценка'!N5,"") -> 3.44 | F5: =IFERROR('04_Оценка'!R5,"") -> Близкий альтернативный конкурент | G5: =IF(E5="","",IF(AND(C5>=4,D5>=4),"Ядро прямой конкуренции",IF(AND(C5>=3,D5>=3),"Близкая альтернатива",IF(C5>=3,"Функциональный заменитель",IF(D5>=3,"Аудиторное пересечение","Периферия"))))) -> Близкая альтернатива | J5: =IFERROR(INDEX('01_Компании'!$I$4:$I$103,MATCH(A5,'01_Компании'!$A$4:$A$103,0)),"") -> высокий | K5: =IFERROR(INDEX('04_Оценка'!$S$4:$S$103,MATCH(A5,'04_Оценка'!$A$4:$A$103,0)),"") -> 0
A6: K003 | B6: =IFERROR(INDEX('04_Оценка'!$B$4:$B$103,MATCH(A6,'04_Оценка'!$A$4:$A$103,0)),"") -> Operis | C6: =IFERROR(AVERAGE('04_Оценка'!D6,'04_Оценка'!F6),"") -> 3.5 | D6: =IFERROR(AVERAGE('04_Оценка'!E6,'04_Оценка'!J6),"") -> 3 | E6: =IFERROR('04_Оценка'!N6,"") -> 3.05 | F6: =IFERROR('04_Оценка'!R6,"") -> Косвенный конкурент / заменитель | G6: =IF(E6="","",IF(AND(C6>=4,D6>=4),"Ядро прямой конкуренции",IF(AND(C6>=3,D6>=3),"Близкая альтернатива",IF(C6>=3,"Функциональный заменитель",IF(D6>=3,"Аудиторное пересечение","Периферия"))))) -> Близкая альтернатива | J6: =IFERROR(INDEX('01_Компании'!$I$4:$I$103,MATCH(A6,'01_Компании'!$A$4:$A$103,0)),"") -> высокий | K6: =IFERROR(INDEX('04_Оценка'!$S$4:$S$103,MATCH(A6,'04_Оценка'!$A$4:$A$103,0)),"") -> 0
A7: K004 | B7: =IFERROR(INDEX('04_Оценка'!$B$4:$B$103,MATCH(A7,'04_Оценка'!$A$4:$A$103,0)),"") -> Shortcut | C7: =IFERROR(AVERAGE('04_Оценка'!D7,'04_Оценка'!F7),"") -> 3 | D7: =IFERROR(AVERAGE('04_Оценка'!E7,'04_Оценка'!J7),"") -> 4 | E7: =IFERROR('04_Оценка'!N7,"") -> 3.47 | F7: =IFERROR('04_Оценка'!R7,"") -> Близкий альтернативный конкурент | G7: =IF(E7="","",IF(AND(C7>=4,D7>=4),"Ядро прямой конкуренции",IF(AND(C7>=3,D7>=3),"Близкая альтернатива",IF(C7>=3,"Функциональный заменитель",IF(D7>=3,"Аудиторное пересечение","Периферия"))))) -> Близкая альтернатива | J7: =IFERROR(INDEX('01_Компании'!$I$4:$I$103,MATCH(A7,'01_Компании'!$A$4:$A$103,0)),"") -> высокий | K7: =IFERROR(INDEX('04_Оценка'!$S$4:$S$103,MATCH(A7,'04_Оценка'!$A$4:$A$103,0)),"") -> 0
A8: K005 | B8: =IFERROR(INDEX('04_Оценка'!$B$4:$B$103,MATCH(A8,'04_Оценка'!$A$4:$A$103,0)),"") -> Numerous.ai | C8: =IFERROR(AVERAGE('04_Оценка'!D8,'04_Оценка'!F8),"") -> 2 | D8: =IFERROR(AVERAGE('04_Оценка'!E8,'04_Оценка'!J8),"") -> 3 | E8: =IFERROR('04_Оценка'!N8,"") -> 2.61 | F8: =IFERROR('04_Оценка'!R8,"") -> Косвенный конкурент / заменитель | G8: =IF(E8="","",IF(AND(C8>=4,D8>=4),"Ядро прямой конкуренции",IF(AND(C8>=3,D8>=3),"Близкая альтернатива",IF(C8>=3,"Функциональный заменитель",IF(D8>=3,"Аудиторное пересечение","Периферия"))))) -> Аудиторное пересечение | J8: =IFERROR(INDEX('01_Компании'!$I$4:$I$103,MATCH(A8,'01_Компании'!$A$4:$A$103,0)),"") -> высокий | K8: =IFERROR(INDEX('04_Оценка'!$S$4:$S$103,MATCH(A8,'04_Оценка'!$A$4:$A$103,0)),"") -> 0
