Workbook

Sheet 00_Методика
A1: Excel-шаблон оценки уровня конкуренции и барьеров входа
A2: Расчетная модель на основе Similarweb и альтернативных источников цифровых данных
A4: Блок | B4: Назначение | C4: Что заполняет пользователь | D4: Что рассчитывается | E4: Как использовать результат
A5: 01_Параметры | B5: Задает границы рынка, пороги и веса факторов. | C5: Название рынка, география, период, веса факторов. | D5: Итоговые индексы и шкалы оценки. | E5: Используется всеми расчетными листами.
A6: 02_Конкуренты_SW | B6: Фиксирует конкурентов и данные Similarweb. | C6: Сайты, визиты, география, каналы, вовлеченность. | D6: Релевантный трафик, доля трафика, концентрация. | E6: Показывает структуру цифровой конкуренции.
A7: 03_Каналы_трафика | B7: Оценивает давление каналов привлечения. | C7: Проверяются доли каналов по конкурентам. | D7: Взвешенные доли organic/paid/social/referral/direct. | E7: Показывает, где вход на рынок дороже.
A8: 04_Поиск_реклама | B8: Оценивает поисковую и рекламную конкуренцию. | C8: Запросы, частотность, цена клика, сложность, активность рекламы. | D8: Индекс рекламного и SEO-давления. | E8: Помогает оценить стоимость входа через поиск и рекламу.
A9: 05_Отзывы_рейтинги | B9: Оценивает репутационные барьеры. | C9: Отзывы, рейтинги, число кейсов, возраст бренда. | D9: Индекс доверия действующих игроков. | E9: Показывает, насколько трудно новому бизнесу получить доверие.
A10: 06_Технологии_финансы | B10: Оценивает технологические и ресурсные барьеры. | C10: Стек сайта, автоматизация, финансирование, команда, рекламные библиотеки. | D10: Индекс технологической силы конкурентов. | E10: Показывает, насколько конкуренты защищены ресурсами и инфраструктурой.
A11: 07_Барьеры_входа | B11: Сводит все факторы в единую оценку. | C11: При необходимости корректируются баллы и веса. | D11: Интегральный индекс барьеров входа. | E11: Дает итоговый вывод: низкие, средние или высокие барьеры.
A12: 08_Дашборд | B12: Показывает итоговые показатели. | C12: Не заполняется вручную. | D12: KPI, графики, финальная интерпретация. | E12: Используется для отчета и презентации.
A13: 09_Источники | B13: Фиксирует источники данных. | C13: Ссылки, дата обращения, комментарии. | D13: Журнал доказательной базы. | E13: Повышает воспроизводимость анализа.
A16: Ключевое правило интерпретации
A17: Similarweb и аналогичные сервисы дают оценочные цифровые сигналы: посещаемость, каналы трафика, географию, поисковые запросы и конкурентное окружение. Их нельзя механически превращать в точный размер рынка. Для оценки барьеров входа используйте несколько источников: Similarweb, Semrush/Ahrefs, G2/Capterra/Trustpilot, Crunchbase, BuiltWith/Wappalyzer, рекламные библиотеки и данные маркетплейсов.

Sheet 01_Параметры
A1: Параметры оценки конкуренции и барьеров входа
A2: Желтые ячейки заполняются пользователем; зеленые рассчитываются формулами
A4: Параметр | B4: Значение | C4: Ед. | D4: Тип | E4: Комментарий | F4: Источник/лист
A5: Название рынка | B5: Онлайн-проверка Excel-моделей и финансовых таблиц (TableMind) | D5: ввод | E5: Укажите анализируемый рынок после фиксации его границ.
A6: География | B6: Англоязычные страны (США, Великобритания, Канада, Австралия, Ирландия) и ЕС-27 | D6: ввод | E6: Страна, регион или город анализа.
A7: Период анализа Similarweb | B7: 06-08.2026 (три месяца), весь мир; снимок 03.10.2026 | D7: ввод | E7: Период, по которому фиксируются данные Similarweb.
A8: Дата обновления модели | B8: 46298 | C8: дата | D8: ввод | E8: Дата снимка Similarweb
A9: Число конкурентов в выборке | B9: =COUNTA('02_Конкуренты_SW'!A4:A33) -> 12 | C9: сайтов | D9: формула | E9: Число сайтов выборки | F9: 02_Конкуренты_SW
A10: Суммарный релевантный трафик | B10: =SUM('02_Конкуренты_SW'!E4:E33) -> 87230.381 | C10: визитов/мес. | D10: формула | E10: Релевантный трафик: визиты x география x релевантность x качество | F10: 02_Конкуренты_SW
A11: Порог высокого CR3 | B11: 0.6 | C11: % | D11: ввод | E11: Если 3 лидера контролируют больше порога, рынок концентрирован.
A12: Порог высокого CR5 | B12: 0.75 | C12: % | D12: ввод | E12: Если 5 лидеров контролируют больше порога, вход труднее.
A13: Порог высокого HHI | B13: 2500 | C13: индекс | D13: ввод | E13: Ориентир высокой концентрации по долям трафика.
A14: Порог высокой доли платного трафика | B14: 0.2 | C14: % | D14: ввод | E14: Высокая доля paid traffic означает дорогой вход через рекламу.
A15: Порог высокой доли органики | B15: 0.45 | C15: % | D15: ввод | E15: Высокая доля органики означает сильную SEO-позицию конкурентов.
A16: Порог высокой брендовой силы | B16: 0.5 | C16: % | D16: ввод | E16: Прямой + брендовый трафик как признак узнаваемости.
A17: Порог отзывов на конкурента | B17: 100 | C17: отзывов | D17: ввод | E17: Если у игроков много отзывов, новому бизнесу труднее получить доверие.
A18: Порог рекламной активности | B18: 30 | C18: объявлений | D18: ввод | E18: Ориентир высокого рекламного давления по рекламным библиотекам.

Sheet 02_Конкуренты_SW
A1: Данные Similarweb по конкурентам
A2: Заполните сайты конкурентов и показатели Similarweb. Релевантный трафик и доля рынка считаются автоматически.
A3: Конкурент / сайт | B3: Тип игрока | C3: Месячные визиты | D3: Доля целевой географии x релевантность x качество | E3: Релевантный трафик | F3: Доля релевантного трафика | G3: Длительность, сек. | H3: Страниц/визит | I3: Отказы | J3: Прямой трафик | K3: Органика | L3: Платный поиск | M3: Соцсети | N3: Рефералы | O3: Медийная реклама | P3: Брендовый поиск | Q3: Комментарий
A4: shortcut.ai | B4: частичный конкурент: AI-агент для Excel | C4: 154111 | D4: 0.079 | E4: =IFERROR(C4*D4,0) -> 12174.769 | F4: =IFERROR(E4/SUM($E$4:$E$33),0) -> 0.13957028 | G4: 83 | H4: 3.14 | J4: 0.5558 | K4: 0.3174 | L4: 0.0023 | M4: 0.0345 | N4: 0.0642 | O4: 0.0033 | Q4: Similarweb Pro, 06-08.2026, 03.10.2026; брендовый поиск - доля прямых заходов как прокси
A5: perfectxl.com | B5: прямой конкурент: аудит таблиц | C5: 35325 | D5: 0.2989 | E5: =IFERROR(C5*D5,0) -> 10558.642 | F5: =IFERROR(E5/SUM($E$4:$E$33),0) -> 0.12104318 | G5: 30 | H5: 1.84 | I5: 0.4033 | J5: 0.4043 | K5: 0.3255 | L5: 0.0153 | M5: 0.0622 | N5: 0.1055 | O5: 0.0271 | Q5: Similarweb Pro, 06-08.2026, 03.10.2026; брендовый поиск - доля прямых заходов как прокси
A6: rows.com | B6: заменитель: AI-таблицы | C6: 241737 | D6: 0.0139 | E6: =IFERROR(C6*D6,0) -> 3360.1443 | F6: =IFERROR(E6/SUM($E$4:$E$33),0) -> 0.038520344 | G6: 37 | H6: 1.95 | I6: 0.4142 | J6: 0.3416 | K6: 0.5314 | L6: 0 | M6: 0.0342 | N6: 0.0296 | O6: 0.0137 | Q6: Similarweb Pro, 06-08.2026, 03.10.2026; брендовый поиск - доля прямых заходов как прокси
A7: numerous.ai | B7: заменитель: AI-помощник в таблицах | C7: 202178 | D7: 0.0414 | E7: =IFERROR(C7*D7,0) -> 8370.1692 | F7: =IFERROR(E7/SUM($E$4:$E$33),0) -> 0.095954748 | G7: 29 | H7: 2.34 | I7: 0.4352 | J7: 0.255 | K7: 0.5638 | L7: 0.0424 | M7: 0.0166 | N7: 0.0829 | O7: 0.0167 | Q7: Similarweb Pro, 06-08.2026, 03.10.2026; брендовый поиск - доля прямых заходов как прокси
A8: operis.com | B8: прямой конкурент: аудит финансовых моделей | C8: 14688 | D8: 0.3839 | E8: =IFERROR(C8*D8,0) -> 5638.7232 | F8: =IFERROR(E8/SUM($E$4:$E$33),0) -> 0.064641736 | G8: 26 | H8: 1.72 | I8: 0.69 | J8: 0.2676 | K8: 0.2938 | L8: 0.0434 | M8: 0.1092 | N8: 0.0819 | O8: 0.0922 | Q8: Similarweb Pro, 06-08.2026, 03.10.2026; брендовый поиск - доля прямых заходов как прокси
A9: arixcel.com | B9: прямой конкурент: аудит таблиц | C9: 17824 | D9: 0.3757 | E9: =IFERROR(C9*D9,0) -> 6696.4768 | F9: =IFERROR(E9/SUM($E$4:$E$33),0) -> 0.076767713 | G9: 31 | H9: 2.03 | I9: 0.3891 | J9: 0.3864 | K9: 0.3295 | L9: 0.0161 | M9: 0.0602 | N9: 0.1089 | O9: 0.0322 | Q9: Similarweb Pro, 06-08.2026, 03.10.2026; брендовый поиск - доля прямых заходов как прокси
A10: formulabot.com | B10: заменитель: AI-помощник в таблицах | C10: 292214 | D10: 0.0232 | E10: =IFERROR(C10*D10,0) -> 6779.3648 | F10: =IFERROR(E10/SUM($E$4:$E$33),0) -> 0.077717932 | G10: 55 | H10: 3.09 | I10: 0.4184 | J10: 0.2826 | K10: 0.577 | L10: 0.0001 | M10: 0.0246 | N10: 0.0758 | O10: 0.0007 | Q10: Similarweb Pro, 06-08.2026, 03.10.2026; брендовый поиск - доля прямых заходов как прокси
A11: ajelix.com | B11: заменитель: AI-помощник в таблицах | C11: 116617 | D11: 0.0387 | E11: =IFERROR(C11*D11,0) -> 4513.0779 | F11: =IFERROR(E11/SUM($E$4:$E$33),0) -> 0.051737455 | G11: 28 | H11: 1.81 | I11: 0.4077 | J11: 0.2635 | K11: 0.5641 | L11: 0.0007 | M11: 0.0174 | N11: 0.1181 | O11: 0.003 | Q11: Similarweb Pro, 06-08.2026, 03.10.2026; брендовый поиск - доля прямых заходов как прокси
A12: datarails.com | B12: заменитель: FP&A-платформа для Excel | C12: 222359 | D12: 0.1031 | E12: =IFERROR(C12*D12,0) -> 22925.213 | F12: =IFERROR(E12/SUM($E$4:$E$33),0) -> 0.26281225 | G12: 199 | H12: 3.86 | I12: 0.392 | J12: 0.592 | K12: 0.121 | L12: 0.1159 | M12: 0.0514 | N12: 0.0199 | O12: 0.0311 | Q12: Similarweb Pro, 06-08.2026, 03.10.2026; брендовый поиск - доля прямых заходов как прокси
A13: julius.ai | B13: заменитель: AI-анализ данных | C13: 701540 | D13: 0.007 | E13: =IFERROR(C13*D13,0) -> 4910.78 | F13: =IFERROR(E13/SUM($E$4:$E$33),0) -> 0.056296671 | G13: 104 | H13: 3.24 | I13: 0.4325 | J13: 0.3559 | K13: 0.4094 | L13: 0.0529 | M13: 0.0201 | N13: 0.1018 | O13: 0.0033 | Q13: Similarweb Pro, 06-08.2026, 03.10.2026; брендовый поиск - доля прямых заходов как прокси
A14: spreadsheetdetective.com | B14: прямой конкурент: аудит таблиц | C14: 1935 | D14: 0.4294 | E14: =IFERROR(C14*D14,0) -> 830.889 | F14: =IFERROR(E14/SUM($E$4:$E$33),0) -> 0.009525225 | G14: 55 | H14: 2.05 | I14: 0.4075 | J14: 0.3897 | K14: 0.3084 | L14: 0.0172 | M14: 0.0637 | N14: 0.1064 | O14: 0.0403 | Q14: Similarweb Pro, 06-08.2026, 03.10.2026; брендовый поиск - доля прямых заходов как прокси
A15: cimcon.com | B15: частичный конкурент: риски пользовательских таблиц | C15: 5522 | D15: 0.0855 | E15: =IFERROR(C15*D15,0) -> 472.131 | F15: =IFERROR(E15/SUM($E$4:$E$33),0) -> 0.0054124606 | G15: 34 | H15: 1.85 | I15: 0.3727 | J15: 0.3852 | K15: 0.3402 | L15: 0.0139 | M15: 0.0614 | N15: 0.0965 | O15: 0.0301 | Q15: Similarweb Pro, 06-08.2026, 03.10.2026; брендовый поиск - доля прямых заходов как прокси
E16: =IFERROR(C16*D16,0) -> 0 | F16: =IFERROR(E16/SUM($E$4:$E$33),0) -> 0
E17: =IFERROR(C17*D17,0) -> 0 | F17: =IFERROR(E17/SUM($E$4:$E$33),0) -> 0
E18: =IFERROR(C18*D18,0) -> 0 | F18: =IFERROR(E18/SUM($E$4:$E$33),0) -> 0
E19: =IFERROR(C19*D19,0) -> 0 | F19: =IFERROR(E19/SUM($E$4:$E$33),0) -> 0
E20: =IFERROR(C20*D20,0) -> 0 | F20: =IFERROR(E20/SUM($E$4:$E$33),0) -> 0
E21: =IFERROR(C21*D21,0) -> 0 | F21: =IFERROR(E21/SUM($E$4:$E$33),0) -> 0
E22: =IFERROR(C22*D22,0) -> 0 | F22: =IFERROR(E22/SUM($E$4:$E$33),0) -> 0
E23: =IFERROR(C23*D23,0) -> 0 | F23: =IFERROR(E23/SUM($E$4:$E$33),0) -> 0
E24: =IFERROR(C24*D24,0) -> 0 | F24: =IFERROR(E24/SUM($E$4:$E$33),0) -> 0
E25: =IFERROR(C25*D25,0) -> 0 | F25: =IFERROR(E25/SUM($E$4:$E$33),0) -> 0
E26: =IFERROR(C26*D26,0) -> 0 | F26: =IFERROR(E26/SUM($E$4:$E$33),0) -> 0
E27: =IFERROR(C27*D27,0) -> 0 | F27: =IFERROR(E27/SUM($E$4:$E$33),0) -> 0
... E33: =IFERROR(C33*D33,0) -> 0 | F33: =IFERROR(E33/SUM($E$4:$E$33),0) -> 0
A36: Показатель | B36: Формула / значение | C36: Интерпретация
A37: Суммарный релевантный трафик | B37: =SUM(E4:E33) -> 87230.381 | C37: Оценочный цифровой размер выборки конкурентов
A38: CR3 по трафику | B38: =LARGE(F4:F33,1)+LARGE(F4:F33,2)+LARGE(F4:F33,3) -> 0.52342572 | C38: Доля трех крупнейших игроков
A39: CR5 по трафику | B39: =LARGE(F4:F33,1)+LARGE(F4:F33,2)+LARGE(F4:F33,3)+LARGE(F4:F33,4)+LARGE(F4:F33,5) -> 0.6970984 | C39: Доля пяти крупнейших игроков
A40: HHI по трафику | B40: =SUMSQ(F4:F33)*10000 -> 1359.7074 | C40: Индекс концентрации на основе долей релевантного трафика
A41: Средняя длительность визита | B41: =IFERROR(SUMPRODUCT(E4:E33,G4:G33)/SUM(E4:E33),0) -> 88.069592 | C41: Косвенный признак вовлеченности

Sheet 03_Каналы_трафика
A1: Оценка конкурентного давления по каналам трафика
A2: Расчет делается как взвешенная доля каналов с учетом релевантного трафика конкурентов
A3: Канал | B3: Формула / источник | C3: Взвешенная доля канала | D3: Порог высокого давления | E3: Балльная оценка 1-5 | F3: Интерпретация | G3: Риски для нового игрока | H3: Что проверить дополнительно | I3: Источник
A4: Прямой трафик | B4: Similarweb: Direct | C4: =IFERROR(SUMPRODUCT('02_Конкуренты_SW'!$E$4:$E$33,'02_Конкуренты_SW'!$J$4:$J$33)/SUM('02_Конкуренты_SW'!$E$4:$E$33),0) -> 0.42811271 | D4: 0.3 | E4: =IF(C4>=D4,5,IF(C4>=D4*0.65,3,1)) -> 5 | F4: Высокая доля означает узнаваемость брендов. | G4: Новому игроку сложнее быстро получить прямые заходы. | H4: Брендовые запросы, отзывы, возраст домена. | I4: Similarweb
A5: Органический поиск | B5: Similarweb: Organic Search | C5: =IFERROR(SUMPRODUCT('02_Конкуренты_SW'!$E$4:$E$33,'02_Конкуренты_SW'!$K$4:$K$33)/SUM('02_Конкуренты_SW'!$E$4:$E$33),0) -> 0.33621025 | D5: ='01_Параметры'!B15 -> 0.45 | E5: =IF(C5>=D5,5,IF(C5>=D5*0.65,3,1)) -> 3 | F5: Высокая доля означает сильные SEO-позиции. | G5: Потребуются контент, ссылки, время и техническая оптимизация. | H5: Semrush/Ahrefs, выдача Google/Яндекс. | I5: Similarweb, Semrush, Ahrefs
A6: Платный поиск | B6: Similarweb: Paid Search | C6: =IFERROR(SUMPRODUCT('02_Конкуренты_SW'!$E$4:$E$33,'02_Конкуренты_SW'!$L$4:$L$33)/SUM('02_Конкуренты_SW'!$E$4:$E$33),0) -> 0.044003954 | D6: ='01_Параметры'!B14 -> 0.2 | E6: =IF(C6>=D6,5,IF(C6>=D6*0.65,3,1)) -> 1 | F6: Высокая доля означает рекламное давление. | G6: Вход через рекламу может быть дорогим. | H6: Google Ads, Яндекс Директ, рекламные библиотеки. | I6: Similarweb, Ads libraries
A7: Социальные сети | B7: Similarweb: Social | C7: =IFERROR(SUMPRODUCT('02_Конкуренты_SW'!$E$4:$E$33,'02_Конкуренты_SW'!$M$4:$M$33)/SUM('02_Конкуренты_SW'!$E$4:$E$33),0) -> 0.045325887 | D7: 0.2 | E7: =IF(C7>=D7,5,IF(C7>=D7*0.65,3,1)) -> 1 | F7: Высокая доля означает сильные социальные каналы. | G7: Нужно развивать контент и сообщество. | H7: Meta/TikTok/YouTube/LinkedIn активность. | I7: Similarweb, социальные сети
A8: Реферальный трафик | B8: Similarweb: Referrals | C8: =IFERROR(SUMPRODUCT('02_Конкуренты_SW'!$E$4:$E$33,'02_Конкуренты_SW'!$N$4:$N$33)/SUM('02_Конкуренты_SW'!$E$4:$E$33),0) -> 0.068977444 | D8: 0.15 | E8: =IF(C8>=D8,5,IF(C8>=D8*0.65,3,1)) -> 1 | F8: Высокая доля означает партнерские и медийные связи. | G8: Потребуются партнерства и присутствие в каталогах. | H8: Каталоги, медиа, партнерские сайты. | I8: Similarweb, каталоги
A9: Медийная реклама | B9: Similarweb: Display | C9: =IFERROR(SUMPRODUCT('02_Конкуренты_SW'!$E$4:$E$33,'02_Конкуренты_SW'!$O$4:$O$33)/SUM('02_Конкуренты_SW'!$E$4:$E$33),0) -> 0.02341855 | D9: 0.1 | E9: =IF(C9>=D9,5,IF(C9>=D9*0.65,3,1)) -> 1 | F9: Высокая доля означает платное медийное давление. | G9: Нужны бюджеты на охват и ретаргетинг. | H9: Библиотеки рекламы, креативы, баннеры. | I9: Similarweb, рекламные библиотеки
A10: Брендовая сила | B10: Direct + Brand Search | C10: =IFERROR(SUMPRODUCT('02_Конкуренты_SW'!$E$4:$E$33,('02_Конкуренты_SW'!$J$4:$J$33+'02_Конкуренты_SW'!$P$4:$P$33))/SUM('02_Конкуренты_SW'!$E$4:$E$33),0) -> 0.42811271 | D10: ='01_Параметры'!B16 -> 0.5 | E10: =IF(C10>=D10,5,IF(C10>=D10*0.65,3,1)) -> 3 | F10: Высокая доля означает устойчивое доверие и узнаваемость. | G10: Новому игроку сложнее перехватить спрос. | H10: Google Trends по брендам, брендовые запросы. | I10: Similarweb, Trends, Wordstat

Sheet 04_Поиск_реклама
A1: Оценка поисковой и рекламной конкуренции
A2: Вводятся данные из Google/Яндекс, Semrush/Ahrefs, рекламных библиотек и Similarweb
A3: Запрос / рекламная тема | B3: Тип намерения | C3: Источник | D3: Индекс Google Trends (спрос) | E3: CPC / цена клика | F3: Конкурентность PPC 0-1 | G3: SEO difficulty 0-100 | H3: Топ-конкурентов в выдаче | I3: Активных рекламодателей | J3: Рекламные объявления | K3: Индекс давления | L3: Балльная оценка 1-5 | M3: Комментарий
A4: excel audit | B4: коммерческий | C4: Google Trends (индекс 0-100, ЛР1) | D4: 47.6 | K4: =IF(COUNT(E4:J4)<2,"",MIN(1,(IF(ISNUMBER(E4),MIN(E4/2,1),0)+IF(ISNUMBER(F4),F4,0)+IF(ISNUMBER(G4),G4/100,0)+IF(ISNUMBER(H4),MIN(H4/10,1),0)+IF(ISNUMBER(J4),MIN(J4/50,1),0))/MAX(1,COUNT(E4:H4,J4)))) | L4: =IF(K4="","",IF(K4>=0.7,5,IF(K4>=0.4,3,1))) | M4: CPC, PPC, SEO difficulty, выдача и объявления: расчетные показатели (отчет ЛР4, приложение Д, допущение Д-33)
A5: spreadsheet audit | B5: коммерческий | C5: Google Trends (индекс 0-100, ЛР1) | D5: 32 | K5: =IF(COUNT(E5:J5)<2,"",MIN(1,(IF(ISNUMBER(E5),MIN(E5/2,1),0)+IF(ISNUMBER(F5),F5,0)+IF(ISNUMBER(G5),G5/100,0)+IF(ISNUMBER(H5),MIN(H5/10,1),0)+IF(ISNUMBER(J5),MIN(J5/50,1),0))/MAX(1,COUNT(E5:H5,J5)))) | L5: =IF(K5="","",IF(K5>=0.7,5,IF(K5>=0.4,3,1))) | M5: CPC, PPC, SEO difficulty, выдача и объявления: расчетные показатели (отчет ЛР4, приложение Д, допущение Д-33)
A6: excel formula checker | B6: инструментальный | C6: Google Trends (индекс 0-100, ЛР1) | D6: 13.2 | K6: =IF(COUNT(E6:J6)<2,"",MIN(1,(IF(ISNUMBER(E6),MIN(E6/2,1),0)+IF(ISNUMBER(F6),F6,0)+IF(ISNUMBER(G6),G6/100,0)+IF(ISNUMBER(H6),MIN(H6/10,1),0)+IF(ISNUMBER(J6),MIN(J6/50,1),0))/MAX(1,COUNT(E6:H6,J6)))) | L6: =IF(K6="","",IF(K6>=0.7,5,IF(K6>=0.4,3,1))) | M6: CPC, PPC, SEO difficulty, выдача и объявления: расчетные показатели (отчет ЛР4, приложение Д, допущение Д-33)
A7: financial model audit | B7: коммерческий | C7: Google Trends (индекс 0-100, ЛР1) | D7: 29 | K7: =IF(COUNT(E7:J7)<2,"",MIN(1,(IF(ISNUMBER(E7),MIN(E7/2,1),0)+IF(ISNUMBER(F7),F7,0)+IF(ISNUMBER(G7),G7/100,0)+IF(ISNUMBER(H7),MIN(H7/10,1),0)+IF(ISNUMBER(J7),MIN(J7/50,1),0))/MAX(1,COUNT(E7:H7,J7)))) | L7: =IF(K7="","",IF(K7>=0.7,5,IF(K7>=0.4,3,1))) | M7: CPC, PPC, SEO difficulty, выдача и объявления: расчетные показатели (отчет ЛР4, приложение Д, допущение Д-33)
A8: excel copilot | B8: AI-альтернатива | C8: Google Trends (индекс 0-100, ЛР1) | D8: 60.9 | K8: =IF(COUNT(E8:J8)<2,"",MIN(1,(IF(ISNUMBER(E8),MIN(E8/2,1),0)+IF(ISNUMBER(F8),F8,0)+IF(ISNUMBER(G8),G8/100,0)+IF(ISNUMBER(H8),MIN(H8/10,1),0)+IF(ISNUMBER(J8),MIN(J8/50,1),0))/MAX(1,COUNT(E8:H8,J8)))) | L8: =IF(K8="","",IF(K8>=0.7,5,IF(K8>=0.4,3,1))) | M8: CPC, PPC, SEO difficulty, выдача и объявления: расчетные показатели (отчет ЛР4, приложение Д, допущение Д-33)
A9: perfectxl | B9: брендовый | C9: Google Trends (индекс 0-100, ЛР1) | D9: 0.6 | K9: =IF(COUNT(E9:J9)<2,"",MIN(1,(IF(ISNUMBER(E9),MIN(E9/2,1),0)+IF(ISNUMBER(F9),F9,0)+IF(ISNUMBER(G9),G9/100,0)+IF(ISNUMBER(H9),MIN(H9/10,1),0)+IF(ISNUMBER(J9),MIN(J9/50,1),0))/MAX(1,COUNT(E9:H9,J9)))) | L9: =IF(K9="","",IF(K9>=0.7,5,IF(K9>=0.4,3,1))) | M9: CPC, PPC, SEO difficulty, выдача и объявления: расчетные показатели (отчет ЛР4, приложение Д, допущение Д-33)
K10: =IF(COUNT(E10:J10)<2,"",MIN(1,(IF(ISNUMBER(E10),MIN(E10/2,1),0)+IF(ISNUMBER(F10),F10,0)+IF(ISNUMBER(G10),G10/100,0)+IF(ISNUMBER(H10),MIN(H10/10,1),0)+IF(ISNUMBER(J10),MIN(J10/50,1),0))/MAX(1,COUNT(E10:H10,J10)))) | L10: =IF(K10="","",IF(K10>=0.7,5,IF(K10>=0.4,3,1)))
K11: =IF(COUNT(E11:J11)<2,"",MIN(1,(IF(ISNUMBER(E11),MIN(E11/2,1),0)+IF(ISNUMBER(F11),F11,0)+IF(ISNUMBER(G11),G11/100,0)+IF(ISNUMBER(H11),MIN(H11/10,1),0)+IF(ISNUMBER(J11),MIN(J11/50,1),0))/MAX(1,COUNT(E11:H11,J11)))) | L11: =IF(K11="","",IF(K11>=0.7,5,IF(K11>=0.4,3,1)))
K12: =IF(COUNT(E12:J12)<2,"",MIN(1,(IF(ISNUMBER(E12),MIN(E12/2,1),0)+IF(ISNUMBER(F12),F12,0)+IF(ISNUMBER(G12),G12/100,0)+IF(ISNUMBER(H12),MIN(H12/10,1),0)+IF(ISNUMBER(J12),MIN(J12/50,1),0))/MAX(1,COUNT(E12:H12,J12)))) | L12: =IF(K12="","",IF(K12>=0.7,5,IF(K12>=0.4,3,1)))
K13: =IF(COUNT(E13:J13)<2,"",MIN(1,(IF(ISNUMBER(E13),MIN(E13/2,1),0)+IF(ISNUMBER(F13),F13,0)+IF(ISNUMBER(G13),G13/100,0)+IF(ISNUMBER(H13),MIN(H13/10,1),0)+IF(ISNUMBER(J13),MIN(J13/50,1),0))/MAX(1,COUNT(E13:H13,J13)))) | L13: =IF(K13="","",IF(K13>=0.7,5,IF(K13>=0.4,3,1)))
K14: =IF(COUNT(E14:J14)<2,"",MIN(1,(IF(ISNUMBER(E14),MIN(E14/2,1),0)+IF(ISNUMBER(F14),F14,0)+IF(ISNUMBER(G14),G14/100,0)+IF(ISNUMBER(H14),MIN(H14/10,1),0)+IF(ISNUMBER(J14),MIN(J14/50,1),0))/MAX(1,COUNT(E14:H14,J14)))) | L14: =IF(K14="","",IF(K14>=0.7,5,IF(K14>=0.4,3,1)))
K15: =IF(COUNT(E15:J15)<2,"",MIN(1,(IF(ISNUMBER(E15),MIN(E15/2,1),0)+IF(ISNUMBER(F15),F15,0)+IF(ISNUMBER(G15),G15/100,0)+IF(ISNUMBER(H15),MIN(H15/10,1),0)+IF(ISNUMBER(J15),MIN(J15/50,1),0))/MAX(1,COUNT(E15:H15,J15)))) | L15: =IF(K15="","",IF(K15>=0.7,5,IF(K15>=0.4,3,1)))
K16: =IF(COUNT(E16:J16)<2,"",MIN(1,(IF(ISNUMBER(E16),MIN(E16/2,1),0)+IF(ISNUMBER(F16),F16,0)+IF(ISNUMBER(G16),G16/100,0)+IF(ISNUMBER(H16),MIN(H16/10,1),0)+IF(ISNUMBER(J16),MIN(J16/50,1),0))/MAX(1,COUNT(E16:H16,J16)))) | L16: =IF(K16="","",IF(K16>=0.7,5,IF(K16>=0.4,3,1)))
K17: =IF(COUNT(E17:J17)<2,"",MIN(1,(IF(ISNUMBER(E17),MIN(E17/2,1),0)+IF(ISNUMBER(F17),F17,0)+IF(ISNUMBER(G17),G17/100,0)+IF(ISNUMBER(H17),MIN(H17/10,1),0)+IF(ISNUMBER(J17),MIN(J17/50,1),0))/MAX(1,COUNT(E17:H17,J17)))) | L17: =IF(K17="","",IF(K17>=0.7,5,IF(K17>=0.4,3,1)))
K18: =IF(COUNT(E18:J18)<2,"",MIN(1,(IF(ISNUMBER(E18),MIN(E18/2,1),0)+IF(ISNUMBER(F18),F18,0)+IF(ISNUMBER(G18),G18/100,0)+IF(ISNUMBER(H18),MIN(H18/10,1),0)+IF(ISNUMBER(J18),MIN(J18/50,1),0))/MAX(1,COUNT(E18:H18,J18)))) | L18: =IF(K18="","",IF(K18>=0.7,5,IF(K18>=0.4,3,1)))
K19: =IF(COUNT(E19:J19)<2,"",MIN(1,(IF(ISNUMBER(E19),MIN(E19/2,1),0)+IF(ISNUMBER(F19),F19,0)+IF(ISNUMBER(G19),G19/100,0)+IF(ISNUMBER(H19),MIN(H19/10,1),0)+IF(ISNUMBER(J19),MIN(J19/50,1),0))/MAX(1,COUNT(E19:H19,J19)))) | L19: =IF(K19="","",IF(K19>=0.7,5,IF(K19>=0.4,3,1)))
K20: =IF(COUNT(E20:J20)<2,"",MIN(1,(IF(ISNUMBER(E20),MIN(E20/2,1),0)+IF(ISNUMBER(F20),F20,0)+IF(ISNUMBER(G20),G20/100,0)+IF(ISNUMBER(H20),MIN(H20/10,1),0)+IF(ISNUMBER(J20),MIN(J20/50,1),0))/MAX(1,COUNT(E20:H20,J20)))) | L20: =IF(K20="","",IF(K20>=0.7,5,IF(K20>=0.4,3,1)))
K21: =IF(COUNT(E21:J21)<2,"",MIN(1,(IF(ISNUMBER(E21),MIN(E21/2,1),0)+IF(ISNUMBER(F21),F21,0)+IF(ISNUMBER(G21),G21/100,0)+IF(ISNUMBER(H21),MIN(H21/10,1),0)+IF(ISNUMBER(J21),MIN(J21/50,1),0))/MAX(1,COUNT(E21:H21,J21)))) | L21: =IF(K21="","",IF(K21>=0.7,5,IF(K21>=0.4,3,1)))
... K33: =IF(COUNT(E33:J33)<2,"",MIN(1,(IF(ISNUMBER(E33),MIN(E33/2,1),0)+IF(ISNUMBER(F33),F33,0)+IF(ISNUMBER(G33),G33/100,0)+IF(ISNUMBER(H33),MIN(H33/10,1),0)+IF(ISNUMBER(J33),MIN(J33/50,1),0))/MAX(1,COUNT(E33:H33,J33)))) | L33: =IF(K33="","",IF(K33>=0.7,5,IF(K33>=0.4,3,1)))
A36: Сводный показатель | B36: Значение | C36: Оценка | D36: Интерпретация
A37: Средний индекс поисково-рекламного давления | B37: =IFERROR(AVERAGE(K4:K33),"нет данных") -> нет данных | C37: =IF(ISNUMBER(B37),IF(B37>=0.7,"высокое",IF(B37>=0.4,"среднее","низкое")),"нет данных") -> нет данных | D37: Учитывает CPC, PPC-конкурентность, SEO difficulty, число конкурентов и рекламных объявлений.
A38: Доля высококонкурентных запросов | B38: =IFERROR(COUNTIF(L4:L33,5)/COUNT(L4:L33),"нет данных") -> нет данных | C38: =IF(ISNUMBER(B38),IF(B38>=0.5,"высокая доля",IF(B38>=0.25,"средняя доля","низкая доля")),"нет данных") -> нет данных | D38: Доля запросов с баллом 5.
A39: Вывод | D39: Данные CPC и SEO difficulty не получены; в сводной оценке используется прокси по каналам Similarweb (лист 07, строка 8).

Sheet 05_Отзывы_рейтинги
A1: Оценка репутационных барьеров: отзывы, рейтинги, кейсы
A2: Заполняется по G2, Capterra, Trustpilot, Google Maps, App Store, Google Play, маркетплейсам и сайтам конкурентов
A3: Конкурент | B3: G2 рейтинг | C3: G2 отзывы | D3: Capterra рейтинг | E3: Capterra отзывы | F3: Trustpilot рейтинг | G3: Trustpilot отзывы | H3: Google рейтинг | I3: Google отзывы | J3: Кейсы на сайте | K3: Возраст бренда, лет | L3: Индекс доверия | M3: Балльная оценка 1-5 | N3: Комментарий
A4: shortcut.ai | L4: =IF(COUNT(B4:K4)=0,"",MIN(1,(IF(COUNT(B4,D4,F4,H4)>0,AVERAGE(B4,D4,F4,H4)/5,0)+IF(COUNT(C4,E4,G4,I4)>0,MIN(SUM(C4,E4,G4,I4)/300,1),0)+IF(ISNUMBER(J4),MIN(J4/30,1),0)+IF(ISNUMBER(K4),MIN(K4/10,1),0))/MAX(1,(COUNT(B4,D4,F4,H4)>0)+(COUNT(C4,E4,G4,I4)>0)+ISNUMBER(J4)+ISNUMBER(K4)))) | M4: =IF(L4="","",IF(L4>=0.7,5,IF(L4>=0.4,3,1))) | N4: G2: карточки Shortcut нет (найдена SheetWhiz - не относится)
A5: perfectxl.com | C5: 0 | G5: 0 | L5: =IF(COUNT(B5:K5)=0,"",MIN(1,(IF(COUNT(B5,D5,F5,H5)>0,AVERAGE(B5,D5,F5,H5)/5,0)+IF(COUNT(C5,E5,G5,I5)>0,MIN(SUM(C5,E5,G5,I5)/300,1),0)+IF(ISNUMBER(J5),MIN(J5/30,1),0)+IF(ISNUMBER(K5),MIN(K5/10,1),0))/MAX(1,(COUNT(B5,D5,F5,H5)>0)+(COUNT(C5,E5,G5,I5)>0)+ISNUMBER(J5)+ISNUMBER(K5)))) -> 0 | M5: =IF(L5="","",IF(L5>=0.7,5,IF(L5>=0.4,3,1))) -> 1 | N5: G2: карточка PerfectXL (Infotron B.V.) 0 отзывов
A6: rows.com | B6: 4.9 | C6: 24 | L6: =IF(COUNT(B6:K6)=0,"",MIN(1,(IF(COUNT(B6,D6,F6,H6)>0,AVERAGE(B6,D6,F6,H6)/5,0)+IF(COUNT(C6,E6,G6,I6)>0,MIN(SUM(C6,E6,G6,I6)/300,1),0)+IF(ISNUMBER(J6),MIN(J6/30,1),0)+IF(ISNUMBER(K6),MIN(K6/10,1),0))/MAX(1,(COUNT(B6,D6,F6,H6)>0)+(COUNT(C6,E6,G6,I6)>0)+ISNUMBER(J6)+ISNUMBER(K6)))) -> 0.53 | M6: =IF(L6="","",IF(L6>=0.7,5,IF(L6>=0.4,3,1))) -> 3 | N6: G2: Rows
A7: numerous.ai | L7: =IF(COUNT(B7:K7)=0,"",MIN(1,(IF(COUNT(B7,D7,F7,H7)>0,AVERAGE(B7,D7,F7,H7)/5,0)+IF(COUNT(C7,E7,G7,I7)>0,MIN(SUM(C7,E7,G7,I7)/300,1),0)+IF(ISNUMBER(J7),MIN(J7/30,1),0)+IF(ISNUMBER(K7),MIN(K7/10,1),0))/MAX(1,(COUNT(B7,D7,F7,H7)>0)+(COUNT(C7,E7,G7,I7)>0)+ISNUMBER(J7)+ISNUMBER(K7)))) | M7: =IF(L7="","",IF(L7>=0.7,5,IF(L7>=0.4,3,1))) | N7: G2: карточки Numerous.ai нет (найден посторонний продукт)
A8: operis.com | L8: =IF(COUNT(B8:K8)=0,"",MIN(1,(IF(COUNT(B8,D8,F8,H8)>0,AVERAGE(B8,D8,F8,H8)/5,0)+IF(COUNT(C8,E8,G8,I8)>0,MIN(SUM(C8,E8,G8,I8)/300,1),0)+IF(ISNUMBER(J8),MIN(J8/30,1),0)+IF(ISNUMBER(K8),MIN(K8/10,1),0))/MAX(1,(COUNT(B8,D8,F8,H8)>0)+(COUNT(C8,E8,G8,I8)>0)+ISNUMBER(J8)+ISNUMBER(K8)))) | M8: =IF(L8="","",IF(L8>=0.7,5,IF(L8>=0.4,3,1))) | N8: G2: найден только однофамилец (Operis by Vastian, лабораторные процессы) - не конкурент
A9: arixcel.com | B9: 4 | C9: 1 | L9: =IF(COUNT(B9:K9)=0,"",MIN(1,(IF(COUNT(B9,D9,F9,H9)>0,AVERAGE(B9,D9,F9,H9)/5,0)+IF(COUNT(C9,E9,G9,I9)>0,MIN(SUM(C9,E9,G9,I9)/300,1),0)+IF(ISNUMBER(J9),MIN(J9/30,1),0)+IF(ISNUMBER(K9),MIN(K9/10,1),0))/MAX(1,(COUNT(B9,D9,F9,H9)>0)+(COUNT(C9,E9,G9,I9)>0)+ISNUMBER(J9)+ISNUMBER(K9)))) -> 0.40166667 | M9: =IF(L9="","",IF(L9>=0.7,5,IF(L9>=0.4,3,1))) -> 3 | N9: G2: Arixcel Explorer
A10: formulabot.com | B10: 4.5 | C10: 90 | L10: =IF(COUNT(B10:K10)=0,"",MIN(1,(IF(COUNT(B10,D10,F10,H10)>0,AVERAGE(B10,D10,F10,H10)/5,0)+IF(COUNT(C10,E10,G10,I10)>0,MIN(SUM(C10,E10,G10,I10)/300,1),0)+IF(ISNUMBER(J10),MIN(J10/30,1),0)+IF(ISNUMBER(K10),MIN(K10/10,1),0))/MAX(1,(COUNT(B10,D10,F10,H10)>0)+(COUNT(C10,E10,G10,I10)>0)+ISNUMBER(J10)+ISNUMBER(K10)))) -> 0.6 | M10: =IF(L10="","",IF(L10>=0.7,5,IF(L10>=0.4,3,1))) -> 3 | N10: G2: Formula Bot (Better Analyst)
A11: ajelix.com | B11: 4.5 | C11: 1 | L11: =IF(COUNT(B11:K11)=0,"",MIN(1,(IF(COUNT(B11,D11,F11,H11)>0,AVERAGE(B11,D11,F11,H11)/5,0)+IF(COUNT(C11,E11,G11,I11)>0,MIN(SUM(C11,E11,G11,I11)/300,1),0)+IF(ISNUMBER(J11),MIN(J11/30,1),0)+IF(ISNUMBER(K11),MIN(K11/10,1),0))/MAX(1,(COUNT(B11,D11,F11,H11)>0)+(COUNT(C11,E11,G11,I11)>0)+ISNUMBER(J11)+ISNUMBER(K11)))) -> 0.45166667 | M11: =IF(L11="","",IF(L11>=0.7,5,IF(L11>=0.4,3,1))) -> 3 | N11: G2: Ajelix
A12: datarails.com | B12: 4.6 | C12: 386 | L12: =IF(COUNT(B12:K12)=0,"",MIN(1,(IF(COUNT(B12,D12,F12,H12)>0,AVERAGE(B12,D12,F12,H12)/5,0)+IF(COUNT(C12,E12,G12,I12)>0,MIN(SUM(C12,E12,G12,I12)/300,1),0)+IF(ISNUMBER(J12),MIN(J12/30,1),0)+IF(ISNUMBER(K12),MIN(K12/10,1),0))/MAX(1,(COUNT(B12,D12,F12,H12)>0)+(COUNT(C12,E12,G12,I12)>0)+ISNUMBER(J12)+ISNUMBER(K12)))) -> 0.96 | M12: =IF(L12="","",IF(L12>=0.7,5,IF(L12>=0.4,3,1))) -> 5 | N12: G2: Datarails
A13: julius.ai | B13: 4.5 | C13: 4 | L13: =IF(COUNT(B13:K13)=0,"",MIN(1,(IF(COUNT(B13,D13,F13,H13)>0,AVERAGE(B13,D13,F13,H13)/5,0)+IF(COUNT(C13,E13,G13,I13)>0,MIN(SUM(C13,E13,G13,I13)/300,1),0)+IF(ISNUMBER(J13),MIN(J13/30,1),0)+IF(ISNUMBER(K13),MIN(K13/10,1),0))/MAX(1,(COUNT(B13,D13,F13,H13)>0)+(COUNT(C13,E13,G13,I13)>0)+ISNUMBER(J13)+ISNUMBER(K13)))) -> 0.45666667 | M13: =IF(L13="","",IF(L13>=0.7,5,IF(L13>=0.4,3,1))) -> 3 | N13: G2: Julius AI
A14: spreadsheetdetective.com | C14: 0 | L14: =IF(COUNT(B14:K14)=0,"",MIN(1,(IF(COUNT(B14,D14,F14,H14)>0,AVERAGE(B14,D14,F14,H14)/5,0)+IF(COUNT(C14,E14,G14,I14)>0,MIN(SUM(C14,E14,G14,I14)/300,1),0)+IF(ISNUMBER(J14),MIN(J14/30,1),0)+IF(ISNUMBER(K14),MIN(K14/10,1),0))/MAX(1,(COUNT(B14,D14,F14,H14)>0)+(COUNT(C14,E14,G14,I14)>0)+ISNUMBER(J14)+ISNUMBER(K14)))) -> 0 | M14: =IF(L14="","",IF(L14>=0.7,5,IF(L14>=0.4,3,1))) -> 1 | N14: G2: карточка без оценок
A15: cimcon.com | B15: 4.7 | C15: 19 | L15: =IF(COUNT(B15:K15)=0,"",MIN(1,(IF(COUNT(B15,D15,F15,H15)>0,AVERAGE(B15,D15,F15,H15)/5,0)+IF(COUNT(C15,E15,G15,I15)>0,MIN(SUM(C15,E15,G15,I15)/300,1),0)+IF(ISNUMBER(J15),MIN(J15/30,1),0)+IF(ISNUMBER(K15),MIN(K15/10,1),0))/MAX(1,(COUNT(B15,D15,F15,H15)>0)+(COUNT(C15,E15,G15,I15)>0)+ISNUMBER(J15)+ISNUMBER(K15)))) -> 0.50166667 | M15: =IF(L15="","",IF(L15>=0.7,5,IF(L15>=0.4,3,1))) -> 3 | N15: G2: CIMCON Software (EUC-риск)
L16: =IF(COUNT(B16:K16)=0,"",MIN(1,(IF(COUNT(B16,D16,F16,H16)>0,AVERAGE(B16,D16,F16,H16)/5,0)+IF(COUNT(C16,E16,G16,I16)>0,MIN(SUM(C16,E16,G16,I16)/300,1),0)+IF(ISNUMBER(J16),MIN(J16/30,1),0)+IF(ISNUMBER(K16),MIN(K16/10,1),0))/MAX(1,(COUNT(B16,D16,F16,H16)>0)+(COUNT(C16,E16,G16,I16)>0)+ISNUMBER(J16)+ISNUMBER(K16)))) | M16: =IF(L16="","",IF(L16>=0.7,5,IF(L16>=0.4,3,1)))
L17: =IF(COUNT(B17:K17)=0,"",MIN(1,(IF(COUNT(B17,D17,F17,H17)>0,AVERAGE(B17,D17,F17,H17)/5,0)+IF(COUNT(C17,E17,G17,I17)>0,MIN(SUM(C17,E17,G17,I17)/300,1),0)+IF(ISNUMBER(J17),MIN(J17/30,1),0)+IF(ISNUMBER(K17),MIN(K17/10,1),0))/MAX(1,(COUNT(B17,D17,F17,H17)>0)+(COUNT(C17,E17,G17,I17)>0)+ISNUMBER(J17)+ISNUMBER(K17)))) | M17: =IF(L17="","",IF(L17>=0.7,5,IF(L17>=0.4,3,1)))
L18: =IF(COUNT(B18:K18)=0,"",MIN(1,(IF(COUNT(B18,D18,F18,H18)>0,AVERAGE(B18,D18,F18,H18)/5,0)+IF(COUNT(C18,E18,G18,I18)>0,MIN(SUM(C18,E18,G18,I18)/300,1),0)+IF(ISNUMBER(J18),MIN(J18/30,1),0)+IF(ISNUMBER(K18),MIN(K18/10,1),0))/MAX(1,(COUNT(B18,D18,F18,H18)>0)+(COUNT(C18,E18,G18,I18)>0)+ISNUMBER(J18)+ISNUMBER(K18)))) | M18: =IF(L18="","",IF(L18>=0.7,5,IF(L18>=0.4,3,1)))
L19: =IF(COUNT(B19:K19)=0,"",MIN(1,(IF(COUNT(B19,D19,F19,H19)>0,AVERAGE(B19,D19,F19,H19)/5,0)+IF(COUNT(C19,E19,G19,I19)>0,MIN(SUM(C19,E19,G19,I19)/300,1),0)+IF(ISNUMBER(J19),MIN(J19/30,1),0)+IF(ISNUMBER(K19),MIN(K19/10,1),0))/MAX(1,(COUNT(B19,D19,F19,H19)>0)+(COUNT(C19,E19,G19,I19)>0)+ISNUMBER(J19)+ISNUMBER(K19)))) | M19: =IF(L19="","",IF(L19>=0.7,5,IF(L19>=0.4,3,1)))
L20: =IF(COUNT(B20:K20)=0,"",MIN(1,(IF(COUNT(B20,D20,F20,H20)>0,AVERAGE(B20,D20,F20,H20)/5,0)+IF(COUNT(C20,E20,G20,I20)>0,MIN(SUM(C20,E20,G20,I20)/300,1),0)+IF(ISNUMBER(J20),MIN(J20/30,1),0)+IF(ISNUMBER(K20),MIN(K20/10,1),0))/MAX(1,(COUNT(B20,D20,F20,H20)>0)+(COUNT(C20,E20,G20,I20)>0)+ISNUMBER(J20)+ISNUMBER(K20)))) | M20: =IF(L20="","",IF(L20>=0.7,5,IF(L20>=0.4,3,1)))
L21: =IF(COUNT(B21:K21)=0,"",MIN(1,(IF(COUNT(B21,D21,F21,H21)>0,AVERAGE(B21,D21,F21,H21)/5,0)+IF(COUNT(C21,E21,G21,I21)>0,MIN(SUM(C21,E21,G21,I21)/300,1),0)+IF(ISNUMBER(J21),MIN(J21/30,1),0)+IF(ISNUMBER(K21),MIN(K21/10,1),0))/MAX(1,(COUNT(B21,D21,F21,H21)>0)+(COUNT(C21,E21,G21,I21)>0)+ISNUMBER(J21)+ISNUMBER(K21)))) | M21: =IF(L21="","",IF(L21>=0.7,5,IF(L21>=0.4,3,1)))
L22: =IF(COUNT(B22:K22)=0,"",MIN(1,(IF(COUNT(B22,D22,F22,H22)>0,AVERAGE(B22,D22,F22,H22)/5,0)+IF(COUNT(C22,E22,G22,I22)>0,MIN(SUM(C22,E22,G22,I22)/300,1),0)+IF(ISNUMBER(J22),MIN(J22/30,1),0)+IF(ISNUMBER(K22),MIN(K22/10,1),0))/MAX(1,(COUNT(B22,D22,F22,H22)>0)+(COUNT(C22,E22,G22,I22)>0)+ISNUMBER(J22)+ISNUMBER(K22)))) | M22: =IF(L22="","",IF(L22>=0.7,5,IF(L22>=0.4,3,1)))
L23: =IF(COUNT(B23:K23)=0,"",MIN(1,(IF(COUNT(B23,D23,F23,H23)>0,AVERAGE(B23,D23,F23,H23)/5,0)+IF(COUNT(C23,E23,G23,I23)>0,MIN(SUM(C23,E23,G23,I23)/300,1),0)+IF(ISNUMBER(J23),MIN(J23/30,1),0)+IF(ISNUMBER(K23),MIN(K23/10,1),0))/MAX(1,(COUNT(B23,D23,F23,H23)>0)+(COUNT(C23,E23,G23,I23)>0)+ISNUMBER(J23)+ISNUMBER(K23)))) | M23: =IF(L23="","",IF(L23>=0.7,5,IF(L23>=0.4,3,1)))
L24: =IF(COUNT(B24:K24)=0,"",MIN(1,(IF(COUNT(B24,D24,F24,H24)>0,AVERAGE(B24,D24,F24,H24)/5,0)+IF(COUNT(C24,E24,G24,I24)>0,MIN(SUM(C24,E24,G24,I24)/300,1),0)+IF(ISNUMBER(J24),MIN(J24/30,1),0)+IF(ISNUMBER(K24),MIN(K24/10,1),0))/MAX(1,(COUNT(B24,D24,F24,H24)>0)+(COUNT(C24,E24,G24,I24)>0)+ISNUMBER(J24)+ISNUMBER(K24)))) | M24: =IF(L24="","",IF(L24>=0.7,5,IF(L24>=0.4,3,1)))
L25: =IF(COUNT(B25:K25)=0,"",MIN(1,(IF(COUNT(B25,D25,F25,H25)>0,AVERAGE(B25,D25,F25,H25)/5,0)+IF(COUNT(C25,E25,G25,I25)>0,MIN(SUM(C25,E25,G25,I25)/300,1),0)+IF(ISNUMBER(J25),MIN(J25/30,1),0)+IF(ISNUMBER(K25),MIN(K25/10,1),0))/MAX(1,(COUNT(B25,D25,F25,H25)>0)+(COUNT(C25,E25,G25,I25)>0)+ISNUMBER(J25)+ISNUMBER(K25)))) | M25: =IF(L25="","",IF(L25>=0.7,5,IF(L25>=0.4,3,1)))
L26: =IF(COUNT(B26:K26)=0,"",MIN(1,(IF(COUNT(B26,D26,F26,H26)>0,AVERAGE(B26,D26,F26,H26)/5,0)+IF(COUNT(C26,E26,G26,I26)>0,MIN(SUM(C26,E26,G26,I26)/300,1),0)+IF(ISNUMBER(J26),MIN(J26/30,1),0)+IF(ISNUMBER(K26),MIN(K26/10,1),0))/MAX(1,(COUNT(B26,D26,F26,H26)>0)+(COUNT(C26,E26,G26,I26)>0)+ISNUMBER(J26)+ISNUMBER(K26)))) | M26: =IF(L26="","",IF(L26>=0.7,5,IF(L26>=0.4,3,1)))
L27: =IF(COUNT(B27:K27)=0,"",MIN(1,(IF(COUNT(B27,D27,F27,H27)>0,AVERAGE(B27,D27,F27,H27)/5,0)+IF(COUNT(C27,E27,G27,I27)>0,MIN(SUM(C27,E27,G27,I27)/300,1),0)+IF(ISNUMBER(J27),MIN(J27/30,1),0)+IF(ISNUMBER(K27),MIN(K27/10,1),0))/MAX(1,(COUNT(B27,D27,F27,H27)>0)+(COUNT(C27,E27,G27,I27)>0)+ISNUMBER(J27)+ISNUMBER(K27)))) | M27: =IF(L27="","",IF(L27>=0.7,5,IF(L27>=0.4,3,1)))
... L33: =IF(COUNT(B33:K33)=0,"",MIN(1,(IF(COUNT(B33,D33,F33,H33)>0,AVERAGE(B33,D33,F33,H33)/5,0)+IF(COUNT(C33,E33,G33,I33)>0,MIN(SUM(C33,E33,G33,I33)/300,1),0)+IF(ISNUMBER(J33),MIN(J33/30,1),0)+IF(ISNUMBER(K33),MIN(K33/10,1),0))/MAX(1,(COUNT(B33,D33,F33,H33)>0)+(COUNT(C33,E33,G33,I33)>0)+ISNUMBER(J33)+ISNUMBER(K33)))) | M33: =IF(L33="","",IF(L33>=0.7,5,IF(L33>=0.4,3,1)))
A36: Сводный показатель | B36: Значение | C36: Оценка | D36: Интерпретация
A37: Средний индекс доверия конкурентов | B37: =AVERAGE(L4:L33) -> 0.43351852 | C37: =IF(B37>=0.7,"высокий",IF(B37>=0.4,"средний","низкий")) -> средний | D37: Высокий индекс означает сильный репутационный барьер.
A38: Среднее число отзывов на конкурента | B38: =SUM(C4:C33,E4:E33,G4:G33,I4:I33)/COUNTA(A4:A33) -> 43.75 | C38: =IF(B38>='01_Параметры'!B17,"высокий барьер",IF(B38>='01_Параметры'!B17*0.5,"средний барьер","низкий барьер")) -> низкий барьер | D38: Среднее число отзывов на конкурента (G2, Capterra, Trustpilot); отзывы Google, кейсы и возраст бренда - по сайтам конкурентов

Sheet 06_Технологии_финансы
A1: Оценка технологических, финансовых и организационных барьеров
A2: Используйте Crunchbase, LinkedIn, BuiltWith, Wappalyzer, рекламные библиотеки, GitHub, вакансии и сайты конкурентов
A3: Конкурент | B3: Финансирование / инвестиции | C3: Сотрудники LinkedIn | D3: Технологический стек 1-5 | E3: CRM/автоматизация 1-5 | F3: Мобильное приложение | G3: Личный кабинет | H3: Активных объявлений | I3: Вакансий | J3: Патенты/уникальные активы | K3: Индекс ресурсной силы | L3: Балльная оценка 1-5 | M3: Комментарий
A4: shortcut.ai | D4: 5 | E4: 5 | K4: =IF(COUNTA(B4:J4)=0,"",MIN(1,(IF(ISNUMBER(B4),MIN(B4/500000,1),0)+IF(ISNUMBER(C4),MIN(C4/60,1),0)+IF(ISNUMBER(D4),D4/5,0)+IF(ISNUMBER(E4),E4/5,0)+IF(F4="да",1,0)+IF(G4="да",1,0)+IF(ISNUMBER(H4),MIN(H4/50,1),0)+IF(ISNUMBER(I4),MIN(I4/6,1),0)+IF(ISNUMBER(J4),IF(J4>0,1,0),0))/MAX(1,ISNUMBER(B4)+ISNUMBER(C4)+ISNUMBER(D4)+ISNUMBER(E4)+(F4<>"")+(G4<>"")+ISNUMBER(H4)+ISNUMBER(I4)+ISNUMBER(J4)))) -> 1 | L4: =IF(K4="","",IF(K4>=0.7,5,IF(K4>=0.4,3,1))) -> 5 | M4: D и E - экспертные баллы (Д-17); финансирование и штат - по открытым источникам (ЛР5, приложение Д)
A5: perfectxl.com | D5: 3 | E5: 3 | K5: =IF(COUNTA(B5:J5)=0,"",MIN(1,(IF(ISNUMBER(B5),MIN(B5/500000,1),0)+IF(ISNUMBER(C5),MIN(C5/60,1),0)+IF(ISNUMBER(D5),D5/5,0)+IF(ISNUMBER(E5),E5/5,0)+IF(F5="да",1,0)+IF(G5="да",1,0)+IF(ISNUMBER(H5),MIN(H5/50,1),0)+IF(ISNUMBER(I5),MIN(I5/6,1),0)+IF(ISNUMBER(J5),IF(J5>0,1,0),0))/MAX(1,ISNUMBER(B5)+ISNUMBER(C5)+ISNUMBER(D5)+ISNUMBER(E5)+(F5<>"")+(G5<>"")+ISNUMBER(H5)+ISNUMBER(I5)+ISNUMBER(J5)))) -> 0.6 | L5: =IF(K5="","",IF(K5>=0.7,5,IF(K5>=0.4,3,1))) -> 3 | M5: D и E - экспертные баллы (Д-17); финансирование и штат - по открытым источникам (ЛР5, приложение Д)
A6: rows.com | D6: 5 | E6: 4 | K6: =IF(COUNTA(B6:J6)=0,"",MIN(1,(IF(ISNUMBER(B6),MIN(B6/500000,1),0)+IF(ISNUMBER(C6),MIN(C6/60,1),0)+IF(ISNUMBER(D6),D6/5,0)+IF(ISNUMBER(E6),E6/5,0)+IF(F6="да",1,0)+IF(G6="да",1,0)+IF(ISNUMBER(H6),MIN(H6/50,1),0)+IF(ISNUMBER(I6),MIN(I6/6,1),0)+IF(ISNUMBER(J6),IF(J6>0,1,0),0))/MAX(1,ISNUMBER(B6)+ISNUMBER(C6)+ISNUMBER(D6)+ISNUMBER(E6)+(F6<>"")+(G6<>"")+ISNUMBER(H6)+ISNUMBER(I6)+ISNUMBER(J6)))) -> 0.9 | L6: =IF(K6="","",IF(K6>=0.7,5,IF(K6>=0.4,3,1))) -> 5 | M6: D и E - экспертные баллы (Д-17); финансирование и штат - по открытым источникам (ЛР5, приложение Д)
A7: numerous.ai | D7: 4 | E7: 4 | K7: =IF(COUNTA(B7:J7)=0,"",MIN(1,(IF(ISNUMBER(B7),MIN(B7/500000,1),0)+IF(ISNUMBER(C7),MIN(C7/60,1),0)+IF(ISNUMBER(D7),D7/5,0)+IF(ISNUMBER(E7),E7/5,0)+IF(F7="да",1,0)+IF(G7="да",1,0)+IF(ISNUMBER(H7),MIN(H7/50,1),0)+IF(ISNUMBER(I7),MIN(I7/6,1),0)+IF(ISNUMBER(J7),IF(J7>0,1,0),0))/MAX(1,ISNUMBER(B7)+ISNUMBER(C7)+ISNUMBER(D7)+ISNUMBER(E7)+(F7<>"")+(G7<>"")+ISNUMBER(H7)+ISNUMBER(I7)+ISNUMBER(J7)))) -> 0.8 | L7: =IF(K7="","",IF(K7>=0.7,5,IF(K7>=0.4,3,1))) -> 5 | M7: D и E - экспертные баллы (Д-17); финансирование и штат - по открытым источникам (ЛР5, приложение Д)
A8: operis.com | D8: 3 | E8: 2 | K8: =IF(COUNTA(B8:J8)=0,"",MIN(1,(IF(ISNUMBER(B8),MIN(B8/500000,1),0)+IF(ISNUMBER(C8),MIN(C8/60,1),0)+IF(ISNUMBER(D8),D8/5,0)+IF(ISNUMBER(E8),E8/5,0)+IF(F8="да",1,0)+IF(G8="да",1,0)+IF(ISNUMBER(H8),MIN(H8/50,1),0)+IF(ISNUMBER(I8),MIN(I8/6,1),0)+IF(ISNUMBER(J8),IF(J8>0,1,0),0))/MAX(1,ISNUMBER(B8)+ISNUMBER(C8)+ISNUMBER(D8)+ISNUMBER(E8)+(F8<>"")+(G8<>"")+ISNUMBER(H8)+ISNUMBER(I8)+ISNUMBER(J8)))) -> 0.5 | L8: =IF(K8="","",IF(K8>=0.7,5,IF(K8>=0.4,3,1))) -> 3 | M8: D и E - экспертные баллы (Д-17); финансирование и штат - по открытым источникам (ЛР5, приложение Д)
A9: arixcel.com | D9: 2 | E9: 2 | K9: =IF(COUNTA(B9:J9)=0,"",MIN(1,(IF(ISNUMBER(B9),MIN(B9/500000,1),0)+IF(ISNUMBER(C9),MIN(C9/60,1),0)+IF(ISNUMBER(D9),D9/5,0)+IF(ISNUMBER(E9),E9/5,0)+IF(F9="да",1,0)+IF(G9="да",1,0)+IF(ISNUMBER(H9),MIN(H9/50,1),0)+IF(ISNUMBER(I9),MIN(I9/6,1),0)+IF(ISNUMBER(J9),IF(J9>0,1,0),0))/MAX(1,ISNUMBER(B9)+ISNUMBER(C9)+ISNUMBER(D9)+ISNUMBER(E9)+(F9<>"")+(G9<>"")+ISNUMBER(H9)+ISNUMBER(I9)+ISNUMBER(J9)))) -> 0.4 | L9: =IF(K9="","",IF(K9>=0.7,5,IF(K9>=0.4,3,1))) -> 3 | M9: D и E - экспертные баллы (Д-17); финансирование и штат - по открытым источникам (ЛР5, приложение Д)
A10: formulabot.com | D10: 3 | E10: 3 | K10: =IF(COUNTA(B10:J10)=0,"",MIN(1,(IF(ISNUMBER(B10),MIN(B10/500000,1),0)+IF(ISNUMBER(C10),MIN(C10/60,1),0)+IF(ISNUMBER(D10),D10/5,0)+IF(ISNUMBER(E10),E10/5,0)+IF(F10="да",1,0)+IF(G10="да",1,0)+IF(ISNUMBER(H10),MIN(H10/50,1),0)+IF(ISNUMBER(I10),MIN(I10/6,1),0)+IF(ISNUMBER(J10),IF(J10>0,1,0),0))/MAX(1,ISNUMBER(B10)+ISNUMBER(C10)+ISNUMBER(D10)+ISNUMBER(E10)+(F10<>"")+(G10<>"")+ISNUMBER(H10)+ISNUMBER(I10)+ISNUMBER(J10)))) -> 0.6 | L10: =IF(K10="","",IF(K10>=0.7,5,IF(K10>=0.4,3,1))) -> 3 | M10: D и E - экспертные баллы (Д-17); финансирование и штат - по открытым источникам (ЛР5, приложение Д)
A11: ajelix.com | D11: 3 | E11: 3 | K11: =IF(COUNTA(B11:J11)=0,"",MIN(1,(IF(ISNUMBER(B11),MIN(B11/500000,1),0)+IF(ISNUMBER(C11),MIN(C11/60,1),0)+IF(ISNUMBER(D11),D11/5,0)+IF(ISNUMBER(E11),E11/5,0)+IF(F11="да",1,0)+IF(G11="да",1,0)+IF(ISNUMBER(H11),MIN(H11/50,1),0)+IF(ISNUMBER(I11),MIN(I11/6,1),0)+IF(ISNUMBER(J11),IF(J11>0,1,0),0))/MAX(1,ISNUMBER(B11)+ISNUMBER(C11)+ISNUMBER(D11)+ISNUMBER(E11)+(F11<>"")+(G11<>"")+ISNUMBER(H11)+ISNUMBER(I11)+ISNUMBER(J11)))) -> 0.6 | L11: =IF(K11="","",IF(K11>=0.7,5,IF(K11>=0.4,3,1))) -> 3 | M11: D и E - экспертные баллы (Д-17); финансирование и штат - по открытым источникам (ЛР5, приложение Д)
A12: datarails.com | D12: 5 | E12: 5 | K12: =IF(COUNTA(B12:J12)=0,"",MIN(1,(IF(ISNUMBER(B12),MIN(B12/500000,1),0)+IF(ISNUMBER(C12),MIN(C12/60,1),0)+IF(ISNUMBER(D12),D12/5,0)+IF(ISNUMBER(E12),E12/5,0)+IF(F12="да",1,0)+IF(G12="да",1,0)+IF(ISNUMBER(H12),MIN(H12/50,1),0)+IF(ISNUMBER(I12),MIN(I12/6,1),0)+IF(ISNUMBER(J12),IF(J12>0,1,0),0))/MAX(1,ISNUMBER(B12)+ISNUMBER(C12)+ISNUMBER(D12)+ISNUMBER(E12)+(F12<>"")+(G12<>"")+ISNUMBER(H12)+ISNUMBER(I12)+ISNUMBER(J12)))) -> 1 | L12: =IF(K12="","",IF(K12>=0.7,5,IF(K12>=0.4,3,1))) -> 5 | M12: D и E - экспертные баллы (Д-17); финансирование и штат - по открытым источникам (ЛР5, приложение Д)
A13: julius.ai | D13: 5 | E13: 4 | K13: =IF(COUNTA(B13:J13)=0,"",MIN(1,(IF(ISNUMBER(B13),MIN(B13/500000,1),0)+IF(ISNUMBER(C13),MIN(C13/60,1),0)+IF(ISNUMBER(D13),D13/5,0)+IF(ISNUMBER(E13),E13/5,0)+IF(F13="да",1,0)+IF(G13="да",1,0)+IF(ISNUMBER(H13),MIN(H13/50,1),0)+IF(ISNUMBER(I13),MIN(I13/6,1),0)+IF(ISNUMBER(J13),IF(J13>0,1,0),0))/MAX(1,ISNUMBER(B13)+ISNUMBER(C13)+ISNUMBER(D13)+ISNUMBER(E13)+(F13<>"")+(G13<>"")+ISNUMBER(H13)+ISNUMBER(I13)+ISNUMBER(J13)))) -> 0.9 | L13: =IF(K13="","",IF(K13>=0.7,5,IF(K13>=0.4,3,1))) -> 5 | M13: D и E - экспертные баллы (Д-17); финансирование и штат - по открытым источникам (ЛР5, приложение Д)
A14: spreadsheetdetective.com | D14: 2 | E14: 1 | K14: =IF(COUNTA(B14:J14)=0,"",MIN(1,(IF(ISNUMBER(B14),MIN(B14/500000,1),0)+IF(ISNUMBER(C14),MIN(C14/60,1),0)+IF(ISNUMBER(D14),D14/5,0)+IF(ISNUMBER(E14),E14/5,0)+IF(F14="да",1,0)+IF(G14="да",1,0)+IF(ISNUMBER(H14),MIN(H14/50,1),0)+IF(ISNUMBER(I14),MIN(I14/6,1),0)+IF(ISNUMBER(J14),IF(J14>0,1,0),0))/MAX(1,ISNUMBER(B14)+ISNUMBER(C14)+ISNUMBER(D14)+ISNUMBER(E14)+(F14<>"")+(G14<>"")+ISNUMBER(H14)+ISNUMBER(I14)+ISNUMBER(J14)))) -> 0.3 | L14: =IF(K14="","",IF(K14>=0.7,5,IF(K14>=0.4,3,1))) -> 1 | M14: D и E - экспертные баллы (Д-17); финансирование и штат - по открытым источникам (ЛР5, приложение Д)
A15: cimcon.com | D15: 4 | E15: 4 | K15: =IF(COUNTA(B15:J15)=0,"",MIN(1,(IF(ISNUMBER(B15),MIN(B15/500000,1),0)+IF(ISNUMBER(C15),MIN(C15/60,1),0)+IF(ISNUMBER(D15),D15/5,0)+IF(ISNUMBER(E15),E15/5,0)+IF(F15="да",1,0)+IF(G15="да",1,0)+IF(ISNUMBER(H15),MIN(H15/50,1),0)+IF(ISNUMBER(I15),MIN(I15/6,1),0)+IF(ISNUMBER(J15),IF(J15>0,1,0),0))/MAX(1,ISNUMBER(B15)+ISNUMBER(C15)+ISNUMBER(D15)+ISNUMBER(E15)+(F15<>"")+(G15<>"")+ISNUMBER(H15)+ISNUMBER(I15)+ISNUMBER(J15)))) -> 0.8 | L15: =IF(K15="","",IF(K15>=0.7,5,IF(K15>=0.4,3,1))) -> 5 | M15: D и E - экспертные баллы (Д-17); финансирование и штат - по открытым источникам (ЛР5, приложение Д)
K16: =IF(COUNTA(B16:J16)=0,"",MIN(1,(IF(ISNUMBER(B16),MIN(B16/500000,1),0)+IF(ISNUMBER(C16),MIN(C16/60,1),0)+IF(ISNUMBER(D16),D16/5,0)+IF(ISNUMBER(E16),E16/5,0)+IF(F16="да",1,0)+IF(G16="да",1,0)+IF(ISNUMBER(H16),MIN(H16/50,1),0)+IF(ISNUMBER(I16),MIN(I16/6,1),0)+IF(ISNUMBER(J16),IF(J16>0,1,0),0))/MAX(1,ISNUMBER(B16)+ISNUMBER(C16)+ISNUMBER(D16)+ISNUMBER(E16)+(F16<>"")+(G16<>"")+ISNUMBER(H16)+ISNUMBER(I16)+ISNUMBER(J16)))) | L16: =IF(K16="","",IF(K16>=0.7,5,IF(K16>=0.4,3,1)))
K17: =IF(COUNTA(B17:J17)=0,"",MIN(1,(IF(ISNUMBER(B17),MIN(B17/500000,1),0)+IF(ISNUMBER(C17),MIN(C17/60,1),0)+IF(ISNUMBER(D17),D17/5,0)+IF(ISNUMBER(E17),E17/5,0)+IF(F17="да",1,0)+IF(G17="да",1,0)+IF(ISNUMBER(H17),MIN(H17/50,1),0)+IF(ISNUMBER(I17),MIN(I17/6,1),0)+IF(ISNUMBER(J17),IF(J17>0,1,0),0))/MAX(1,ISNUMBER(B17)+ISNUMBER(C17)+ISNUMBER(D17)+ISNUMBER(E17)+(F17<>"")+(G17<>"")+ISNUMBER(H17)+ISNUMBER(I17)+ISNUMBER(J17)))) | L17: =IF(K17="","",IF(K17>=0.7,5,IF(K17>=0.4,3,1)))
K18: =IF(COUNTA(B18:J18)=0,"",MIN(1,(IF(ISNUMBER(B18),MIN(B18/500000,1),0)+IF(ISNUMBER(C18),MIN(C18/60,1),0)+IF(ISNUMBER(D18),D18/5,0)+IF(ISNUMBER(E18),E18/5,0)+IF(F18="да",1,0)+IF(G18="да",1,0)+IF(ISNUMBER(H18),MIN(H18/50,1),0)+IF(ISNUMBER(I18),MIN(I18/6,1),0)+IF(ISNUMBER(J18),IF(J18>0,1,0),0))/MAX(1,ISNUMBER(B18)+ISNUMBER(C18)+ISNUMBER(D18)+ISNUMBER(E18)+(F18<>"")+(G18<>"")+ISNUMBER(H18)+ISNUMBER(I18)+ISNUMBER(J18)))) | L18: =IF(K18="","",IF(K18>=0.7,5,IF(K18>=0.4,3,1)))
K19: =IF(COUNTA(B19:J19)=0,"",MIN(1,(IF(ISNUMBER(B19),MIN(B19/500000,1),0)+IF(ISNUMBER(C19),MIN(C19/60,1),0)+IF(ISNUMBER(D19),D19/5,0)+IF(ISNUMBER(E19),E19/5,0)+IF(F19="да",1,0)+IF(G19="да",1,0)+IF(ISNUMBER(H19),MIN(H19/50,1),0)+IF(ISNUMBER(I19),MIN(I19/6,1),0)+IF(ISNUMBER(J19),IF(J19>0,1,0),0))/MAX(1,ISNUMBER(B19)+ISNUMBER(C19)+ISNUMBER(D19)+ISNUMBER(E19)+(F19<>"")+(G19<>"")+ISNUMBER(H19)+ISNUMBER(I19)+ISNUMBER(J19)))) | L19: =IF(K19="","",IF(K19>=0.7,5,IF(K19>=0.4,3,1)))
K20: =IF(COUNTA(B20:J20)=0,"",MIN(1,(IF(ISNUMBER(B20),MIN(B20/500000,1),0)+IF(ISNUMBER(C20),MIN(C20/60,1),0)+IF(ISNUMBER(D20),D20/5,0)+IF(ISNUMBER(E20),E20/5,0)+IF(F20="да",1,0)+IF(G20="да",1,0)+IF(ISNUMBER(H20),MIN(H20/50,1),0)+IF(ISNUMBER(I20),MIN(I20/6,1),0)+IF(ISNUMBER(J20),IF(J20>0,1,0),0))/MAX(1,ISNUMBER(B20)+ISNUMBER(C20)+ISNUMBER(D20)+ISNUMBER(E20)+(F20<>"")+(G20<>"")+ISNUMBER(H20)+ISNUMBER(I20)+ISNUMBER(J20)))) | L20: =IF(K20="","",IF(K20>=0.7,5,IF(K20>=0.4,3,1)))
K21: =IF(COUNTA(B21:J21)=0,"",MIN(1,(IF(ISNUMBER(B21),MIN(B21/500000,1),0)+IF(ISNUMBER(C21),MIN(C21/60,1),0)+IF(ISNUMBER(D21),D21/5,0)+IF(ISNUMBER(E21),E21/5,0)+IF(F21="да",1,0)+IF(G21="да",1,0)+IF(ISNUMBER(H21),MIN(H21/50,1),0)+IF(ISNUMBER(I21),MIN(I21/6,1),0)+IF(ISNUMBER(J21),IF(J21>0,1,0),0))/MAX(1,ISNUMBER(B21)+ISNUMBER(C21)+ISNUMBER(D21)+ISNUMBER(E21)+(F21<>"")+(G21<>"")+ISNUMBER(H21)+ISNUMBER(I21)+ISNUMBER(J21)))) | L21: =IF(K21="","",IF(K21>=0.7,5,IF(K21>=0.4,3,1)))
K22: =IF(COUNTA(B22:J22)=0,"",MIN(1,(IF(ISNUMBER(B22),MIN(B22/500000,1),0)+IF(ISNUMBER(C22),MIN(C22/60,1),0)+IF(ISNUMBER(D22),D22/5,0)+IF(ISNUMBER(E22),E22/5,0)+IF(F22="да",1,0)+IF(G22="да",1,0)+IF(ISNUMBER(H22),MIN(H22/50,1),0)+IF(ISNUMBER(I22),MIN(I22/6,1),0)+IF(ISNUMBER(J22),IF(J22>0,1,0),0))/MAX(1,ISNUMBER(B22)+ISNUMBER(C22)+ISNUMBER(D22)+ISNUMBER(E22)+(F22<>"")+(G22<>"")+ISNUMBER(H22)+ISNUMBER(I22)+ISNUMBER(J22)))) | L22: =IF(K22="","",IF(K22>=0.7,5,IF(K22>=0.4,3,1)))
K23: =IF(COUNTA(B23:J23)=0,"",MIN(1,(IF(ISNUMBER(B23),MIN(B23/500000,1),0)+IF(ISNUMBER(C23),MIN(C23/60,1),0)+IF(ISNUMBER(D23),D23/5,0)+IF(ISNUMBER(E23),E23/5,0)+IF(F23="да",1,0)+IF(G23="да",1,0)+IF(ISNUMBER(H23),MIN(H23/50,1),0)+IF(ISNUMBER(I23),MIN(I23/6,1),0)+IF(ISNUMBER(J23),IF(J23>0,1,0),0))/MAX(1,ISNUMBER(B23)+ISNUMBER(C23)+ISNUMBER(D23)+ISNUMBER(E23)+(F23<>"")+(G23<>"")+ISNUMBER(H23)+ISNUMBER(I23)+ISNUMBER(J23)))) | L23: =IF(K23="","",IF(K23>=0.7,5,IF(K23>=0.4,3,1)))
K24: =IF(COUNTA(B24:J24)=0,"",MIN(1,(IF(ISNUMBER(B24),MIN(B24/500000,1),0)+IF(ISNUMBER(C24),MIN(C24/60,1),0)+IF(ISNUMBER(D24),D24/5,0)+IF(ISNUMBER(E24),E24/5,0)+IF(F24="да",1,0)+IF(G24="да",1,0)+IF(ISNUMBER(H24),MIN(H24/50,1),0)+IF(ISNUMBER(I24),MIN(I24/6,1),0)+IF(ISNUMBER(J24),IF(J24>0,1,0),0))/MAX(1,ISNUMBER(B24)+ISNUMBER(C24)+ISNUMBER(D24)+ISNUMBER(E24)+(F24<>"")+(G24<>"")+ISNUMBER(H24)+ISNUMBER(I24)+ISNUMBER(J24)))) | L24: =IF(K24="","",IF(K24>=0.7,5,IF(K24>=0.4,3,1)))
K25: =IF(COUNTA(B25:J25)=0,"",MIN(1,(IF(ISNUMBER(B25),MIN(B25/500000,1),0)+IF(ISNUMBER(C25),MIN(C25/60,1),0)+IF(ISNUMBER(D25),D25/5,0)+IF(ISNUMBER(E25),E25/5,0)+IF(F25="да",1,0)+IF(G25="да",1,0)+IF(ISNUMBER(H25),MIN(H25/50,1),0)+IF(ISNUMBER(I25),MIN(I25/6,1),0)+IF(ISNUMBER(J25),IF(J25>0,1,0),0))/MAX(1,ISNUMBER(B25)+ISNUMBER(C25)+ISNUMBER(D25)+ISNUMBER(E25)+(F25<>"")+(G25<>"")+ISNUMBER(H25)+ISNUMBER(I25)+ISNUMBER(J25)))) | L25: =IF(K25="","",IF(K25>=0.7,5,IF(K25>=0.4,3,1)))
K26: =IF(COUNTA(B26:J26)=0,"",MIN(1,(IF(ISNUMBER(B26),MIN(B26/500000,1),0)+IF(ISNUMBER(C26),MIN(C26/60,1),0)+IF(ISNUMBER(D26),D26/5,0)+IF(ISNUMBER(E26),E26/5,0)+IF(F26="да",1,0)+IF(G26="да",1,0)+IF(ISNUMBER(H26),MIN(H26/50,1),0)+IF(ISNUMBER(I26),MIN(I26/6,1),0)+IF(ISNUMBER(J26),IF(J26>0,1,0),0))/MAX(1,ISNUMBER(B26)+ISNUMBER(C26)+ISNUMBER(D26)+ISNUMBER(E26)+(F26<>"")+(G26<>"")+ISNUMBER(H26)+ISNUMBER(I26)+ISNUMBER(J26)))) | L26: =IF(K26="","",IF(K26>=0.7,5,IF(K26>=0.4,3,1)))
K27: =IF(COUNTA(B27:J27)=0,"",MIN(1,(IF(ISNUMBER(B27),MIN(B27/500000,1),0)+IF(ISNUMBER(C27),MIN(C27/60,1),0)+IF(ISNUMBER(D27),D27/5,0)+IF(ISNUMBER(E27),E27/5,0)+IF(F27="да",1,0)+IF(G27="да",1,0)+IF(ISNUMBER(H27),MIN(H27/50,1),0)+IF(ISNUMBER(I27),MIN(I27/6,1),0)+IF(ISNUMBER(J27),IF(J27>0,1,0),0))/MAX(1,ISNUMBER(B27)+ISNUMBER(C27)+ISNUMBER(D27)+ISNUMBER(E27)+(F27<>"")+(G27<>"")+ISNUMBER(H27)+ISNUMBER(I27)+ISNUMBER(J27)))) | L27: =IF(K27="","",IF(K27>=0.7,5,IF(K27>=0.4,3,1)))
... K33: =IF(COUNTA(B33:J33)=0,"",MIN(1,(IF(ISNUMBER(B33),MIN(B33/500000,1),0)+IF(ISNUMBER(C33),MIN(C33/60,1),0)+IF(ISNUMBER(D33),D33/5,0)+IF(ISNUMBER(E33),E33/5,0)+IF(F33="да",1,0)+IF(G33="да",1,0)+IF(ISNUMBER(H33),MIN(H33/50,1),0)+IF(ISNUMBER(I33),MIN(I33/6,1),0)+IF(ISNUMBER(J33),IF(J33>0,1,0),0))/MAX(1,ISNUMBER(B33)+ISNUMBER(C33)+ISNUMBER(D33)+ISNUMBER(E33)+(F33<>"")+(G33<>"")+ISNUMBER(H33)+ISNUMBER(I33)+ISNUMBER(J33)))) | L33: =IF(K33="","",IF(K33>=0.7,5,IF(K33>=0.4,3,1)))
A36: Сводный показатель | B36: Значение | C36: Оценка | D36: Интерпретация
A37: Средний индекс ресурсной силы | B37: =AVERAGE(K4:K33) -> 0.7 | C37: =IF(B37>=0.7,"высокая",IF(B37>=0.4,"средняя","низкая")) -> высокая | D37: Высокая ресурсная сила конкурентов повышает барьеры входа.
A38: Доля конкурентов с личным кабинетом/приложением | B38: =(COUNTIF(F4:F33,"да")+COUNTIF(G4:G33,"да"))/(2*COUNTA(A4:A33)) -> 0 | C38: =IF(B38>=0.75,"высокая цифровая зрелость",IF(B38>=0.35,"средняя цифровая зрелость","низкая цифровая зрелость")) -> низкая цифровая зрелость | D38: Показывает степень цифровой зрелости конкурентов.

Sheet 07_Барьеры_входа
A1: Сводная оценка уровня конкуренции и барьеров входа
A2: Баллы 1/3/5 формируются из расчетных листов. Веса можно корректировать в зависимости от рынка.
A3: Фактор барьера входа | B3: Ключевой показатель | C3: Значение | D3: Балльная оценка 1-5 | E3: Вес | F3: Взвешенный балл | G3: Уровень давления | H3: Что означает | I3: Рекомендуемое действие
A4: Концентрация трафика | B4: CR3 / CR5 / HHI | C4: ='02_Конкуренты_SW'!B38 -> 0.52342572 | D4: =IF(OR('02_Конкуренты_SW'!B38>='01_Параметры'!B11,'02_Конкуренты_SW'!B40>='01_Параметры'!B13),5,IF(OR('02_Конкуренты_SW'!B38>='01_Параметры'!B11*0.65,'02_Конкуренты_SW'!B40>='01_Параметры'!B13*0.65),3,1)) -> 3 | E4: 0.16 | F4: =D4*E4 -> 0.48 | G4: =IF(D4>=5,"высокое",IF(D4>=3,"среднее","низкое")) -> среднее | H4: Лидеры контролируют значимую часть цифрового спроса. | I4: Искать узкие сегменты и менее занятые каналы.
A5: Органическое SEO-давление | B5: Доля органического трафика конкурентов | C5: ='03_Каналы_трафика'!C5 -> 0.33621025 | D5: ='03_Каналы_трафика'!E5 -> 3 | E5: 0.12 | F5: =D5*E5 -> 0.36 | G5: =IF(D5>=5,"высокое",IF(D5>=3,"среднее","низкое")) -> среднее | H5: Конкуренты занимают поисковую видимость. | I5: Планировать контент, поисковую оптимизацию и долгий горизонт входа.
A6: Платное рекламное давление | B6: Доля paid search + рекламная активность | C6: =AVERAGE('03_Каналы_трафика'!C6,'04_Поиск_реклама'!B37) -> 0.044003954 | D6: =IF(C6>=0.6,5,IF(C6>=0.35,3,1)) -> 1 | E6: 0.12 | F6: =D6*E6 -> 0.12 | G6: =IF(D6>=5,"высокое",IF(D6>=3,"среднее","низкое")) -> низкое | H6: Вход через рекламу требует бюджета. | I6: Проверить стоимость клика и юнит-экономику.
A7: Брендовая сила конкурентов | B7: Direct + брендовый поиск | C7: ='03_Каналы_трафика'!C10 -> 0.42811271 | D7: ='03_Каналы_трафика'!E10 -> 3 | E7: 0.12 | F7: =D7*E7 -> 0.36 | G7: =IF(D7>=5,"высокое",IF(D7>=3,"среднее","низкое")) -> среднее | H7: Клиенты уже знают действующих игроков. | I7: Строить доверие, кейсы, репутацию и рекомендации.
A8: Поисково-рекламная конкуренция | B8: CPC, PPC, SEO difficulty (при отсутствии - прокси: органика и платный поиск Similarweb к порогам) | C8: =IF(ISNUMBER('04_Поиск_реклама'!B37),'04_Поиск_реклама'!B37,AVERAGE(MIN('03_Каналы_трафика'!C5/'01_Параметры'!B15,1),MIN('03_Каналы_трафика'!C6/'01_Параметры'!B14,1))) -> 0.48357683 | D8: =IF(C8>=0.7,5,IF(C8>=0.4,3,1)) -> 3 | E8: 0.12 | F8: =D8*E8 -> 0.36 | G8: =IF(D8>=5,"высокое",IF(D8>=3,"среднее","низкое")) -> среднее | H8: Коммерческие запросы заняты сильными игроками. | I8: Выбирать длинные и проблемные запросы.
A9: Репутационный барьер | B9: Отзывы, рейтинги, кейсы | C9: ='05_Отзывы_рейтинги'!B37 -> 0.43351852 | D9: =IF(C9>=0.7,5,IF(C9>=0.4,3,1)) -> 3 | E9: 0.12 | F9: =D9*E9 -> 0.36 | G9: =IF(D9>=5,"высокое",IF(D9>=3,"среднее","низкое")) -> среднее | H9: У конкурентов накоплены отзывы и социальное доказательство. | I9: Запускать пилоты, собирать отзывы, демонстрировать кейсы.
A10: Технологический и ресурсный барьер | B10: Стек, команда, финансирование, автоматизация | C10: ='06_Технологии_финансы'!B37 -> 0.7 | D10: =IF(C10>=0.7,5,IF(C10>=0.4,3,1)) -> 5 | E10: 0.12 | F10: =D10*E10 -> 0.6 | G10: =IF(D10>=5,"высокое",IF(D10>=3,"среднее","низкое")) -> высокое | H10: Конкуренты защищены ресурсами или цифровой инфраструктурой. | I10: Фокусироваться на нише и сервисном преимуществе.
A11: Платформенная зависимость | B11: Доля планируемых каналов через внешние платформы (AppSource, Product Hunt, поиск) из каналов ПЗ1 | C11: 0.6 | D11: =IF(C11>=0.7,5,IF(C11>=0.4,3,1)) -> 3 | E11: 0.08 | F11: =D11*E11 -> 0.24 | G11: =IF(D11>=5,"высокое",IF(D11>=3,"среднее","низкое")) -> среднее | H11: Доступ к клиенту контролируется платформами. | I11: Диверсифицировать каналы и строить собственную базу клиентов.
A12: Угроза заменителей | B12: Доля релевантного трафика, приходящаяся на частичных конкурентов и заменителей | C12: =IFERROR(1-SUMPRODUCT(('02_Конкуренты_SW'!B4:B33<>"")*(LEFT('02_Конкуренты_SW'!B4:B33,6)="прямой")*'02_Конкуренты_SW'!E4:E33)/SUM('02_Конкуренты_SW'!E4:E33),0) -> 0.72802215 | D12: =IF(C12>=0.7,5,IF(C12>=0.4,3,1)) -> 5 | E12: 0.08 | F12: =D12*E12 -> 0.4 | G12: =IF(D12>=5,"высокое",IF(D12>=3,"среднее","низкое")) -> высокое | H12: Клиент может решить задачу альтернативным способом. | I12: Уточнить ценность: результат, скорость, экспертиза, сопровождение.
A13: Суммарный индекс барьеров входа | C13: =F13 -> 3.1538462 | D13: =C13 -> 3.1538462 | E13: 1 | F13: =SUM(F4:F12)/SUM(E4:E12) -> 3.1538462 | G13: =IF(F13>=4,"высокие барьеры",IF(F13>=2.5,"средние барьеры","низкие барьеры")) -> средние барьеры | H13: Интегральная оценка давления (сумма весов в шаблоне 1,04, поэтому делится на сумму весов). | I13: Использовать как итоговый вывод для анализа входа на рынок.

Sheet 08_Дашборд
A1: Дашборд оценки уровня конкуренции и барьеров входа
A2: Итоговые показатели автоматически подтягиваются из расчетных листов
A4: KPI | B4: Значение | C4: Ед. | D4: Интерпретация | F4: Фактор | G4: Балл | H4: Вес | I4: Взвешенный балл
A5: Индекс барьеров входа | B5: ='07_Барьеры_входа'!F13 -> 3.1538462 | C5: 1-5 | D5: =IF(B5>=4,"Рынок труден для входа: нужны ресурсы, нишевание или сильное отличие.",IF(B5>=2.5,"Вход возможен, но требует проверки каналов и позиционирования.","Барьеры относительно низкие, но требуется проверка платежеспособности.")) -> Вход возможен, но требует проверки каналов и позиционирования. | F5: Концентрация трафика | G5: ='07_Барьеры_входа'!D4 -> 3 | H5: ='07_Барьеры_входа'!E4 -> 0.16 | I5: ='07_Барьеры_входа'!F4 -> 0.48
A6: Итоговый уровень | B6: ='07_Барьеры_входа'!G13 -> средние барьеры | F6: SEO-давление | G6: ='07_Барьеры_входа'!D5 -> 3 | H6: ='07_Барьеры_входа'!E5 -> 0.12 | I6: ='07_Барьеры_входа'!F5 -> 0.36
A7: CR3 по релевантному трафику | B7: ='02_Конкуренты_SW'!B38 -> 0.52342572 | C7: % | D7: =IF(B7>='01_Параметры'!B11,"Высокая концентрация лидеров",IF(B7>='01_Параметры'!B11*0.65,"Средняя концентрация","Низкая концентрация")) -> Средняя концентрация | F7: Рекламное давление | G7: ='07_Барьеры_входа'!D6 -> 1 | H7: ='07_Барьеры_входа'!E6 -> 0.12 | I7: ='07_Барьеры_входа'!F6 -> 0.12
A8: HHI по релевантному трафику | B8: ='02_Конкуренты_SW'!B40 -> 1359.7074 | C8: индекс | F8: Брендовая сила | G8: ='07_Барьеры_входа'!D7 -> 3 | H8: ='07_Барьеры_входа'!E7 -> 0.12 | I8: ='07_Барьеры_входа'!F7 -> 0.36
A9: Средний поисково-рекламный индекс | B9: ='04_Поиск_реклама'!B37 -> нет данных | C9: % | F9: Поиск/реклама | G9: ='07_Барьеры_входа'!D8 -> 3 | H9: ='07_Барьеры_входа'!E8 -> 0.12 | I9: ='07_Барьеры_входа'!F8 -> 0.36
A10: Средний индекс доверия конкурентов | B10: ='05_Отзывы_рейтинги'!B37 -> 0.43351852 | C10: % | F10: Репутация | G10: ='07_Барьеры_входа'!D9 -> 3 | H10: ='07_Барьеры_входа'!E9 -> 0.12 | I10: ='07_Барьеры_входа'!F9 -> 0.36
A11: Средний индекс ресурсной силы | B11: ='06_Технологии_финансы'!B37 -> 0.7 | C11: % | F11: Технологии | G11: ='07_Барьеры_входа'!D10 -> 5 | H11: ='07_Барьеры_входа'!E10 -> 0.12 | I11: ='07_Барьеры_входа'!F10 -> 0.6
F12: Платформы | G12: ='07_Барьеры_входа'!D11 -> 3 | H12: ='07_Барьеры_входа'!E11 -> 0.08 | I12: ='07_Барьеры_входа'!F11 -> 0.24
F13: Заменители | G13: ='07_Барьеры_входа'!D12 -> 5 | H13: ='07_Барьеры_входа'!E12 -> 0.08 | I13: ='07_Барьеры_входа'!F12 -> 0.4
A14: Итоговая формулировка для отчета
A15: ="По результатам оценки цифровой конкуренции индекс барьеров входа составляет "&ROUND(B5,2)&" из 5, что соответствует уровню: "&B6&". "&"Наиболее значимые факторы давления определены по листу 07_Барьеры_входа. "&"Данные Similarweb и альтернативных источников являются оценочной базой и требуют проверки "&"через фактические коммерческие данные, цены, конверсии и платежеспособность клиентов." -> По результатам оценки цифровой конкуренции индекс барьеров входа составляет 3,15 из 5, что соответствует уровню: средние барьеры. Наиболее значимые факторы давления определены по листу 07_Барьеры_входа. Данные Similarweb и альтернативных источников являются оценочной базой и требуют проверки через фактические коммерческие данные, цены, конверсии и платежеспособность клиентов.

Sheet 09_Источники
A1: Журнал источников данных для оценки конкуренции
A2: Фиксируйте дату обращения, ссылку, что именно взято и ограничения интерпретации
A3: Источник | B3: URL | C3: Что брать | D3: Для какой силы/фактора | E3: Формат фиксации | F3: Дата обращения | G3: Ограничения
A4: Similarweb | B4: https://www.similarweb.com/website/ | C4: визиты, каналы трафика, география, похожие сайты, поисковые запросы | D4: конкуренция, каналы, география, барьеры входа | E4: ручная фиксация / выгрузка при наличии доступа | F4: 46298 | G4: оценочные данные, слабее для малых сайтов
A5: Semrush | B5: https://www.semrush.com/ | C5: органический трафик, paid search, keyword difficulty, конкуренты | D5: SEO и рекламное давление | E5: таблица/скриншот/экспорт при доступе | F5: 46298 | G5: часть данных платная, оценки расчетные
A6: Ahrefs | B6: https://ahrefs.com/ | C6: ссылки, ключевые слова, органическая видимость, конкуренты | D6: SEO-барьеры | E6: таблица/экспорт при доступе | F6: 46298 | G6: зависит от базы и тарифа
A7: G2 | B7: https://www.g2.com/ | C7: отзывы, рейтинги, сравнения, категории B2B-софта | D7: сила покупателей, репутация, заменители | E7: таблица отзывов и рейтингов | F7: 46298 | G7: сильнее для программных продуктов
A8: Capterra | B8: https://www.capterra.com/ | C8: отзывы и рейтинги программных решений | D8: репутация и заменители | E8: таблица отзывов | F8: 46298 | G8: не все локальные рынки представлены
A9: Trustpilot | B9: https://www.trustpilot.com/ | C9: отзывы, рейтинг, динамика доверия | D9: репутационные барьеры | E9: таблица/скриншот | F9: 46298 | G9: разная полнота по странам и нишам
A10: Crunchbase | B10: https://www.crunchbase.com/ | C10: финансирование, сделки, инвесторы, рост компаний | D10: угроза новых игроков, ресурсная сила | E10: таблица компаний | F10: 46298 | G10: многие данные доступны по подписке
A11: BuiltWith | B11: https://builtwith.com/ | C11: технологический стек сайта | D11: технологические барьеры | E11: таблица технологий | F11: 46298 | G11: не показывает всю внутреннюю инфраструктуру
A12: Wappalyzer | B12: https://www.wappalyzer.com/ | C12: технологии сайта, аналитика, CRM, e-commerce stack | D12: технологические барьеры | E12: таблица технологий | F12: 46298 | G12: только видимые технологии
A13: Meta Ad Library | B13: https://www.facebook.com/ads/library/ | C13: активные рекламные объявления | D13: рекламное давление | E13: ссылка/скриншот/число объявлений | F13: 46298 | G13: не дает полный бюджет
A14: Google Ads Transparency Center | B14: https://adstransparency.google.com/ | C14: объявления рекламодателей в Google | D14: рекламное давление | E14: ссылка/скриншот | F14: 46298 | G14: не всегда видно бюджет и эффективность
A15: LinkedIn Ads Library | B15: https://www.linkedin.com/ad-library/ | C15: B2B-реклама и активность брендов | D15: рекламное давление B2B | E15: ссылка/скриншот | F15: 46298 | G15: актуально для B2B-рынков
