Workbook

Sheet Инструкция
A1: Шаблон перехода от бизнес-логики и пользовательских сценариев к страницам и экранам
A2: Рабочая книга предназначена для проектирования состава сайта или мобильного приложения на основе результатов анализа проблем, конкурентов, ценностного предложения, цифрового товара, бизнес-модели и пользовательских сценариев.
A4: Шаг | B4: Действие | C4: Что сделать
A5: 1 | B5: Собрать исходные выводы | C5: Перенесите ключевые выводы из анализа проблем, конкурентов, отзывов, бизнес-модели и пользовательских сценариев в лист «Банк_выводов».
A6: 2 | B6: Зафиксировать роли | C6: Опишите пользовательские роли и сегменты на листе «Роли_и_сегменты». Эти роли используются дальше для сценариев, страниц и экранов.
A7: 3 | B7: Описать сценарии | C7: На листе «Пользовательские_сценарии» заполните пользовательские цели, потоки, данные, критичность, частоту и сложность.
A8: 4 | B8: Вывести страницы и экраны | C8: На листе «Страницы_и_экраны» каждая интерфейсная единица должна иметь связанный сценарий, задачу пользователя, действие и источник требования.
A9: 5 | B9: Проверить покрытие | C9: Лист «Матрица_сценарий_интерфейс» связывает сценарии со страницами и экранами. По нему рассчитывается покрытие сценариев.
A10: 6 | B10: Описать навигацию и состояния | C10: Заполните переходы, состояния, ошибки, пустые состояния и сообщения пользователю. Это снижает риск разрывов сценария.
A11: 7 | B11: Сформировать паспорта | C11: На листе «Паспорт_экрана» оформите итоговое описание каждой страницы или экрана для передачи в проектирование прототипа и техническое задание.
A12: 8 | B12: Приоритизировать | C12: Используйте лист «Приоритизация» для выбора первой версии, следующих выпусков и отложенных интерфейсных единиц.
A13: 9 | B13: Проверить готовность | C13: Листы «Проверка_связности» и «Дашборд» показывают полноту и согласованность проектной логики.

Sheet Банк_выводов
A1: Банк исходных выводов из всех видов анализа
A2: Каждая строка — доказанный вывод, который может повлиять на состав страниц, экранов, навигации, контента или состояний.
A4: ID вывода | B4: Вид анализа | C4: Объект анализа | D4: Вывод / факт | E4: Доказательство / ссылка | F4: Надежность 1–5 | G4: Значимость 1–5 | H4: Влияние на интерфейс | I4: Связанные роли | J4: Связанные сценарии | K4: Решение для страниц/экранов
A5: A-001 | B5: Анализ поискового спроса | C5: Вордстат, ЛР1 | D5: Спрос проблемный: ошибки в формулах ищут чаще, чем аудит | E5: Проблемные 36,6 %, AI 45,3 %, услуги 2,3 % выборки топов | F5: 4 | G5: 5 | H5: Нужны страницы по проблемным запросам и четкий первый экран | I5: ROLE-001 | J5: SC-001 | K5: Добавить страницу продукта с примерами ошибок
A6: A-002 | B6: Оценка рынка | C6: ЛР2-3 | D6: Рынок достаточен для старта, но канал ограничивает SOM | E6: SAM 35 млн EUR, платящих за 4 месяца бета 19 при цели 50 | F6: 4 | G6: 5 | H6: Интерфейс должен вести к быстрому первому результату и оплате | I6: ROLE-002 | J6: SC-001 | K6: Сократить путь до первой проверки
A7: A-003 | B7: Конкуренция | C7: ЛР4 | D7: Заменители создают критичное давление (73 % трафика) | E7: Индекс барьеров 3,15; пять сил 3,55 | F7: 4 | G7: 5 | H7: Нужен экран, показывающий отличие от универсального AI | I7: ROLE-001 | J7: SC-001 | K7: Блок «чем отличается» на странице продукта
A8: A-004 | B8: Отзывы | C8: G2 | D8: У прямых конкурентов нет отзывов | E8: PerfectXL 0, Arixcel 1, CIMCON 19 против Datarails 386 | F8: 4 | G8: 4 | H8: Нужны блоки отзывов и кейсов | I8: ROLE-002 | J8: SC-001 | K8: Раздел отзывов после пилота
A9: A-005 | B9: Цены | C9: страницы цен | D9: Цена Pro 19 EUR на медиане рынка, специализированные аналоги от 69 EUR | E9: PerfectXL 69 EUR, Rows 8 USD, Copilot 18 USD, Shortcut 100 USD | F9: 4 | G9: 4 | H9: Тарифы должны быть видны без разговора с продавцом | I9: ROLE-001 | J9: SC-001 | K9: Страница тарифов с лестницей Free, 9, 19, 29 EUR
A10: A-006 | B10: Цифровой товар | C10: ЛР5 | D10: Стандарт товара - надстройка Excel; разрывы - поиск ошибок, безопасность, пробный доступ | E10: по 3 из 7 конкурентов | F10: 4 | G10: 5 | H10: Нужны экраны поиска ошибок, пробного доступа и безопасности | I10: ROLE-002 | J10: SC-001 | K10: Включить в MVP
A11: A-007 | B11: Цифровой товар | C11: ЛР5 | D11: Зона дифференциации - доказательство вывода движком | E11: есть у 2 из 7 конкурентов | F11: 4 | G11: 5 | H11: Нужна карточка находки с доказательством | I11: ROLE-001 | J11: SC-001 | K11: Выделить доказательство в карточке
A12: A-008 | B12: Безопасность | C12: Shortcut, DataSnipper | D12: Безопасность и соответствие нужны для доверия к загрузке файлов | E12: SOC 2, GDPR на главных страницах | F12: 4 | G12: 4 | H12: Нужна страница безопасности и удаление данных | I12: ROLE-002 | J12: SC-001 | K12: Страница политики данных и экран удаления
A13: A-009 | B13: Бизнес-модели | C13: ЛР5 | D13: Практика: корпоративные пакеты и демо; самообслуживание только у AI-помощников | E13: 5 из 7 с корпоративными пакетами | F13: 4 | G13: 4 | H13: Нужны экраны командной работы позже | I13: ROLE-001 | J13: SC-001 | K13: Отложить до релиза 4
A14: A-010 | B14: Проблема клиентов | C14: ПЗ1 | D14: Ошибки есть в 86-94 % таблиц, AI-надстройки сами требуют проверки | E14: оценка ПЗ1 | F14: 4 | G14: 5 | H14: Проблема массовая: первый экран должен называть ее прямо | I14: ROLE-002 | J14: SC-001 | K14: Первый экран про ошибки в моделях
A15: A-011 | B15: Платежеспособность | C15: ЛР2-3 | D15: Бюджет сегментов выше цены предложения (индекс 2,4) | E15: индексы 1,3-4,2 | F15: 4 | G15: 4 | H15: Цена и ценность должны быть рядом | I15: ROLE-001 | J15: SC-001 | K15: Блок окупаемости на странице тарифов
A16: A-012 | B16: Каналы | C16: AppSource | D16: В AppSource по запросу formula checker один результат | E16: 138 результатов по excel audit, один по formula checker | F16: 4 | G16: 4 | H16: Нужен экран установки надстройки | I16: ROLE-002 | J16: SC-001 | K16: Описание установки в справке

Sheet Роли_и_сегменты
A1: Роли и пользовательские сегменты
A2: Роли используются как связующее звено между бизнес-логикой, сценариями, страницами и экранами.
A4: Роль_ID | B4: Роль / сегмент | C4: Цель роли | D4: Основная проблема | E4: Ожидаемая ценность | F4: Цифровая зрелость | G4: Частота использования | H4: Критичность задачи 1–5 | I4: Канал входа | J4: Примечание
A5: ROLE-001 | B5: Финансовый аналитик / FP&A | C5: Проверить модель перед передачей | D5: Скрытые ошибки в формулах | E5: Не допустить неверные числа | F5: Средняя | G5: периодически | H5: 5 | I5: Поиск по проблемным запросам | J5: A-010
A6: ROLE-002 | B6: Консультант по управлению | C6: Проверить модель клиента и передать отчет | D6: Нет передаваемого отчета | E6: Усилить заключение доказательствами | F6: Средняя | G6: периодически | H6: 3 | I6: Партнерские фирмы | J6: A-004
A7: ROLE-003 | B7: Бухгалтер / аудитор | C7: Подтвердить расчеты в таблицах | D7: Нет следов проверки | E7: Соответствие стандартам | F7: Средняя | G7: периодически | H7: 4 | I7: Профессиональные сообщества | J7: A-008
A8: ROLE-004 | B8: Основатель / операционный менеджер МСП | C8: Проверить таблицы без штатного аудитора | D8: Цена и безопасность | E8: Экономия времени и денег | F8: Средняя | G8: периодически | H8: 3 | I8: AppSource, поиск | J8: A-012
A9: ROLE-005 | B9: Администратор команды | C9: Настроить проверку для сотрудников | D9: Нет общего контроля качества | E9: Единый стандарт проверки | F9: Средняя | G9: периодически | H9: 2 | I9: Рекомендация коллеги | J9: A-009

Sheet Пользовательские_сценарии
A1: Пользовательские сценарии
A2: Сценарий должен иметь пользовательскую цель, поток действий, бизнес-результат и связку с интерфейсными единицами.
A4: Сценарий_ID | B4: Роль_ID | C4: Этап пути | D4: Пользовательская цель | E4: Начальный триггер | F4: Основной поток | G4: Альтернативный поток | H4: Данные / контент | I4: Бизнес-результат | J4: Критичность 1–5 | K4: Частота 1–5 | L4: Сложность 1–5 | M4: Кол-во страниц/экранов | N4: Статус покрытия | O4: Приоритет сценария
A5: SC-001 | B5: ROLE-001 | C5: Получение ценности | D5: Увидеть ошибки в своем файле | E5: Переход из поиска на страницу продукта | F5: Загрузка файла → запуск проверки → список находок | G5: Файл слишком большой: сообщение с лимитом | H5: файл Excel, находки, отчет | I5: Рост активации | J5: 5 | K5: 5 | L5: 3 | M5: =IF(A5="","",COUNTIF(Страницы_и_экраны!$E$5:$E$304,A5)) -> 5 | N5: =IF(A5="","",IF(M5>0,"Покрыт","Нет страницы/экрана")) -> Покрыт | O5: =IF(A5="","",MAX(0,MIN(100,ROUND(((J5*0.45)+(K5*0.35)-(L5*0.2))*20,0)))) -> 68
A6: SC-002 | B6: ROLE-001 | C6: Регистрация | D6: Сохранить находки и отчет | E6: Просмотр находок | F6: Кнопка сохранить → регистрация → личный кабинет | G6: Уже есть аккаунт: вход | H6: файл Excel, находки, отчет | I6: Рост регистраций | J6: 4 | K6: 5 | L6: 3 | M6: =IF(A6="","",COUNTIF(Страницы_и_экраны!$E$5:$E$304,A6)) -> 1 | N6: =IF(A6="","",IF(M6>0,"Покрыт","Нет страницы/экрана")) -> Покрыт | O6: =IF(A6="","",MAX(0,MIN(100,ROUND(((J6*0.45)+(K6*0.35)-(L6*0.2))*20,0)))) -> 59
A7: SC-003 | B7: ROLE-002 | C7: Оплата | D7: Получить полный отчет | E7: Лимит бесплатной проверки | F7: Тарифы → оплата 9 EUR → полный отчет | G7: Отказ платежа: повтор и поддержка | H7: файл Excel, находки, отчет | I7: Первая оплата | J7: 5 | K7: 4 | L7: 3 | M7: =IF(A7="","",COUNTIF(Страницы_и_экраны!$E$5:$E$304,A7)) -> 2 | N7: =IF(A7="","",IF(M7>0,"Покрыт","Нет страницы/экрана")) -> Покрыт | O7: =IF(A7="","",MAX(0,MIN(100,ROUND(((J7*0.45)+(K7*0.35)-(L7*0.2))*20,0)))) -> 61
A8: SC-004 | B8: ROLE-001 | C8: Оплата | D8: Проверять без ограничений | E8: Третья проверка за месяц | F8: Предложение Pro → оплата 19 EUR → активация | G8: Отказ: остаться на Free | H8: файл Excel, находки, отчет | I8: Рост подписок | J8: 4 | K8: 4 | L8: 3 | M8: =IF(A8="","",COUNTIF(Страницы_и_экраны!$E$5:$E$304,A8)) -> 1 | N8: =IF(A8="","",IF(M8>0,"Покрыт","Нет страницы/экрана")) -> Покрыт | O8: =IF(A8="","",MAX(0,MIN(100,ROUND(((J8*0.45)+(K8*0.35)-(L8*0.2))*20,0)))) -> 52
A9: SC-005 | B9: ROLE-001 | C9: Получение ценности | D9: Проверить книгу после правки AI | E9: Правка формул помощником | F9: Надстройка → проверка книги → подсветка находок | G9: Нет доступа к надстройке: веб-версия | H9: файл Excel, находки, отчет | I9: Удержание | J9: 5 | K9: 5 | L9: 3 | M9: =IF(A9="","",COUNTIF(Страницы_и_экраны!$E$5:$E$304,A9)) -> 1 | N9: =IF(A9="","",IF(M9>0,"Покрыт","Нет страницы/экрана")) -> Покрыт | O9: =IF(A9="","",MAX(0,MIN(100,ROUND(((J9*0.45)+(K9*0.35)-(L9*0.2))*20,0)))) -> 68
A10: SC-006 | B10: ROLE-002 | C10: Получение ценности | D10: Передать проверенную модель с отчетом | E10: Завершение проекта | F10: Отчет → экспорт → отправка заказчику | G10: Формат не подходит: шаблон отчета | H10: файл Excel, находки, отчет | I10: Рекомендации и повторные покупки | J10: 4 | K10: 3 | L10: 3 | M10: =IF(A10="","",COUNTIF(Страницы_и_экраны!$E$5:$E$304,A10)) -> 1 | N10: =IF(A10="","",IF(M10>0,"Покрыт","Нет страницы/экрана")) -> Покрыт | O10: =IF(A10="","",MAX(0,MIN(100,ROUND(((J10*0.45)+(K10*0.35)-(L10*0.2))*20,0)))) -> 45
A11: SC-007 | B11: ROLE-002 | C11: Получение ценности | D11: Найти риски до заключения | E11: Получение модели от клиента | F11: Загрузка → проверка → карточки находок → заключение | G11: Файл защищен паролем: запрос пароля | H11: файл Excel, находки, отчет | I11: Рост спроса среди консультантов | J11: 4 | K11: 3 | L11: 3 | M11: =IF(A11="","",COUNTIF(Страницы_и_экраны!$E$5:$E$304,A11)) -> 0 | N11: =IF(A11="","",IF(M11>0,"Покрыт","Нет страницы/экрана")) -> Нет страницы/экрана | O11: =IF(A11="","",MAX(0,MIN(100,ROUND(((J11*0.45)+(K11*0.35)-(L11*0.2))*20,0)))) -> 45
A12: SC-008 | B12: ROLE-005 | C12: Настройка | D12: Задать правила команды | E12: Внедрение в команде | F12: Кабинет → правила → сохранение | G12: Конфликт правил: подсказка | H12: файл Excel, находки, отчет | I12: Удержание команд | J12: 3 | K12: 2 | L12: 3 | M12: =IF(A12="","",COUNTIF(Страницы_и_экраны!$E$5:$E$304,A12)) -> 0 | N12: =IF(A12="","",IF(M12>0,"Покрыт","Нет страницы/экрана")) -> Нет страницы/экрана | O12: =IF(A12="","",MAX(0,MIN(100,ROUND(((J12*0.45)+(K12*0.35)-(L12*0.2))*20,0)))) -> 29
A13: SC-009 | B13: ROLE-005 | C13: Оплата | D13: Дать доступ сотрудникам | E13: Решение руководителя | F13: Кабинет → приглашение → оплата мест 29 EUR | G13: Нет свободных мест: докупка | H13: файл Excel, находки, отчет | I13: Рост выручки за место | J13: 3 | K13: 2 | L13: 3 | M13: =IF(A13="","",COUNTIF(Страницы_и_экраны!$E$5:$E$304,A13)) -> 1 | N13: =IF(A13="","",IF(M13>0,"Покрыт","Нет страницы/экрана")) -> Покрыт | O13: =IF(A13="","",MAX(0,MIN(100,ROUND(((J13*0.45)+(K13*0.35)-(L13*0.2))*20,0)))) -> 29
A14: SC-010 | B14: ROLE-003 | C14: Поддержка | D14: Удалить файлы и аккаунт | E14: Запрос пользователя | F14: Кабинет → удалить данные → подтверждение | G14: Платная подписка активна: напоминание | H14: файл Excel, находки, отчет | I14: Снижение рисков отказа | J14: 4 | K14: 2 | L14: 3 | M14: =IF(A14="","",COUNTIF(Страницы_и_экраны!$E$5:$E$304,A14)) -> 2 | N14: =IF(A14="","",IF(M14>0,"Покрыт","Нет страницы/экрана")) -> Покрыт | O14: =IF(A14="","",MAX(0,MIN(100,ROUND(((J14*0.45)+(K14*0.35)-(L14*0.2))*20,0)))) -> 38
M15: =IF(A15="","",COUNTIF(Страницы_и_экраны!$E$5:$E$304,A15)) | N15: =IF(A15="","",IF(M15>0,"Покрыт","Нет страницы/экрана")) | O15: =IF(A15="","",MAX(0,MIN(100,ROUND(((J15*0.45)+(K15*0.35)-(L15*0.2))*20,0))))
M16: =IF(A16="","",COUNTIF(Страницы_и_экраны!$E$5:$E$304,A16)) | N16: =IF(A16="","",IF(M16>0,"Покрыт","Нет страницы/экрана")) | O16: =IF(A16="","",MAX(0,MIN(100,ROUND(((J16*0.45)+(K16*0.35)-(L16*0.2))*20,0))))
M17: =IF(A17="","",COUNTIF(Страницы_и_экраны!$E$5:$E$304,A17)) | N17: =IF(A17="","",IF(M17>0,"Покрыт","Нет страницы/экрана")) | O17: =IF(A17="","",MAX(0,MIN(100,ROUND(((J17*0.45)+(K17*0.35)-(L17*0.2))*20,0))))
M18: =IF(A18="","",COUNTIF(Страницы_и_экраны!$E$5:$E$304,A18)) | N18: =IF(A18="","",IF(M18>0,"Покрыт","Нет страницы/экрана")) | O18: =IF(A18="","",MAX(0,MIN(100,ROUND(((J18*0.45)+(K18*0.35)-(L18*0.2))*20,0))))
M19: =IF(A19="","",COUNTIF(Страницы_и_экраны!$E$5:$E$304,A19)) | N19: =IF(A19="","",IF(M19>0,"Покрыт","Нет страницы/экрана")) | O19: =IF(A19="","",MAX(0,MIN(100,ROUND(((J19*0.45)+(K19*0.35)-(L19*0.2))*20,0))))
M20: =IF(A20="","",COUNTIF(Страницы_и_экраны!$E$5:$E$304,A20)) | N20: =IF(A20="","",IF(M20>0,"Покрыт","Нет страницы/экрана")) | O20: =IF(A20="","",MAX(0,MIN(100,ROUND(((J20*0.45)+(K20*0.35)-(L20*0.2))*20,0))))
M21: =IF(A21="","",COUNTIF(Страницы_и_экраны!$E$5:$E$304,A21)) | N21: =IF(A21="","",IF(M21>0,"Покрыт","Нет страницы/экрана")) | O21: =IF(A21="","",MAX(0,MIN(100,ROUND(((J21*0.45)+(K21*0.35)-(L21*0.2))*20,0))))
M22: =IF(A22="","",COUNTIF(Страницы_и_экраны!$E$5:$E$304,A22)) | N22: =IF(A22="","",IF(M22>0,"Покрыт","Нет страницы/экрана")) | O22: =IF(A22="","",MAX(0,MIN(100,ROUND(((J22*0.45)+(K22*0.35)-(L22*0.2))*20,0))))
M23: =IF(A23="","",COUNTIF(Страницы_и_экраны!$E$5:$E$304,A23)) | N23: =IF(A23="","",IF(M23>0,"Покрыт","Нет страницы/экрана")) | O23: =IF(A23="","",MAX(0,MIN(100,ROUND(((J23*0.45)+(K23*0.35)-(L23*0.2))*20,0))))
M24: =IF(A24="","",COUNTIF(Страницы_и_экраны!$E$5:$E$304,A24)) | N24: =IF(A24="","",IF(M24>0,"Покрыт","Нет страницы/экрана")) | O24: =IF(A24="","",MAX(0,MIN(100,ROUND(((J24*0.45)+(K24*0.35)-(L24*0.2))*20,0))))
M25: =IF(A25="","",COUNTIF(Страницы_и_экраны!$E$5:$E$304,A25)) | N25: =IF(A25="","",IF(M25>0,"Покрыт","Нет страницы/экрана")) | O25: =IF(A25="","",MAX(0,MIN(100,ROUND(((J25*0.45)+(K25*0.35)-(L25*0.2))*20,0))))
M26: =IF(A26="","",COUNTIF(Страницы_и_экраны!$E$5:$E$304,A26)) | N26: =IF(A26="","",IF(M26>0,"Покрыт","Нет страницы/экрана")) | O26: =IF(A26="","",MAX(0,MIN(100,ROUND(((J26*0.45)+(K26*0.35)-(L26*0.2))*20,0))))
... M304: =IF(A304="","",COUNTIF(Страницы_и_экраны!$E$5:$E$304,A304)) | N304: =IF(A304="","",IF(M304>0,"Покрыт","Нет страницы/экрана")) | O304: =IF(A304="","",MAX(0,MIN(100,ROUND(((J304*0.45)+(K304*0.35)-(L304*0.2))*20,0))))

Sheet Страницы_и_экраны
A1: Страницы сайта и экраны приложения
A2: Каждая интерфейсная единица должна выводиться из сценария, проблемы, ценностного предложения или требования бизнес-модели.
A4: Unit_ID | B4: Тип | C4: Название | D4: Назначение | E4: Связанный сценарий_ID | F4: Роль_ID | G4: Этап пути | H4: Главная задача пользователя | I4: Ключевое действие | J4: Источник требования | K4: Данные / контент | L4: Компоненты | M4: Состояния | N4: Ошибки / исключения | O4: Нужна авторизация | P4: Монетизационная роль | Q4: Оценка приоритета | R4: Статус | S4: Доказательность 1–5 | T4: Полнота описания | U4: Решение
A5: U-001 | B5: Страница сайта | C5: Страница продукта с примерами ошибок | D5: Показать ценность и направить к бесплатной проверке | E5: SC-001 | F5: ROLE-001 | G5: Первичный интерес | H5: Понять пользу | I5: Нажать «Проверить файл» | J5: F-001; F-008 | K5: ценностное предложение, примеры найденных ошибок, отличие от AI | L5: первый экран, примеры, сравнение, призыв к действию | M5: нормальное; пустое; загрузка; ошибка; успех | N5: см. лист «Состояния_и_ошибки» | O5: Нет | P5: вход в воронку | Q5: =IF(A5="","",IFERROR(INDEX(Пользовательские_сценарии!$O$5:$O$304,MATCH(E5,Пользовательские_сценарии!$A$5:$A$304,0)),0)) -> 68 | R5: Черновик | S5: 4 | T5: =IF(A5="","",ROUND(COUNTA(D5:P5)/13,2)) -> 1
A6: U-002 | B6: Экран приложения | C6: Загрузка файла и запуск проверки | D6: Принять файл Excel и запустить проверку без регистрации | E6: SC-001 | F6: ROLE-001 | G6: Получение ценности | H6: Загрузить файл | I6: Выбрать файл и запустить проверку | J6: F-001 | K6: файл xlsx, лимиты Free | L6: поле загрузки, лимиты, индикатор прогресса | M6: нормальное; пустое; загрузка; ошибка; успех | N6: см. лист «Состояния_и_ошибки» | O6: Нет | P6: активация | Q6: =IF(A6="","",IFERROR(INDEX(Пользовательские_сценарии!$O$5:$O$304,MATCH(E6,Пользовательские_сценарии!$A$5:$A$304,0)),0)) -> 68 | R6: Черновик | S6: 4 | T6: =IF(A6="","",ROUND(COUNTA(D6:P6)/13,2)) -> 1
A7: U-003 | B7: Экран приложения | C7: Результат проверки: список находок | D7: Показать найденные ошибки с критичностью | E7: SC-001 | F7: ROLE-001 | G7: Получение ценности | H7: Понять, что найдено | I7: Открыть карточку находки | J7: F-002 | K7: список находок, критичность, ячейки | L7: таблица находок, фильтры, сводка | M7: нормальное; пустое; загрузка; ошибка; успех | N7: см. лист «Состояния_и_ошибки» | O7: Нет | P7: активация | Q7: =IF(A7="","",IFERROR(INDEX(Пользовательские_сценарии!$O$5:$O$304,MATCH(E7,Пользовательские_сценарии!$A$5:$A$304,0)),0)) -> 68 | R7: Черновик | S7: 4 | T7: =IF(A7="","",ROUND(COUNTA(D7:P7)/13,2)) -> 1
A8: U-004 | B8: Экран приложения | C8: Карточка находки с доказательством | D8: Объяснить ошибку и доказать ее вычислением | E8: SC-001 | F8: ROLE-001 | G8: Получение ценности | H8: Убедиться в находке | I8: Принять или отклонить находку | J8: F-003 | K8: ячейка, формула, вычисление-доказательство | L8: описание, доказательство, исправление | M8: нормальное; пустое; загрузка; ошибка; успех | N8: см. лист «Состояния_и_ошибки» | O8: Нет | P8: доверие | Q8: =IF(A8="","",IFERROR(INDEX(Пользовательские_сценарии!$O$5:$O$304,MATCH(E8,Пользовательские_сценарии!$A$5:$A$304,0)),0)) -> 68 | R8: Черновик | S8: 5 | T8: =IF(A8="","",ROUND(COUNTA(D8:P8)/13,2)) -> 1
A9: U-005 | B9: Экран приложения | C9: Отчет аудита | D9: Собрать находки в передаваемый отчет | E9: SC-006 | F9: ROLE-002 | G9: Получение ценности | H9: Получить отчет | I9: Скачать или переслать отчет | J9: F-004 | K9: перечень находок, сводка, дата проверки | L9: заголовок, сводка, таблица, подпись проверки | M9: нормальное; пустое; загрузка; ошибка; успех | N9: см. лист «Состояния_и_ошибки» | O9: Да | P9: монетизация | Q9: =IF(A9="","",IFERROR(INDEX(Пользовательские_сценарии!$O$5:$O$304,MATCH(E9,Пользовательские_сценарии!$A$5:$A$304,0)),0)) -> 45 | R9: Черновик | S9: 4 | T9: =IF(A9="","",ROUND(COUNTA(D9:P9)/13,2)) -> 1
A10: U-006 | B10: Экран приложения | C10: Регистрация и вход | D10: Сохранить результат и открыть кабинет | E10: SC-002 | F10: ROLE-001 | G10: Регистрация | H10: Создать аккаунт | I10: Ввести email и подтвердить | J10: F-005 | K10: email, пароль, согласие с условиями | L10: форма, подтверждение, ссылка входа | M10: нормальное; пустое; загрузка; ошибка; успех | N10: см. лист «Состояния_и_ошибки» | O10: Нет | P10: регистрация | Q10: =IF(A10="","",IFERROR(INDEX(Пользовательские_сценарии!$O$5:$O$304,MATCH(E10,Пользовательские_сценарии!$A$5:$A$304,0)),0)) -> 59 | R10: Черновик | S10: 4 | T10: =IF(A10="","",ROUND(COUNTA(D10:P10)/13,2)) -> 1
A11: U-007 | B11: Страница сайта | C11: Страница тарифов | D11: Показать тарифы и помочь выбрать | E11: SC-003 | F11: ROLE-002 | G11: Оплата | H11: Выбрать тариф | I11: Нажать «Купить» или «Оформить Pro» | J11: F-008 | K11: Free, 9 EUR, Pro 19 EUR, Team 29 EUR | L11: таблица тарифов, сравнение, вопросы и ответы | M11: нормальное; пустое; загрузка; ошибка; успех | N11: см. лист «Состояния_и_ошибки» | O11: Нет | P11: оплата | Q11: =IF(A11="","",IFERROR(INDEX(Пользовательские_сценарии!$O$5:$O$304,MATCH(E11,Пользовательские_сценарии!$A$5:$A$304,0)),0)) -> 61 | R11: Черновик | S11: 5 | T11: =IF(A11="","",ROUND(COUNTA(D11:P11)/13,2)) -> 1
A12: U-008 | B12: Экран приложения | C12: Оплата | D12: Принять платеж за аудит или подписку | E12: SC-003 | F12: ROLE-002 | G12: Оплата | H12: Оплатить | I12: Подтвердить платеж | J12: F-006 | K12: тариф, сумма, налоги | L12: форма оплаты, итог, подтверждение | M12: нормальное; пустое; загрузка; ошибка; успех | N12: см. лист «Состояния_и_ошибки» | O12: Да | P12: оплата | Q12: =IF(A12="","",IFERROR(INDEX(Пользовательские_сценарии!$O$5:$O$304,MATCH(E12,Пользовательские_сценарии!$A$5:$A$304,0)),0)) -> 61 | R12: Черновик | S12: 4 | T12: =IF(A12="","",ROUND(COUNTA(D12:P12)/13,2)) -> 1
A13: U-009 | B13: Страница сайта | C13: Безопасность и политика данных | D13: Снять опасения по загрузке файлов | E13: SC-010 | F13: ROLE-003 | G13: Первичный интерес | H13: Проверить безопасность | I13: Открыть политику данных | J13: F-007 | K13: политика данных, GDPR, сроки хранения | L13: описание мер, сроки, контакты | M13: нормальное; пустое; загрузка; ошибка; успех | N13: см. лист «Состояния_и_ошибки» | O13: Нет | P13: доверие | Q13: =IF(A13="","",IFERROR(INDEX(Пользовательские_сценарии!$O$5:$O$304,MATCH(E13,Пользовательские_сценарии!$A$5:$A$304,0)),0)) -> 38 | R13: Черновик | S13: 4 | T13: =IF(A13="","",ROUND(COUNTA(D13:P13)/13,2)) -> 1
A14: U-010 | B14: Экран приложения | C14: Настройки аккаунта и удаление данных | D14: Дать пользователю управление данными | E14: SC-010 | F14: ROLE-003 | G14: Поддержка | H14: Удалить данные | I14: Подтвердить удаление | J14: F-007 | K14: аккаунт, список файлов | L14: настройки, кнопка удаления, подтверждение | M14: нормальное; пустое; загрузка; ошибка; успех | N14: см. лист «Состояния_и_ошибки» | O14: Да | P14: доверие | Q14: =IF(A14="","",IFERROR(INDEX(Пользовательские_сценарии!$O$5:$O$304,MATCH(E14,Пользовательские_сценарии!$A$5:$A$304,0)),0)) -> 38 | R14: Черновик | S14: 4 | T14: =IF(A14="","",ROUND(COUNTA(D14:P14)/13,2)) -> 1
A15: U-011 | B15: Экран приложения | C15: Личный кабинет: история проверок | D15: Показать прошлые проверки и повторить | E15: SC-004 | F15: ROLE-001 | G15: Удержание | H15: Вернуться к проверке | I15: Повторить проверку | J15: F-005 | K15: список проверок, даты, статусы | L15: список, фильтры, кнопка повторной проверки | M15: нормальное; пустое; загрузка; ошибка; успех | N15: см. лист «Состояния_и_ошибки» | O15: Да | P15: удержание | Q15: =IF(A15="","",IFERROR(INDEX(Пользовательские_сценарии!$O$5:$O$304,MATCH(E15,Пользовательские_сценарии!$A$5:$A$304,0)),0)) -> 52 | R15: Черновик | S15: 3 | T15: =IF(A15="","",ROUND(COUNTA(D15:P15)/13,2)) -> 1
A16: U-012 | B16: Экран приложения | C16: Надстройка Excel: панель проверки | D16: Проверять книгу прямо в Excel | E16: SC-005 | F16: ROLE-001 | G16: Получение ценности | H16: Проверить книгу | I16: Нажать «Проверить книгу» | J16: F-009 | K16: книга, находки, ячейки | L16: боковая панель, список находок, подсветка | M16: нормальное; пустое; загрузка; ошибка; успех | N16: см. лист «Состояния_и_ошибки» | O16: Да | P16: удержание | Q16: =IF(A16="","",IFERROR(INDEX(Пользовательские_сценарии!$O$5:$O$304,MATCH(E16,Пользовательские_сценарии!$A$5:$A$304,0)),0)) -> 68 | R16: Идея | S16: 3 | T16: =IF(A16="","",ROUND(COUNTA(D16:P16)/13,2)) -> 1
... A18: U-017 | B18: Страница сайта | C18: Документация и справка | D18: Помочь начать и объяснить правила проверки | E18: SC-001 | F18: ROLE-001 | G18: Первичный интерес | H18: Найти ответ | I18: Открыть статью | J18: F-008 | K18: статьи, видео, часто задаваемые вопросы | L18: поиск, разделы, статьи | M18: нормальное; пустое; загрузка; ошибка; успех | N18: см. лист «Состояния_и_ошибки» | O18: Нет | P18: доверие | Q18: =IF(A18="","",IFERROR(INDEX(Пользовательские_сценарии!$O$5:$O$304,MATCH(E18,Пользовательские_сценарии!$A$5:$A$304,0)),0)) -> 68 | R18: Черновик | S18: 3 | T18: =IF(A18="","",ROUND(COUNTA(D18:P18)/13,2)) -> 1
Q19: =IF(A19="","",IFERROR(INDEX(Пользовательские_сценарии!$O$5:$O$304,MATCH(E19,Пользовательские_сценарии!$A$5:$A$304,0)),0)) | T19: =IF(A19="","",ROUND(COUNTA(D19:P19)/13,2))
Q20: =IF(A20="","",IFERROR(INDEX(Пользовательские_сценарии!$O$5:$O$304,MATCH(E20,Пользовательские_сценарии!$A$5:$A$304,0)),0)) | T20: =IF(A20="","",ROUND(COUNTA(D20:P20)/13,2))
Q21: =IF(A21="","",IFERROR(INDEX(Пользовательские_сценарии!$O$5:$O$304,MATCH(E21,Пользовательские_сценарии!$A$5:$A$304,0)),0)) | T21: =IF(A21="","",ROUND(COUNTA(D21:P21)/13,2))
Q22: =IF(A22="","",IFERROR(INDEX(Пользовательские_сценарии!$O$5:$O$304,MATCH(E22,Пользовательские_сценарии!$A$5:$A$304,0)),0)) | T22: =IF(A22="","",ROUND(COUNTA(D22:P22)/13,2))
Q23: =IF(A23="","",IFERROR(INDEX(Пользовательские_сценарии!$O$5:$O$304,MATCH(E23,Пользовательские_сценарии!$A$5:$A$304,0)),0)) | T23: =IF(A23="","",ROUND(COUNTA(D23:P23)/13,2))
Q24: =IF(A24="","",IFERROR(INDEX(Пользовательские_сценарии!$O$5:$O$304,MATCH(E24,Пользовательские_сценарии!$A$5:$A$304,0)),0)) | T24: =IF(A24="","",ROUND(COUNTA(D24:P24)/13,2))
Q25: =IF(A25="","",IFERROR(INDEX(Пользовательские_сценарии!$O$5:$O$304,MATCH(E25,Пользовательские_сценарии!$A$5:$A$304,0)),0)) | T25: =IF(A25="","",ROUND(COUNTA(D25:P25)/13,2))
Q26: =IF(A26="","",IFERROR(INDEX(Пользовательские_сценарии!$O$5:$O$304,MATCH(E26,Пользовательские_сценарии!$A$5:$A$304,0)),0)) | T26: =IF(A26="","",ROUND(COUNTA(D26:P26)/13,2))
Q27: =IF(A27="","",IFERROR(INDEX(Пользовательские_сценарии!$O$5:$O$304,MATCH(E27,Пользовательские_сценарии!$A$5:$A$304,0)),0)) | T27: =IF(A27="","",ROUND(COUNTA(D27:P27)/13,2))
Q28: =IF(A28="","",IFERROR(INDEX(Пользовательские_сценарии!$O$5:$O$304,MATCH(E28,Пользовательские_сценарии!$A$5:$A$304,0)),0)) | T28: =IF(A28="","",ROUND(COUNTA(D28:P28)/13,2))
Q29: =IF(A29="","",IFERROR(INDEX(Пользовательские_сценарии!$O$5:$O$304,MATCH(E29,Пользовательские_сценарии!$A$5:$A$304,0)),0)) | T29: =IF(A29="","",ROUND(COUNTA(D29:P29)/13,2))
Q30: =IF(A30="","",IFERROR(INDEX(Пользовательские_сценарии!$O$5:$O$304,MATCH(E30,Пользовательские_сценарии!$A$5:$A$304,0)),0)) | T30: =IF(A30="","",ROUND(COUNTA(D30:P30)/13,2))
... Q304: =IF(A304="","",IFERROR(INDEX(Пользовательские_сценарии!$O$5:$O$304,MATCH(E304,Пользовательские_сценарии!$A$5:$A$304,0)),0)) | T304: =IF(A304="","",ROUND(COUNTA(D304:P304)/13,2))

Sheet Матрица_сценарий_интерфейс
A1: Матрица связи сценариев со страницами и экранами
A2: Используется для проверки покрытия сценариев и исключения интерфейсных единиц без понятной задачи.
A4: Связь_ID | B4: Сценарий_ID | C4: Unit_ID | D4: Тип связи | E4: Обязательность | F4: Порядок в сценарии | G4: Предыдущее Unit_ID | H4: Следующее Unit_ID | I4: Комментарий
A5: M-001 | B5: SC-001 | C5: U-001 | D5: Основная | E5: Обязательно для первой версии | F5: 1 | H5: U-002 | I5: Страница продукта ведет к загрузке файла
A6: M-002 | B6: SC-001 | C6: U-002 | D6: Основная | E6: Обязательно для первой версии | F6: 2 | G6: U-001 | H6: U-003 | I6: Загрузка запускает проверку
A7: M-003 | B7: SC-001 | C7: U-003 | D7: Основная | E7: Обязательно для первой версии | F7: 3 | G7: U-002 | H7: U-004 | I7: Список находок ведет к карточке
A8: M-004 | B8: SC-001 | C8: U-004 | D8: Основная | E8: Обязательно для первой версии | F8: 4 | G8: U-003 | H8: U-006 | I8: Карточка подводит к сохранению
A9: M-005 | B9: SC-002 | C9: U-006 | D9: Основная | E9: Обязательно для первой версии | F9: 1 | G9: U-004 | H9: U-011 | I9: Регистрация сохраняет результат
A10: M-006 | B10: SC-002 | C10: U-011 | D10: Основная | E10: Следующий выпуск | F10: 2 | G10: U-006 | I10: История в кабинете
A11: M-007 | B11: SC-003 | C11: U-007 | D11: Основная | E11: Обязательно для первой версии | F11: 1 | G11: U-003 | H11: U-008 | I11: Тарифы ведут к оплате
A12: M-008 | B12: SC-003 | C12: U-008 | D12: Основная | E12: Обязательно для первой версии | F12: 2 | G12: U-007 | H12: U-005 | I12: Оплата открывает полный отчет
A13: M-009 | B13: SC-003 | C13: U-005 | D13: Основная | E13: Обязательно для первой версии | F13: 3 | G13: U-008 | I13: Полный отчет
A14: M-010 | B14: SC-004 | C14: U-011 | D14: Основная | E14: Следующий выпуск | F14: 1 | H14: U-007 | I14: Предложение Pro после нескольких проверок
A15: M-011 | B15: SC-004 | C15: U-008 | D15: Основная | E15: Обязательно для первой версии | F15: 2 | G15: U-007 | I15: Оформление подписки
A16: M-012 | B16: SC-005 | C16: U-012 | D16: Основная | E16: Следующий выпуск | F16: 1 | H16: U-003 | I16: Проверка книги в Excel
A17: M-013 | B17: SC-006 | C17: U-005 | D17: Основная | E17: Обязательно для первой версии | F17: 1 | G17: U-004 | I17: Отчет передается заказчику
A18: M-014 | B18: SC-007 | C18: U-002 | D18: Основная | E18: Обязательно для первой версии | F18: 1 | H18: U-003 | I18: Проверка чужой модели
A19: M-015 | B19: SC-009 | C19: U-016 | D19: Основная | E19: Следующий выпуск | F19: 1 | H19: U-008 | I19: Приглашение коллег и оплата мест
A20: M-016 | B20: SC-010 | C20: U-009 | D20: Вспомогательная | E20: Обязательно для первой версии | F20: 1 | H20: U-010 | I20: Политика данных
A21: M-017 | B21: SC-010 | C21: U-010 | D21: Основная | E21: Обязательно для первой версии | F21: 2 | G21: U-009 | I21: Удаление данных

Sheet Навигация_и_карта
A1: Навигация и карта переходов
A2: Каждый переход описывает действие, условие, направление и риск разрыва пользовательского сценария.
A4: Переход_ID | B4: Откуда Unit_ID | C4: Куда Unit_ID | D4: Событие / действие | E4: Условие | F4: Роль_ID | G4: Этап пути | H4: Тип перехода | I4: Риск разрыва 1–5 | J4: Комментарий
A5: N-001 | B5: U-001 | C5: U-002 | D5: Нажатие «Проверить файл» | E5: Пользователь готов попробовать | F5: ROLE-001 | G5: Получение ценности | H5: Основной | I5: 2 | J5: Призыв должен быть виден на первом экране
A6: N-002 | B6: U-002 | C6: U-003 | D6: Завершение проверки | E6: Файл принят | F6: ROLE-001 | G6: Получение ценности | H6: Основной | I6: 2 | J6: Показывать прогресс
A7: N-003 | B7: U-003 | C7: U-004 | D7: Открытие находки | E7: Есть находки | F7: ROLE-001 | G7: Получение ценности | H7: Основной | I7: 1 | J7: Находки кликабельны
A8: N-004 | B8: U-004 | C8: U-006 | D8: Сохранить результат | E8: Пользователь не вошел | F8: ROLE-001 | G8: Регистрация | H8: Основной | I8: 3 | J8: Результат не должен теряться
A9: N-005 | B9: U-003 | C9: U-007 | D9: Открыть полный отчет | E9: Лимит Free исчерпан | F9: ROLE-002 | G9: Оплата | H9: Основной | I9: 3 | J9: Объяснить лимиты
A10: N-006 | B10: U-007 | C10: U-008 | D10: Нажатие «Купить» | E10: Тариф выбран | F10: ROLE-002 | G10: Оплата | H10: Основной | I10: 2 | J10: Показывать итоговую сумму
A11: N-007 | B11: U-008 | C11: U-005 | D11: Платеж подтвержден | E11: Оплата прошла | F11: ROLE-002 | G11: Получение ценности | H11: Основной | I11: 2 | J11: Сразу открыть отчет
A12: N-008 | B12: U-006 | C12: U-011 | D12: Вход выполнен | E12: Аккаунт создан | F12: ROLE-001 | G12: Удержание | H12: Основной | I12: 1 | J12: Кабинет с историей
A13: N-009 | B13: U-001 | C13: U-009 | D13: Открытие политики данных | E13: Сомнение в безопасности | F13: ROLE-003 | G13: Первичный интерес | H13: Вспомогательный | I13: 2 | J13: Ссылка в подвале и у загрузки
A14: N-010 | B14: U-009 | C14: U-010 | D14: Удаление данных | E14: Пользователь вошел | F14: ROLE-003 | G14: Поддержка | H14: Вспомогательный | I14: 3 | J14: Двойное подтверждение
A15: N-011 | B15: U-011 | C15: U-007 | D15: Предложение Pro | E15: Три проверки в месяц | F15: ROLE-001 | G15: Оплата | H15: Основной | I15: 2 | J15: Не навязчиво
A16: N-012 | B16: U-012 | C16: U-003 | D16: Проверка книги | E16: Лицензия активна | F16: ROLE-001 | G16: Получение ценности | H16: Основной | I16: 3 | J16: Единый вид результата с веб-версией
A17: N-013 | B17: U-016 | C17: U-008 | D17: Оплата мест | E17: Роль администратора | F17: ROLE-005 | G17: Оплата | H17: Основной | I17: 3 | J17: Команда позже

Sheet Состояния_и_ошибки
A1: Состояния, ошибки и исключения
A2: Для каждой ключевой страницы или экрана фиксируются нормальные, пустые, загрузочные, ошибочные и успешные состояния.
A4: State_ID | B4: Unit_ID | C4: Нормальное состояние | D4: Пустое состояние | E4: Загрузка | F4: Ошибка валидации | G4: Ошибка сети/сервера | H4: Нет прав | I4: Успешное завершение | J4: Сообщение пользователю | K4: Полнота состояний
A5: S-001 | B5: U-001 | C5: Показаны блоки и призыв | D5: Не применимо | E5: Индикатор загрузки | F5: Не применимо | G5: Сообщение о недоступности | H5: Не применимо | I5: Переход к загрузке | J5: Повторите попытку позже | K5: =IF(A5="","",ROUND(COUNTA(C5:J5)/8,2)) -> 1
A6: S-002 | B6: U-002 | C6: Поле загрузки и лимиты | D6: Файл не выбран | E6: Индикатор проверки | F6: Неверный формат или размер | G6: Сервис недоступен | H6: Не применимо | I6: Переход к результату | J6: Проверьте формат xlsx и размер до лимита | K6: =IF(A6="","",ROUND(COUNTA(C6:J6)/8,2)) -> 1
A7: S-003 | B7: U-003 | C7: Таблица находок | D7: Ошибок не найдено | E7: Индикатор проверки | F7: Не применимо | G7: Не удалось получить результат | H7: Не применимо | I7: Находки отображены | J7: Повторите проверку | K7: =IF(A7="","",ROUND(COUNTA(C7:J7)/8,2)) -> 1
A8: S-004 | B8: U-004 | C8: Описание и доказательство | D8: Не применимо | E8: Индикатор расчета | F8: Не применимо | G8: Не удалось загрузить доказательство | H8: Не применимо | I8: Находка принята | J8: Обновите страницу | K8: =IF(A8="","",ROUND(COUNTA(C8:J8)/8,2)) -> 1
A9: S-005 | B9: U-005 | C9: Отчет собран | D9: Нет находок для отчета | E9: Индикатор сборки | F9: Не применимо | G9: Сбой экспорта | H9: Нужен вход | I9: Отчет получен | J9: Повторите экспорт | K9: =IF(A9="","",ROUND(COUNTA(C9:J9)/8,2)) -> 1
A10: S-006 | B10: U-006 | C10: Форма регистрации | D10: Не применимо | E10: Индикатор отправки | F10: Неверный email | G10: Сервис недоступен | H10: Не применимо | I10: Аккаунт создан | J10: Проверьте email и пароль | K10: =IF(A10="","",ROUND(COUNTA(C10:J10)/8,2)) -> 1
A11: S-007 | B11: U-007 | C11: Таблица тарифов | D11: Не применимо | E11: Индикатор загрузки | F11: Не применимо | G11: Цены временно недоступны | H11: Не применимо | I11: Переход к оплате | J11: Повторите попытку позже | K11: =IF(A11="","",ROUND(COUNTA(C11:J11)/8,2)) -> 1
A12: S-008 | B12: U-008 | C12: Форма оплаты | D12: Корзина пуста | E12: Индикатор оплаты | F12: Неверные данные карты | G12: Платежный сервис недоступен | H12: Нужен вход | I12: Платеж подтвержден | J12: Платеж не прошел: проверьте карту | K12: =IF(A12="","",ROUND(COUNTA(C12:J12)/8,2)) -> 1
A13: S-009 | B13: U-009 | C13: Текст политики | D13: Не применимо | E13: Индикатор загрузки | F13: Не применимо | G13: Страница недоступна | H13: Не применимо | I13: Не применимо | J13: Повторите попытку позже | K13: =IF(A13="","",ROUND(COUNTA(C13:J13)/8,2)) -> 1
A14: S-010 | B14: U-010 | C14: Настройки аккаунта | D14: Файлов нет | E14: Индикатор удаления | F14: Неверное подтверждение | G14: Сбой удаления | H14: Нужен вход | I14: Данные удалены | J14: Подтвердите удаление повторно | K14: =IF(A14="","",ROUND(COUNTA(C14:J14)/8,2)) -> 1
A15: S-011 | B15: U-011 | C15: Список проверок | D15: История пуста | E15: Индикатор загрузки | F15: Не применимо | G15: Не удалось загрузить историю | H15: Нужен вход | I15: Проверка запущена повторно | J15: Повторите попытку | K15: =IF(A15="","",ROUND(COUNTA(C15:J15)/8,2)) -> 1
A16: S-012 | B16: U-012 | C16: Панель надстройки | D16: Книга пуста | E16: Индикатор проверки | F16: Книга защищена | G16: Нет сети | H16: Нет лицензии | I16: Находки подсвечены | J16: Проверьте лицензию и доступ | K16: =IF(A16="","",ROUND(COUNTA(C16:J16)/8,2)) -> 1
... A18: S-014 | B18: U-017 | C18: Статьи справки | D18: Ничего не найдено | E18: Индикатор поиска | F18: Не применимо | G18: Страница недоступна | H18: Не применимо | I18: Не применимо | J18: Попробуйте другой запрос | K18: =IF(A18="","",ROUND(COUNTA(C18:J18)/8,2)) -> 1
K19: =IF(A19="","",ROUND(COUNTA(C19:J19)/8,2))
K20: =IF(A20="","",ROUND(COUNTA(C20:J20)/8,2))
K21: =IF(A21="","",ROUND(COUNTA(C21:J21)/8,2))
K22: =IF(A22="","",ROUND(COUNTA(C22:J22)/8,2))
K23: =IF(A23="","",ROUND(COUNTA(C23:J23)/8,2))
K24: =IF(A24="","",ROUND(COUNTA(C24:J24)/8,2))
K25: =IF(A25="","",ROUND(COUNTA(C25:J25)/8,2))
K26: =IF(A26="","",ROUND(COUNTA(C26:J26)/8,2))
K27: =IF(A27="","",ROUND(COUNTA(C27:J27)/8,2))
K28: =IF(A28="","",ROUND(COUNTA(C28:J28)/8,2))
K29: =IF(A29="","",ROUND(COUNTA(C29:J29)/8,2))
K30: =IF(A30="","",ROUND(COUNTA(C30:J30)/8,2))
... K204: =IF(A204="","",ROUND(COUNTA(C204:J204)/8,2))

Sheet Контент_и_данные
A1: Контент и данные для страниц и экранов
A2: Лист нужен для перевода сценариев в состав данных, текстов, полей, правил отображения и источников информации.
A4: Unit_ID | B4: Элемент контента / данных | C4: Источник данных | D4: Обязательность | E4: Частота обновления | F4: Персонализация | G4: Правило отображения | H4: Формат | I4: Ответственный
A5: U-001 | B5: Ценностное предложение и примеры ошибок | C5: ЛР6.1, VP-001 | D5: Обязательно для первой версии | E5: По мере изменения товара | F5: Нет | G5: Показывать всем | H5: Текст + визуальный блок | I5: Продукт
A6: U-002 | B6: Лимиты Free и поддерживаемые форматы | C6: Тарифы ПЗ1 | D6: Обязательно для первой версии | E6: При изменении тарифов | F6: Нет | G6: Показывать всем | H6: Текст | I6: Продукт
A7: U-003 | B7: Список находок и критичность | C7: Движок проверки | D7: Обязательно для первой версии | E7: При каждой проверке | F7: Да | G7: Показывать владельцу файла | H7: Таблица | I7: Разработка
A8: U-004 | B8: Доказательство находки | C8: Движок проверки | D8: Обязательно для первой версии | E8: При каждой проверке | F8: Да | G8: Показывать владельцу файла | H8: Формула + значение | I8: Разработка
A9: U-005 | B9: Отчет аудита | C9: Движок проверки | D9: Обязательно для первой версии | E9: При каждой проверке | F9: Да | G9: Показывать после оплаты | H9: Документ | I9: Разработка
A10: U-007 | B10: Таблица тарифов | C10: ПЗ1, ЛР2-3 | D10: Обязательно для первой версии | E10: При изменении цен | F10: Нет | G10: Показывать всем | H10: Таблица | I10: Продукт
A11: U-009 | B11: Политика данных и GDPR | C11: ЛР5, юридические условия | D11: Обязательно для первой версии | E11: При изменении политики | F11: Нет | G11: Показывать всем | H11: Текст | I11: Юрист
A12: U-017 | B12: Статьи справки | C12: Команда продукта | D12: Следующий выпуск | E12: Ежемесячно | F12: Нет | G12: Показывать всем | H12: Статья | I12: Продукт

Sheet Паспорт_экрана
A1: Паспорт страницы или экрана
A2: Итоговая форма описания интерфейсной единицы для прототипирования, постановки задачи и проверки связности.
A4: Unit_ID | B4: Название | C4: Тип | D4: Сценарий_ID | E4: Роль_ID | F4: Назначение | G4: Главная задача | H4: Основное действие | I4: Состав блоков | J4: Состояния | K4: Навигация | L4: Метрики успеха | M4: Риски | N4: Полнота паспорта | O4: Вердикт
A5: U-001 | B5: Страница продукта с примерами ошибок | C5: Страница сайта | D5: SC-001 | E5: ROLE-001 | F5: Показать ценность и направить к бесплатной проверке | G5: Понять пользу | H5: Нажать «Проверить файл» | I5: первый экран, примеры, сравнение, призыв к действию | J5: нормальное; пустое; загрузка; ошибка; успех | K5: переход к Загрузка файла и запуск проверки | L5: клики по призыву, переход к загрузке | M5: Непонятная ценность, перегрузка | N5: =IF(A5="","",ROUND(COUNTA(B5:M5)/12,2)) -> 1 | O5: =IF(A5="","",IF(N5>=0.85,"Готов к прототипу",IF(N5>=0.6,"Требует доработки","Недостаточно данных"))) -> Готов к прототипу
A6: U-002 | B6: Загрузка файла и запуск проверки | C6: Экран приложения | D6: SC-001 | E6: ROLE-001 | F6: Принять файл Excel и запустить проверку без регистрации | G6: Загрузить файл | H6: Выбрать файл и запустить проверку | I6: поле загрузки, лимиты, индикатор прогресса | J6: нормальное; пустое; загрузка; ошибка; успех | K6: переход к Результат проверки: список находок | L6: доля завершенных загрузок | M6: Большой файл, неверный формат | N6: =IF(A6="","",ROUND(COUNTA(B6:M6)/12,2)) -> 1 | O6: =IF(A6="","",IF(N6>=0.85,"Готов к прототипу",IF(N6>=0.6,"Требует доработки","Недостаточно данных"))) -> Готов к прототипу
A7: U-003 | B7: Результат проверки: список находок | C7: Экран приложения | D7: SC-001 | E7: ROLE-001 | F7: Показать найденные ошибки с критичностью | G7: Понять, что найдено | H7: Открыть карточку находки | I7: таблица находок, фильтры, сводка | J7: нормальное; пустое; загрузка; ошибка; успех | K7: переход к Карточка находки с доказательством | L7: доля просмотренных находок | M7: Слишком много находок | N7: =IF(A7="","",ROUND(COUNTA(B7:M7)/12,2)) -> 1 | O7: =IF(A7="","",IF(N7>=0.85,"Готов к прототипу",IF(N7>=0.6,"Требует доработки","Недостаточно данных"))) -> Готов к прототипу
A8: U-004 | B8: Карточка находки с доказательством | C8: Экран приложения | D8: SC-001 | E8: ROLE-001 | F8: Объяснить ошибку и доказать ее вычислением | G8: Убедиться в находке | H8: Принять или отклонить находку | I8: описание, доказательство, исправление | J8: нормальное; пустое; загрузка; ошибка; успех | K8: переход к Регистрация и вход | L8: доля принятых находок | M8: Непонятное доказательство | N8: =IF(A8="","",ROUND(COUNTA(B8:M8)/12,2)) -> 1 | O8: =IF(A8="","",IF(N8>=0.85,"Готов к прототипу",IF(N8>=0.6,"Требует доработки","Недостаточно данных"))) -> Готов к прототипу
A9: U-005 | B9: Отчет аудита | C9: Экран приложения | D9: SC-006 | E9: ROLE-002 | F9: Собрать находки в передаваемый отчет | G9: Получить отчет | H9: Скачать или переслать отчет | I9: заголовок, сводка, таблица, подпись проверки | J9: нормальное; пустое; загрузка; ошибка; успех | K9: возврат к предыдущему шагу | L9: доля купивших отчет | M9: Формат не подходит заказчику | N9: =IF(A9="","",ROUND(COUNTA(B9:M9)/12,2)) -> 1 | O9: =IF(A9="","",IF(N9>=0.85,"Готов к прототипу",IF(N9>=0.6,"Требует доработки","Недостаточно данных"))) -> Готов к прототипу
A10: U-006 | B10: Регистрация и вход | C10: Экран приложения | D10: SC-002 | E10: ROLE-001 | F10: Сохранить результат и открыть кабинет | G10: Создать аккаунт | H10: Ввести email и подтвердить | I10: форма, подтверждение, ссылка входа | J10: нормальное; пустое; загрузка; ошибка; успех | K10: переход к Личный кабинет: история проверок | L10: конверсия в регистрацию | M10: Потеря результата без входа | N10: =IF(A10="","",ROUND(COUNTA(B10:M10)/12,2)) -> 1 | O10: =IF(A10="","",IF(N10>=0.85,"Готов к прототипу",IF(N10>=0.6,"Требует доработки","Недостаточно данных"))) -> Готов к прототипу
A11: U-007 | B11: Страница тарифов | C11: Страница сайта | D11: SC-003 | E11: ROLE-002 | F11: Показать тарифы и помочь выбрать | G11: Выбрать тариф | H11: Нажать «Купить» или «Оформить Pro» | I11: таблица тарифов, сравнение, вопросы и ответы | J11: нормальное; пустое; загрузка; ошибка; успех | K11: переход к Оплата | L11: доля перешедших к оплате | M11: Неясные лимиты Free | N11: =IF(A11="","",ROUND(COUNTA(B11:M11)/12,2)) -> 1 | O11: =IF(A11="","",IF(N11>=0.85,"Готов к прототипу",IF(N11>=0.6,"Требует доработки","Недостаточно данных"))) -> Готов к прототипу
A12: U-008 | B12: Оплата | C12: Экран приложения | D12: SC-003 | E12: ROLE-002 | F12: Принять платеж за аудит или подписку | G12: Оплатить | H12: Подтвердить платеж | I12: форма оплаты, итог, подтверждение | J12: нормальное; пустое; загрузка; ошибка; успех | K12: переход к Отчет аудита | L12: конверсия в платящего | M12: Сбой платежа | N12: =IF(A12="","",ROUND(COUNTA(B12:M12)/12,2)) -> 1 | O12: =IF(A12="","",IF(N12>=0.85,"Готов к прототипу",IF(N12>=0.6,"Требует доработки","Недостаточно данных"))) -> Готов к прототипу
A13: U-009 | B13: Безопасность и политика данных | C13: Страница сайта | D13: SC-010 | E13: ROLE-003 | F13: Снять опасения по загрузке файлов | G13: Проверить безопасность | H13: Открыть политику данных | I13: описание мер, сроки, контакты | J13: нормальное; пустое; загрузка; ошибка; успех | K13: переход к Настройки аккаунта и удаление данных | L13: доля посетителей страницы, дошедших до загрузки | M13: Неполные формулировки | N13: =IF(A13="","",ROUND(COUNTA(B13:M13)/12,2)) -> 1 | O13: =IF(A13="","",IF(N13>=0.85,"Готов к прототипу",IF(N13>=0.6,"Требует доработки","Недостаточно данных"))) -> Готов к прототипу
A14: U-010 | B14: Настройки аккаунта и удаление данных | C14: Экран приложения | D14: SC-010 | E14: ROLE-003 | F14: Дать пользователю управление данными | G14: Удалить данные | H14: Подтвердить удаление | I14: настройки, кнопка удаления, подтверждение | J14: нормальное; пустое; загрузка; ошибка; успех | K14: возврат к предыдущему шагу | L14: число запросов на удаление | M14: Случайное удаление | N14: =IF(A14="","",ROUND(COUNTA(B14:M14)/12,2)) -> 1 | O14: =IF(A14="","",IF(N14>=0.85,"Готов к прототипу",IF(N14>=0.6,"Требует доработки","Недостаточно данных"))) -> Готов к прототипу
A15: U-011 | B15: Личный кабинет: история проверок | C15: Экран приложения | D15: SC-004 | E15: ROLE-001 | F15: Показать прошлые проверки и повторить | G15: Вернуться к проверке | H15: Повторить проверку | I15: список, фильтры, кнопка повторной проверки | J15: нормальное; пустое; загрузка; ошибка; успех | K15: возврат к предыдущему шагу | L15: доля повторных проверок | M15: Пустая история у новых | N15: =IF(A15="","",ROUND(COUNTA(B15:M15)/12,2)) -> 1 | O15: =IF(A15="","",IF(N15>=0.85,"Готов к прототипу",IF(N15>=0.6,"Требует доработки","Недостаточно данных"))) -> Готов к прототипу
A16: U-012 | B16: Надстройка Excel: панель проверки | C16: Экран приложения | D16: SC-005 | E16: ROLE-001 | F16: Проверять книгу прямо в Excel | G16: Проверить книгу | H16: Нажать «Проверить книгу» | I16: боковая панель, список находок, подсветка | J16: нормальное; пустое; загрузка; ошибка; успех | K16: переход к Результат проверки: список находок | L16: установки и активация | M16: Правила публикации AppSource | N16: =IF(A16="","",ROUND(COUNTA(B16:M16)/12,2)) -> 1 | O16: =IF(A16="","",IF(N16>=0.85,"Готов к прототипу",IF(N16>=0.6,"Требует доработки","Недостаточно данных"))) -> Готов к прототипу
... A18: U-017 | B18: Документация и справка | C18: Страница сайта | D18: SC-001 | E18: ROLE-001 | F18: Помочь начать и объяснить правила проверки | G18: Найти ответ | H18: Открыть статью | I18: поиск, разделы, статьи | J18: нормальное; пустое; загрузка; ошибка; успех | K18: возврат к предыдущему шагу | L18: просмотры статей, обращения в поддержку | M18: Устаревшие статьи | N18: =IF(A18="","",ROUND(COUNTA(B18:M18)/12,2)) -> 1 | O18: =IF(A18="","",IF(N18>=0.85,"Готов к прототипу",IF(N18>=0.6,"Требует доработки","Недостаточно данных"))) -> Готов к прототипу
N19: =IF(A19="","",ROUND(COUNTA(B19:M19)/12,2)) | O19: =IF(A19="","",IF(N19>=0.85,"Готов к прототипу",IF(N19>=0.6,"Требует доработки","Недостаточно данных")))
N20: =IF(A20="","",ROUND(COUNTA(B20:M20)/12,2)) | O20: =IF(A20="","",IF(N20>=0.85,"Готов к прототипу",IF(N20>=0.6,"Требует доработки","Недостаточно данных")))
N21: =IF(A21="","",ROUND(COUNTA(B21:M21)/12,2)) | O21: =IF(A21="","",IF(N21>=0.85,"Готов к прототипу",IF(N21>=0.6,"Требует доработки","Недостаточно данных")))
N22: =IF(A22="","",ROUND(COUNTA(B22:M22)/12,2)) | O22: =IF(A22="","",IF(N22>=0.85,"Готов к прототипу",IF(N22>=0.6,"Требует доработки","Недостаточно данных")))
N23: =IF(A23="","",ROUND(COUNTA(B23:M23)/12,2)) | O23: =IF(A23="","",IF(N23>=0.85,"Готов к прототипу",IF(N23>=0.6,"Требует доработки","Недостаточно данных")))
N24: =IF(A24="","",ROUND(COUNTA(B24:M24)/12,2)) | O24: =IF(A24="","",IF(N24>=0.85,"Готов к прототипу",IF(N24>=0.6,"Требует доработки","Недостаточно данных")))
N25: =IF(A25="","",ROUND(COUNTA(B25:M25)/12,2)) | O25: =IF(A25="","",IF(N25>=0.85,"Готов к прототипу",IF(N25>=0.6,"Требует доработки","Недостаточно данных")))
N26: =IF(A26="","",ROUND(COUNTA(B26:M26)/12,2)) | O26: =IF(A26="","",IF(N26>=0.85,"Готов к прототипу",IF(N26>=0.6,"Требует доработки","Недостаточно данных")))
N27: =IF(A27="","",ROUND(COUNTA(B27:M27)/12,2)) | O27: =IF(A27="","",IF(N27>=0.85,"Готов к прототипу",IF(N27>=0.6,"Требует доработки","Недостаточно данных")))
N28: =IF(A28="","",ROUND(COUNTA(B28:M28)/12,2)) | O28: =IF(A28="","",IF(N28>=0.85,"Готов к прототипу",IF(N28>=0.6,"Требует доработки","Недостаточно данных")))
N29: =IF(A29="","",ROUND(COUNTA(B29:M29)/12,2)) | O29: =IF(A29="","",IF(N29>=0.85,"Готов к прототипу",IF(N29>=0.6,"Требует доработки","Недостаточно данных")))
N30: =IF(A30="","",ROUND(COUNTA(B30:M30)/12,2)) | O30: =IF(A30="","",IF(N30>=0.85,"Готов к прототипу",IF(N30>=0.6,"Требует доработки","Недостаточно данных")))
... N304: =IF(A304="","",ROUND(COUNTA(B304:M304)/12,2)) | O304: =IF(A304="","",IF(N304>=0.85,"Готов к прототипу",IF(N304>=0.6,"Требует доработки","Недостаточно данных")))

Sheet Приоритизация
A1: Приоритизация страниц, экранов и интерфейсных инициатив
A2: Итоговый балл помогает определить состав первой версии и очередность следующих выпусков.
A4: Unit_ID | B4: Название | C4: Связанный сценарий_ID | D4: Ценность для пользователя 1–5 | E4: Влияние на бизнес 1–5 | F4: Частота использования 1–5 | G4: Риск без реализации 1–5 | H4: Сложность 1–5 | I4: Итоговый балл | J4: Класс приоритета | K4: Основание | L4: Решение
A5: U-001 | B5: Страница продукта с примерами ошибок | C5: SC-001 | D5: 5 | E5: 5 | F5: 5 | G5: 5 | H5: 2 | I5: =IF(A5="","",MAX(0,MIN(100,ROUND(((D5*0.3)+(E5*0.3)+(F5*0.15)+(G5*0.15)-(H5*0.1))*20,0)))) -> 86 | J5: =IF(A5="","",IF(I5>=80,"P1 — первая версия",IF(I5>=60,"P2 — следующий выпуск",IF(I5>=40,"P3 — можно отложить","Не включать")))) -> P1 — первая версия | K5: Критична для первичного понимания ценности | L5: Включить в первую версию
A6: U-002 | B6: Загрузка файла и запуск проверки | C6: SC-001 | D6: 5 | E6: 5 | F6: 5 | G6: 5 | H6: 2 | I6: =IF(A6="","",MAX(0,MIN(100,ROUND(((D6*0.3)+(E6*0.3)+(F6*0.15)+(G6*0.15)-(H6*0.1))*20,0)))) -> 86 | J6: =IF(A6="","",IF(I6>=80,"P1 — первая версия",IF(I6>=60,"P2 — следующий выпуск",IF(I6>=40,"P3 — можно отложить","Не включать")))) -> P1 — первая версия | K6: Без экрана нет первого результата | L6: Включить в первую версию
A7: U-003 | B7: Результат проверки: список находок | C7: SC-001 | D7: 5 | E7: 5 | F7: 5 | G7: 5 | H7: 3 | I7: =IF(A7="","",MAX(0,MIN(100,ROUND(((D7*0.3)+(E7*0.3)+(F7*0.15)+(G7*0.15)-(H7*0.1))*20,0)))) -> 84 | J7: =IF(A7="","",IF(I7>=80,"P1 — первая версия",IF(I7>=60,"P2 — следующий выпуск",IF(I7>=40,"P3 — можно отложить","Не включать")))) -> P1 — первая версия | K7: Показывает ключевую ценность | L7: Включить в первую версию
A8: U-004 | B8: Карточка находки с доказательством | C8: SC-001 | D8: 5 | E8: 4 | F8: 4 | G8: 4 | H8: 3 | I8: =IF(A8="","",MAX(0,MIN(100,ROUND(((D8*0.3)+(E8*0.3)+(F8*0.15)+(G8*0.15)-(H8*0.1))*20,0)))) -> 72 | J8: =IF(A8="","",IF(I8>=80,"P1 — первая версия",IF(I8>=60,"P2 — следующий выпуск",IF(I8>=40,"P3 — можно отложить","Не включать")))) -> P2 — следующий выпуск | K8: Зона дифференциации | L8: Включить в первую версию
A9: U-005 | B9: Отчет аудита | C9: SC-006 | D9: 4 | E9: 5 | F9: 4 | G9: 4 | H9: 2 | I9: =IF(A9="","",MAX(0,MIN(100,ROUND(((D9*0.3)+(E9*0.3)+(F9*0.15)+(G9*0.15)-(H9*0.1))*20,0)))) -> 74 | J9: =IF(A9="","",IF(I9>=80,"P1 — первая версия",IF(I9>=60,"P2 — следующий выпуск",IF(I9>=40,"P3 — можно отложить","Не включать")))) -> P2 — следующий выпуск | K9: Основа платных продаж | L9: Включить в первую версию
A10: U-006 | B10: Регистрация и вход | C10: SC-002 | D10: 3 | E10: 5 | F10: 4 | G10: 4 | H10: 2 | I10: =IF(A10="","",MAX(0,MIN(100,ROUND(((D10*0.3)+(E10*0.3)+(F10*0.15)+(G10*0.15)-(H10*0.1))*20,0)))) -> 68 | J10: =IF(A10="","",IF(I10>=80,"P1 — первая версия",IF(I10>=60,"P2 — следующий выпуск",IF(I10>=40,"P3 — можно отложить","Не включать")))) -> P2 — следующий выпуск | K10: Нужна для сохранения результата и оплаты | L10: Включить в первую версию
A11: U-007 | B11: Страница тарифов | C11: SC-003 | D11: 4 | E11: 5 | F11: 4 | G11: 5 | H11: 1 | I11: =IF(A11="","",MAX(0,MIN(100,ROUND(((D11*0.3)+(E11*0.3)+(F11*0.15)+(G11*0.15)-(H11*0.1))*20,0)))) -> 79 | J11: =IF(A11="","",IF(I11>=80,"P1 — первая версия",IF(I11>=60,"P2 — следующий выпуск",IF(I11>=40,"P3 — можно отложить","Не включать")))) -> P2 — следующий выпуск | K11: Прозрачная цена - зона дифференциации | L11: Включить в первую версию
A12: U-008 | B12: Оплата | C12: SC-003 | D12: 3 | E12: 5 | F12: 3 | G12: 5 | H12: 3 | I12: =IF(A12="","",MAX(0,MIN(100,ROUND(((D12*0.3)+(E12*0.3)+(F12*0.15)+(G12*0.15)-(H12*0.1))*20,0)))) -> 66 | J12: =IF(A12="","",IF(I12>=80,"P1 — первая версия",IF(I12>=60,"P2 — следующий выпуск",IF(I12>=40,"P3 — можно отложить","Не включать")))) -> P2 — следующий выпуск | K12: Без оплаты нет дохода | L12: Включить в первую версию
A13: U-009 | B13: Безопасность и политика данных | C13: SC-010 | D13: 4 | E13: 4 | F13: 3 | G13: 5 | H13: 1 | I13: =IF(A13="","",MAX(0,MIN(100,ROUND(((D13*0.3)+(E13*0.3)+(F13*0.15)+(G13*0.15)-(H13*0.1))*20,0)))) -> 70 | J13: =IF(A13="","",IF(I13>=80,"P1 — первая версия",IF(I13>=60,"P2 — следующий выпуск",IF(I13>=40,"P3 — можно отложить","Не включать")))) -> P2 — следующий выпуск | K13: Обязательный разрыв ЛР5 | L13: Включить в первую версию
A14: U-010 | B14: Настройки аккаунта и удаление данных | C14: SC-010 | D14: 3 | E14: 3 | F14: 2 | G14: 4 | H14: 2 | I14: =IF(A14="","",MAX(0,MIN(100,ROUND(((D14*0.3)+(E14*0.3)+(F14*0.15)+(G14*0.15)-(H14*0.1))*20,0)))) -> 50 | J14: =IF(A14="","",IF(I14>=80,"P1 — первая версия",IF(I14>=60,"P2 — следующий выпуск",IF(I14>=40,"P3 — можно отложить","Не включать")))) -> P3 — можно отложить | K14: Требование GDPR | L14: Включить в первую версию
A15: U-011 | B15: Личный кабинет: история проверок | C15: SC-004 | D15: 3 | E15: 3 | F15: 4 | G15: 3 | H15: 2 | I15: =IF(A15="","",MAX(0,MIN(100,ROUND(((D15*0.3)+(E15*0.3)+(F15*0.15)+(G15*0.15)-(H15*0.1))*20,0)))) -> 53 | J15: =IF(A15="","",IF(I15>=80,"P1 — первая версия",IF(I15>=60,"P2 — следующий выпуск",IF(I15>=40,"P3 — можно отложить","Не включать")))) -> P3 — можно отложить | K15: Удержание, не нужна для первой ценности | L15: Отложить
A16: U-012 | B16: Надстройка Excel: панель проверки | C16: SC-005 | D16: 5 | E16: 4 | F16: 4 | G16: 4 | H16: 5 | I16: =IF(A16="","",MAX(0,MIN(100,ROUND(((D16*0.3)+(E16*0.3)+(F16*0.15)+(G16*0.15)-(H16*0.1))*20,0)))) -> 68 | J16: =IF(A16="","",IF(I16>=80,"P1 — первая версия",IF(I16>=60,"P2 — следующий выпуск",IF(I16>=40,"P3 — можно отложить","Не включать")))) -> P2 — следующий выпуск | K16: Стандарт рынка, выпуск в бета v1 | L16: Отложить
... A18: U-017 | B18: Документация и справка | C18: SC-001 | D18: 3 | E18: 3 | F18: 4 | G18: 3 | H18: 2 | I18: =IF(A18="","",MAX(0,MIN(100,ROUND(((D18*0.3)+(E18*0.3)+(F18*0.15)+(G18*0.15)-(H18*0.1))*20,0)))) -> 53 | J18: =IF(A18="","",IF(I18>=80,"P1 — первая версия",IF(I18>=60,"P2 — следующий выпуск",IF(I18>=40,"P3 — можно отложить","Не включать")))) -> P3 — можно отложить | K18: Стандарт рынка, развивается после запуска | L18: Включить в первую версию
I19: =IF(A19="","",MAX(0,MIN(100,ROUND(((D19*0.3)+(E19*0.3)+(F19*0.15)+(G19*0.15)-(H19*0.1))*20,0)))) | J19: =IF(A19="","",IF(I19>=80,"P1 — первая версия",IF(I19>=60,"P2 — следующий выпуск",IF(I19>=40,"P3 — можно отложить","Не включать"))))
I20: =IF(A20="","",MAX(0,MIN(100,ROUND(((D20*0.3)+(E20*0.3)+(F20*0.15)+(G20*0.15)-(H20*0.1))*20,0)))) | J20: =IF(A20="","",IF(I20>=80,"P1 — первая версия",IF(I20>=60,"P2 — следующий выпуск",IF(I20>=40,"P3 — можно отложить","Не включать"))))
I21: =IF(A21="","",MAX(0,MIN(100,ROUND(((D21*0.3)+(E21*0.3)+(F21*0.15)+(G21*0.15)-(H21*0.1))*20,0)))) | J21: =IF(A21="","",IF(I21>=80,"P1 — первая версия",IF(I21>=60,"P2 — следующий выпуск",IF(I21>=40,"P3 — можно отложить","Не включать"))))
I22: =IF(A22="","",MAX(0,MIN(100,ROUND(((D22*0.3)+(E22*0.3)+(F22*0.15)+(G22*0.15)-(H22*0.1))*20,0)))) | J22: =IF(A22="","",IF(I22>=80,"P1 — первая версия",IF(I22>=60,"P2 — следующий выпуск",IF(I22>=40,"P3 — можно отложить","Не включать"))))
I23: =IF(A23="","",MAX(0,MIN(100,ROUND(((D23*0.3)+(E23*0.3)+(F23*0.15)+(G23*0.15)-(H23*0.1))*20,0)))) | J23: =IF(A23="","",IF(I23>=80,"P1 — первая версия",IF(I23>=60,"P2 — следующий выпуск",IF(I23>=40,"P3 — можно отложить","Не включать"))))
I24: =IF(A24="","",MAX(0,MIN(100,ROUND(((D24*0.3)+(E24*0.3)+(F24*0.15)+(G24*0.15)-(H24*0.1))*20,0)))) | J24: =IF(A24="","",IF(I24>=80,"P1 — первая версия",IF(I24>=60,"P2 — следующий выпуск",IF(I24>=40,"P3 — можно отложить","Не включать"))))
I25: =IF(A25="","",MAX(0,MIN(100,ROUND(((D25*0.3)+(E25*0.3)+(F25*0.15)+(G25*0.15)-(H25*0.1))*20,0)))) | J25: =IF(A25="","",IF(I25>=80,"P1 — первая версия",IF(I25>=60,"P2 — следующий выпуск",IF(I25>=40,"P3 — можно отложить","Не включать"))))
I26: =IF(A26="","",MAX(0,MIN(100,ROUND(((D26*0.3)+(E26*0.3)+(F26*0.15)+(G26*0.15)-(H26*0.1))*20,0)))) | J26: =IF(A26="","",IF(I26>=80,"P1 — первая версия",IF(I26>=60,"P2 — следующий выпуск",IF(I26>=40,"P3 — можно отложить","Не включать"))))
I27: =IF(A27="","",MAX(0,MIN(100,ROUND(((D27*0.3)+(E27*0.3)+(F27*0.15)+(G27*0.15)-(H27*0.1))*20,0)))) | J27: =IF(A27="","",IF(I27>=80,"P1 — первая версия",IF(I27>=60,"P2 — следующий выпуск",IF(I27>=40,"P3 — можно отложить","Не включать"))))
I28: =IF(A28="","",MAX(0,MIN(100,ROUND(((D28*0.3)+(E28*0.3)+(F28*0.15)+(G28*0.15)-(H28*0.1))*20,0)))) | J28: =IF(A28="","",IF(I28>=80,"P1 — первая версия",IF(I28>=60,"P2 — следующий выпуск",IF(I28>=40,"P3 — можно отложить","Не включать"))))
I29: =IF(A29="","",MAX(0,MIN(100,ROUND(((D29*0.3)+(E29*0.3)+(F29*0.15)+(G29*0.15)-(H29*0.1))*20,0)))) | J29: =IF(A29="","",IF(I29>=80,"P1 — первая версия",IF(I29>=60,"P2 — следующий выпуск",IF(I29>=40,"P3 — можно отложить","Не включать"))))
I30: =IF(A30="","",MAX(0,MIN(100,ROUND(((D30*0.3)+(E30*0.3)+(F30*0.15)+(G30*0.15)-(H30*0.1))*20,0)))) | J30: =IF(A30="","",IF(I30>=80,"P1 — первая версия",IF(I30>=60,"P2 — следующий выпуск",IF(I30>=40,"P3 — можно отложить","Не включать"))))
... I304: =IF(A304="","",MAX(0,MIN(100,ROUND(((D304*0.3)+(E304*0.3)+(F304*0.15)+(G304*0.15)-(H304*0.1))*20,0)))) | J304: =IF(A304="","",IF(I304>=80,"P1 — первая версия",IF(I304>=60,"P2 — следующий выпуск",IF(I304>=40,"P3 — можно отложить","Не включать"))))

Sheet Проверка_связности
A1: Проверка связности проектной логики
A2: Лист показывает, насколько интерфейсные единицы выведены из анализа и связаны со сценариями, навигацией, состояниями и бизнес-моделью.
A4: Проверка | B4: Описание | C4: Расчет / критерий | D4: Результат | E4: Статус | F4: Что исправить
A5: Покрытие сценариев | B5: У каждого значимого сценария есть хотя бы одна страница или экран | C5: Сценарии с покрытием / всего сценариев | D5: =IFERROR(COUNTIF(Пользовательские_сценарии!$N$5:$N$304,"Покрыт")/SUMPRODUCT(--(Пользовательские_сценарии!$A$5:$A$304<>"")),0) -> 0.8 | E5: =IF(D5>=0.9,"Норма",IF(D5>=0.7,"Требует проверки","Проблема")) -> Требует проверки | F5: Для сценариев без покрытия добавить интерфейсную единицу или исключить сценарий
A6: Интерфейсные единицы без сценария | B6: Не должно быть страниц и экранов без связанного сценария | C6: Количество строк с пустым сценарием | D6: =SUMPRODUCT(--(Страницы_и_экраны!$A$5:$A$304<>""),--(Страницы_и_экраны!$E$5:$E$304="")) -> 0 | E6: =IF(D6=0,"Норма","Проблема") -> Норма | F6: Указать сценарий или удалить лишнюю единицу
A7: Полнота паспортов | B7: Паспорта ключевых страниц и экранов должны быть заполнены не менее чем на 85% | C7: Средняя полнота паспортов | D7: =IFERROR(AVERAGE(Паспорт_экрана!$N$5:$N$304),0) -> 1 | E7: =IF(D7>=0.85,"Норма",IF(D7>=0.6,"Требует проверки","Проблема")) -> Норма | F7: Заполнить назначение, задачи, действия, состояния, навигацию, метрики
